Workbook

Sheet 00_Beta
A1: BẢNG TÍNH HỆ SỐ BETA LỊCH SỬ | B1: Beta thô (raw): | C1: =COVAR(C1138:C1637,E1138:E1637)/VAR(E1138:E1637) | D1: Beta Blume (đã điều chỉnh): | E1: =0.67*C1+0.33
B2: Số phiên giao dịch: | C2: =COUNT(C1138:C1637)
A4: Ngày | B4: Giá MWG | C4: Tỷ suất sinh lời MWG | D4: Giá VNINDEX | E4: Tỷ suất sinh lời VNINDEX
A5: 2020-01-02 | B5: 36902 | D5: 966.67
A6: 2020-01-03 | B6: 36366 | C6: =(B6-B5)/B5 | D6: 965.14 | E6: =(D6-D5)/D5
A7: 2020-01-06 | B7: 36176 | C7: =(B7-B6)/B6 | D7: 955.79 | E7: =(D7-D6)/D6
A8: 2020-01-07 | B8: 36460 | C8: =(B8-B7)/B7 | D8: 958.88 | E8: =(D8-D7)/D7
A9: 2020-01-08 | B9: 35577 | C9: =(B9-B8)/B8 | D9: 948.98 | E9: =(D9-D8)/D8
A10: 2020-01-09 | B10: 36113 | C10: =(B10-B9)/B9 | D10: 960.15 | E10: =(D10-D9)/D9
A11: 2020-01-10 | B11: 36303 | C11: =(B11-B10)/B10 | D11: 968.54 | E11: =(D11-D10)/D10
A12: 2020-01-13 | B12: 36113 | C12: =(B12-B11)/B11 | D12: 965.84 | E12: =(D12-D11)/D11
A13: 2020-01-14 | B13: 35924 | C13: =(B13-B12)/B12 | D13: 967 | E13: =(D13-D12)/D12
A14: 2020-01-15 | B14: 35956 | C14: =(B14-B13)/B13 | D14: 967.56 | E14: =(D14-D13)/D13
A15: 2020-01-16 | B15: 36397 | C15: =(B15-B14)/B14 | D15: 974.31 | E15: =(D15-D14)/D14
A16: 2020-01-17 | B16: 36618 | C16: =(B16-B15)/B15 | D16: 978.96 | E16: =(D16-D15)/D15
A17: 2020-01-20 | B17: 37406 | C17: =(B17-B16)/B16 | D17: 978.63 | E17: =(D17-D16)/D16
... A1637: 2026-07-21 | B1637: 75000 | C1637: =(B1637-B1636)/B1636 | D1637: 1735.33 | E1637: =(D1637-D1636)/D1636

Sheet 00_COE
A1: CHI PHÍ VỐN CSH (COE) — MÔ HÌNH CAPM
A3: Tham số | B3: Giá trị | C3: Ghi chú / Nguồn
A4: Rf — Lãi suất phi rủi ro (TPCP 10 năm) | B4: 0.045 | C4: Cache lần chạy trước (2026-07-15 14:49)
A5: β — Hệ số Beta (Blume-adjusted) | B5: ='00_Beta'!E1 | C5: Tu tinh toan (1633 phien)
A6: ERP — Phần bù rủi ro vốn (Damodaran) | B6: 0.07
A7: α — Phần bù rủi ro đặc thù (Frontier-market retail) | B7: 0.015
A9: COE = Rf + β×ERP + α | B9: =B4+B5*B6+B7

Sheet 01_Cover
A1: PHÂN TÍCH CỔ PHIẾU MWG — CTCP Đầu tư Thế Giới Di Động
A2: Ticker | B2: MWG
A3: Sàn | B3: HOSE
A4: Ngành | B4: Bán lẻ
A5: Giá hiện tại (VND) | B5: ='02_Assumptions'!B2
A6: Số CP lưu hành (triệu) | B6: ='02_Assumptions'!B3
A7: Vốn hóa (tỷ VND) | B7: ='02_Assumptions'!B4
A8: P/E TTM (x) | B8: 15.7
A9: P/B (x) | B9: 3.33
A10: EPS TTM (VND) | B10: 4785
A11: BVPS (VND) | B11: 22569
A12: Kế hoạch DT 2026 (tỷ) | B12: 185000
A13: Kế hoạch LNST 2026 (tỷ) | B13: 9200
A14: Khuyến nghị | B14: =IF('07_Valuation'!C13>0.15,"MUA",IF('07_Valuation'!C13<-0.05,"BÁN","THEO DÕI"))
A15: Giá mục tiêu (VND) | B15: ='07_Valuation'!C11
A16: Upside/Downside | B16: ='07_Valuation'!C13
A17: Ngày phân tích | B17: 21/07/2026 06:30
A19: 4 PHƯƠNG PHÁP ĐỊNH GIÁ (trọng số theo skill ban-le, đã bỏ P/S+P/B)
A20: P/E Median (20%) | B20: ='07_Valuation'!C6
A21: P/B Median (20%) | B21: ='07_Valuation'!C7
A22: Residual Income (10%) | B22: ='07_Valuation'!C8
A23: P/S + P/E theo mảng, cả 4 mảng (35%) | B23: ='07_Valuation'!C9

Sheet 02_Assumptions
A1: Giả định | B1: 2021A | C1: 2022A | D1: 2023A | E1: 2024A | F1: 2025A | G1: 2026E | H1: 2027F | I1: 2028F | J1: Ghi chú
A2: Giá cổ phiếu hiện tại (VND) | B2: 75200 | C2: Giá đóng cửa gần nhất (Vietcap)
A3: Số CP lưu hành (triệu CP) | B3: 1470 | C3: Vốn góp/mệnh giá 10,000đ
A4: Vốn hóa (tỷ VND) | B4: =B2*B3/1000 | C4: Giá x SL CP (không phải công thức, chỉ là ghi chú)
A6: SỐ CỬA HÀNG CUỐI KỲ (cửa hàng)
A7: TGDĐ (gồm Topzone) | G7: 998 | H7: 988 | I7: 978 | J7: IR MWG; dự phóng: xu hướng tái cơ cấu -1%/năm
A8: ĐMX (gồm ĐMS) | G8: 2005 | H8: 2005 | I8: 2005 | J8: Dự phóng: đi ngang (bão hòa)
A9: BHX | G9: 3559 | H9: 4259 | I9: 4759 | J9: Dự phóng: +1000/+700/+500 theo kế hoạch IR
A10: Khác (An Khang+AvaKids+EraBlue) | G10: 810 | H10: 910 | I10: 1010 | J10: EraBlue mục tiêu >300 CH 2026 (IR)
A12: HIỆU QUẢ DT/CH/THÁNG HIỆN TẠI (tỷ VND, lag 3 tháng)
A13: TGDD | B13: 3.642 | C13: DT 5T2026/5/số CH lag 3 tháng (skill ban-le mục 2)
A14: DMX | B14: 3.759 | C14: DT 5T2026/5/số CH lag 3 tháng (skill ban-le mục 2)
A15: BHX | B15: 1.54 | C15: DT 5T2026/5/số CH lag 3 tháng (skill ban-le mục 2)
A16: Khac | B16: 0.52 | C16: DT 5T2026/5/số CH lag 3 tháng (skill ban-le mục 2)
A17: Tăng trưởng hiệu quả/CH TGDD (%/năm) | B17: 0 | C17: Giả định có căn cứ — xem comment code
A18: Tăng trưởng hiệu quả/CH DMX (%/năm) | B18: 0.03 | C18: Giả định có căn cứ — xem comment code
A19: Tăng trưởng hiệu quả/CH BHX (%/năm) | B19: 0.08 | C19: Giả định có căn cứ — xem comment code
A20: Tăng trưởng hiệu quả/CH Khac (%/năm) | B20: 0.05 | C20: Giả định có căn cứ — xem comment code
A22: BIÊN LỢI NHUẬN & CHI PHÍ
A23: Biên lợi nhuận gộp (%) | B23: 0.2247 | C23: 0.2313 | D23: 0.1904 | E23: 0.2047 | F23: 0.1988 | G23: 0.2079 | H23: 0.2079 | I23: 0.2079 | J23: Dự phóng = TB 2 quý gần nhất (skill ban-le mục 4)
A24: SG&A / Doanh thu (%) | B24: 0.17678868 | C24: 0.1815362 | D24: 0.1867132 | E24: 0.17429947 | F24: 0.15344893 | G24: 0.1451 | H24: 0.1389 | I24: 0.1327 | J24: Dự phóng = hồi quy tuyến tính 4 quý gần nhất
A25: Thuế suất hiệu dụng (%) | B25: 0.2036 | C25: TB 2 năm gần nhất = 1-LNST hợp nhất/LNTT (isa16)
A26: DT/CP tài chính ròng / DT (%) | B26: 0.0094 | C26: TB 2 năm gần nhất (lãi tiền gửi ròng)
A27: Tỷ lệ chia cổ tức tiền mặt/LNST (%) | B27: 0.3 | C27: Giả định — MWG trả cổ tức đều đặn
A29: VÒNG QUAY VỐN LƯU ĐỘNG
A30: DIO - Số ngày tồn kho | B30: 77.830029 | C30: TB 2 năm gần nhất
A31: DSO - Số ngày phải thu | B31: 23.907883 | C31: TB 2 năm gần nhất
A32: DPO - Số ngày phải trả | B32: 34.837552 | C32: TB 2 năm gần nhất
A33: D&A / Doanh thu (%) | B33: 0.016906657 | C33: TB 2 năm gần nhất
A34: CAPEX / Doanh thu (%) | B34: 0.0039794004 | C34: TB 2 năm gần nhất
A35: Tăng trưởng Nợ vay YoY (%) | B35: 0.091712982 | C35: TB 2 năm gần nhất
A36: Tăng trưởng Tiền mặt YoY (%) | B36: 0.27204785 | C36: TB 2 năm gần nhất
A38: ĐỊNH GIÁ
A39: P/E Median lịch sử (x) | B39: ='13_PE_PB_History'!B36 | C39: Xem đầy đủ 33 quý + công thức MEDIAN tại sheet 13_PE_PB_History
A40: P/B Median lịch sử (x) | B40: ='13_PE_PB_History'!C36 | C40: Xem đầy đủ 33 quý + công thức MEDIAN tại sheet 13_PE_PB_History
A41: Beta (Blume-adjusted) | B41: 1.0821 | C41: Beta thô 1.1226 (Tu tinh toan (1633 phien))
A42: Lãi suất phi rủi ro Rf (%) | B42: 0.045 | C42: Nguồn: Cache lần chạy trước (2026-07-15 14:49)
A43: Equity Risk Premium (%) | B43: 0.07 | C43: Damodaran ERP
A44: Premium rủi ro đặc thù (%) | B44: 0.015 | C44: Frontier-market retail risk premium
A45: Chi phí vốn CSH COE (%) | B45: ='00_COE'!B9 | C45: Xem chi tiết CAPM tại sheet 00_COE/00_Beta
...

Sheet 03a_Monthly_Data
A1: Chỉ tiêu | B1: T1-19 | C1: T2-19 | D1: T3-19 | E1: T4-19 | F1: T5-19 | G1: T6-19 | H1: T7-19 | I1: T8-19 | J1: T9-19 | K1: T10-19 | L1: T11-19 | M1: T12-19 | N1: T1-20 | O1: T2-20 | P1: T3-20 | Q1: T4-20 | R1: T5-20 | S1: T6-20 | T1: T7-20 | U1: T8-20 | V1: T9-20 | W1: T10-20 | X1: T11-20 | Y1: T12-20 | Z1: T1-21 | AA1: T2-21 | AB1: T3-21 | AC1: T4-21 | AD1: T5-21 | AE1: T6-21 | AF1: T7-21 | AG1: T8-21 | AH1: T9-21 | AI1: T10-21 | AJ1: T11-21 | AK1: T12-21 | AL1: T1-22 | AM1: T2-22 | AN1: T3-22 | AO1: T4-22 | AP1: T5-22 | AQ1: T6-22 | AR1: T7-22 | AS1: T8-22 | AT1: T9-22 | AU1: T10-22 | AV1: T11-22 | AW1: T12-22 | AX1: T1-23 | AY1: T2-23 | AZ1: T3-23 | BA1: T4-23 | BB1: T5-23 | BC1: T6-23 | BD1: T7-23 | BE1: T8-23 | BF1: T9-23 | BG1: T10-23 | BH1: T11-23 | BI1: T12-23 | BJ1: T1-24 | BK1: T2-24 | BL1: T3-24 | BM1: T4-24 | BN1: T5-24 | BO1: T6-24 | BP1: T7-24 | BQ1: T8-24 | BR1: T9-24 | BS1: T10-24 | BT1: T11-24 | BU1: T12-24 | BV1: T1-25 | BW1: T2-25 | BX1: T3-25 | BY1: T4-25 | BZ1: T5-25 | CA1: T6-25 | CB1: T7-25 | CC1: T8-25 | CD1: T9-25 | CE1: T10-25 | CF1: T11-25 | CG1: T12-25 | CH1: T1-26 | CI1: T2-26 | CJ1: T3-26 | CK1: T4-26 | CL1: T5-26 | CM1: T6-26 | CN1: Ước tính 2026 | CO1: Ước tính 2027 | CP1: Ước tính 2028 | CQ1: Ghi chú
A2: Doanh thu tổng (tỷ VND) | B2: 10350 | C2: 7026 | D2: 7641 | E2: 8903.3 | F2: 8903.3 | G2: 8903.3 | H2: 8345.3 | I2: 8345.3 | J2: 8345.3 | K2: 8470.3 | L2: 8470.3 | M2: 8470.3 | N2: 12560 | O2: 4836 | P2: 7621 | Q2: 9105 | R2: 8662 | S2: 8837 | T2: 9296 | U2: 12053 | V2: 3793 | W2: 7960 | X2: 8363 | Y2: 15460 | Z2: 11049 | AA2: 9492 | AB2: 8812 | AC2: 11096 | AD2: 11381 | AE2: 10657 | AF2: 9499 | AG2: 6509 | AH2: 8325 | AI2: 12186 | AJ2: 11524 | AK2: 12428 | AL2: 12691.5 | AM2: 12691.5 | AN2: 11084 | AO2: 11441 | AP2: 11416 | AQ2: 11480 | AR2: 11066 | AS2: 10413 | AT2: 10533 | AU2: 10896 | AV2: 9971 | AW2: 9362 | AX2: 9505 | AY2: 9505 | AZ2: 7980 | BA2: 9857 | BB2: 10297 | BC2: 9426 | BD2: 9920 | BE2: 9965 | BF2: 10403 | BG2: 11188 | BH2: 9908 | BI2: 10326 | BJ2: 10806.5 | BK2: 10806.5 | BL2: 9828 | BM2: 11598 | BN2: 11201 | BO2: 11381 | BP2: 10920 | BQ2: 11426 | BR2: 11800 | BS2: 11586 | BT2: 10945 | BU2: 12043 | BV2: 12262 | BW2: 12262 | BX2: 11567 | BY2: 12544 | BZ2: 12594 | CA2: 12426 | CB2: 12852 | CC2: 13294 | CD2: 13635 | CE2: 14853 | CF2: 14013 | CG2: 13864 | CH2: 16102 | CI2: 16102 | CJ2: 14304 | CK2: 15988 | CL2: 16663 | CM2: 16146 | CN2: =CN8+CN9+CN10+CN11 | CO2: =CO8+CO9+CO10+CO11 | CP2: =CP8+CP9+CP10+CP11
A3: %Dthu TGDD | B3: 0.3106 | C3: 0.3822 | D3: 0.3738 | E3: 0.319 | F3: 0.319 | G3: 0.319 | H3: 0.3309 | I3: 0.3309 | J3: 0.3309 | K3: 0.3008 | L3: 0.3008 | M3: 0.3008 | Q3: 0.274 | R3: 0.2049 | S3: 0.272 | T3: 0.265 | U3: 0.2832 | V3: 0.3085 | W3: 0.2913 | X3: 0.272 | Y3: 0.272 | Z3: 0.272 | AA3: 0.26 | AB3: 0.2866 | AC3: 0.268 | AD3: 0.2225 | AE3: 0.2111 | AF3: 0.1666 | AG3: 0.1666 | AH3: 0.2643 | AI3: 0.2685 | AJ3: 0.2688 | AK3: 0.2688 | AL3: 0.2689 | AM3: 0.2689 | AN3: 0.2857 | AO3: 0.2644 | AP3: 0.2717 | AQ3: 0.2427 | AR3: 0.2344 | AS3: 0.2883 | AT3: 0.2372 | AU3: 0.3033 | AV3: 0.2107 | AW3: 0.2336 | AX3: 0.255 | AY3: 0.255 | AZ3: 0.2246 | BA3: 0.2236 | BB3: 0.2171 | BC3: 0.241 | BD3: 0.236 | BE3: 0.236 | BF3: 0.2527 | BG3: 0.2818 | BH3: 0.2321 | BI3: 0.2076 | BJ3: 0.212 | BK3: 0.212 | BL3: 0.2248 | BM3: 0.1826 | BN3: 0.1973 | BO3: 0.217 | BP3: 0.217 | BQ3: 0.217 | BR3: 0.217 | BS3: 0.217 | BT3: 0.217 | BU3: 0.217 | BV3: 0.217 | BW3: 0.217 | BX3: 0.226 | BY3: 0.226 | BZ3: 0.226 | CA3: 0.226 | CB3: 0.226 | CC3: 0.226 | CD3: 0.226 | CE3: 0.237 | CF3: 0.237 | CG3: 0.237 | CH3: 0.237 | CI3: 0.229 | CJ3: 0.229 | CK3: 0.229 | CL3: 0.225 | CM3: 0.225
A4: %Dthu DMX | B4: 0.6287 | C4: 0.5628 | D4: 0.5299 | E4: 0.5936 | F4: 0.5936 | G4: 0.5936 | H4: 0.5471 | I4: 0.5471 | J4: 0.5471 | K4: 0.5579 | L4: 0.5579 | M4: 0.5579 | N4: 0.631 | O4: 0.631 | P4: 0.631 | Q4: 0.5545 | R4: 0.6341 | S4: 0.538 | T4: 0.56 | U4: 0.5055 | V4: 0.4093 | W4: 0.4801 | X4: 0.5046 | Y4: 0.538 | Z4: 0.538 | AA4: 0.557 | AB4: 0.497 | AC4: 0.5135 | AD4: 0.5411 | AE4: 0.5281 | AF4: 0.5281 | AG4: 0.5281 | AH4: 0.4906 | AI4: 0.5731 | AJ4: 0.5665 | AK4: 0.5665 | AL4: 0.5703 | AM4: 0.5703 | AN4: 0.5002 | AO4: 0.5297 | AP4: 0.5444 | AQ4: 0.5049 | AR4: 0.5336 | AS4: 0.4612 | AT4: 0.4937 | AU4: 0.4866 | AV4: 0.5029 | AW4: 0.4774 | AX4: 0.51 | AY4: 0.51 | AZ4: 0.4525 | BA4: 0.5229 | BB4: 0.5239 | BC4: 0.464 | BD4: 0.4454 | BE4: 0.4526 | BF4: 0.4359 | BG4: 0.4187 | BH4: 0.4294 | BI4: 0.4461 | BJ4: 0.477 | BK4: 0.477 | BL4: 0.429 | BM4: 0.514 | BN4: 0.4663 | BO4: 0.452 | BP4: 0.452 | BQ4: 0.452 | BR4: 0.452 | BS4: 0.452 | BT4: 0.452 | BU4: 0.452 | BV4: 0.452 | BW4: 0.452 | BX4: 0.446 | BY4: 0.446 | BZ4: 0.446 | CA4: 0.446 | CB4: 0.446 | CC4: 0.446 | CD4: 0.446 | CE4: 0.44 | CF4: 0.44 | CG4: 0.44 | CH4: 0.44 | CI4: 0.464 | CJ4: 0.464 | CK4: 0.464 | CL4: 0.463 | CM4: 0.463
A5: %Dthu BHX | B5: 0.0607 | C5: 0.0551 | D5: 0.0963 | E5: 0.0874 | F5: 0.0874 | G5: 0.0874 | H5: 0.1219 | I5: 0.1219 | J5: 0.1219 | K5: 0.1413 | L5: 0.1413 | M5: 0.1413 | N5: 0.105 | O5: 0.1805 | P5: 0.2146 | Q5: 0.2017 | R5: 0.1611 | S5: 0.19 | T5: 0.175 | U5: 0.2113 | V5: 0.2822 | W5: 0.2286 | X5: 0.2234 | Y5: 0.19 | Z5: 0.19 | AA5: 0.183 | AB5: 0.2163 | AC5: 0.2185 | AD5: 0.2228 | AE5: 0.2578 | AF5: 0.2578 | AG5: 0.2578 | AH5: 0.2317 | AI5: 0.1625 | AJ5: 0.1521 | AK5: 0.149 | AL5: 0.1536 | AM5: 0.1536 | AN5: 0.1944 | AO5: 0.1878 | AP5: 0.1712 | AQ5: 0.2316 | AR5: 0.2158 | AS5: 0.23 | AT5: 0.2278 | AU5: 0.2112 | AV5: 0.2321 | AW5: 0.2558 | AX5: 0.217 | AY5: 0.217 | AZ5: 0.2813 | BA5: 0.2323 | BB5: 0.2396 | BC5: 0.272 | BD5: 0.2822 | BE5: 0.294 | BF5: 0.279 | BG5: 0.2745 | BH5: 0.3026 | BI5: 0.3088 | BJ5: 0.282 | BK5: 0.282 | BL5: 0.3108 | BM5: 0.2799 | BN5: 0.3074 | BO5: 0.304 | BP5: 0.304 | BQ5: 0.304 | BR5: 0.304 | BS5: 0.304 | BT5: 0.304 | BU5: 0.304 | BV5: 0.304 | BW5: 0.304 | BX5: 0.305 | BY5: 0.305 | BZ5: 0.305 | CA5: 0.305 | CB5: 0.305 | CC5: 0.305 | CD5: 0.305 | CE5: 0.3 | CF5: 0.3 | CG5: 0.3 | CH5: 0.3 | CI5: 0.287 | CJ5: 0.287 | CK5: 0.287 | CL5: 0.292 | CM5: 0.292
A6: %Dthu Khac | AW6: 0.023 | AX6: 0.023 | AY6: 0.023 | AZ6: 0.023 | BA6: 0.023 | BB6: 0.023 | BC6: 0.023 | BD6: 0.023 | BE6: 0.023 | BF6: 0.023 | BG6: 0.023 | BH6: 0.023 | BI6: 0.023 | BL6: 0.027 | BM6: 0.027 | BN6: 0.027 | BO6: 0.027 | BP6: 0.027 | BQ6: 0.027 | BR6: 0.027 | BS6: 0.027 | BT6: 0.027 | BU6: 0.027 | BV6: 0.027 | BW6: 0.027 | BX6: 0.023 | BY6: 0.023 | BZ6: 0.023 | CA6: 0.023 | CB6: 0.023 | CC6: 0.023 | CD6: 0.023 | CE6: 0.023 | CF6: 0.023 | CG6: 0.023 | CH6: 0.023 | CI6: 0.02 | CJ6: 0.02 | CK6: 0.02 | CL6: 0.02 | CM6: 0.02
A8: Doanh thu TGDD | B8: =B$2*B$3 | C8: =C$2*C$3 | D8: =D$2*D$3 | E8: =E$2*E$3 | F8: =F$2*F$3 | G8: =G$2*G$3 | H8: =H$2*H$3 | I8: =I$2*I$3 | ... M8: =M$2*M$3 | Q8: =Q$2*Q$3 | R8: =R$2*R$3 | S8: =S$2*S$3 | T8: =T$2*T$3 | U8: =U$2*U$3 | V8: =V$2*V$3 | W8: =W$2*W$3 | X8: =X$2*X$3 | ... CM8: =CM$2*CM$3 | CN8: =CN13*CN18*6+(CH8+CI8+CJ8+CK8+CL8+CM8) | CO8: =CO13*CO18*12 | CP8: =CP13*CP18*12
A9: Doanh thu DMX | B9: =B$2*B$4 | C9: =C$2*C$4 | D9: =D$2*D$4 | E9: =E$2*E$4 | F9: =F$2*F$4 | G9: =G$2*G$4 | H9: =H$2*H$4 | I9: =I$2*I$4 | ... CM9: =CM$2*CM$4 | CN9: =CN14*CN19*6+(CH9+CI9+CJ9+CK9+CL9+CM9) | CO9: =CO14*CO19*12 | CP9: =CP14*CP19*12
A10: Doanh thu BHX | B10: =B$2*B$5 | C10: =C$2*C$5 | D10: =D$2*D$5 | E10: =E$2*E$5 | F10: =F$2*F$5 | G10: =G$2*G$5 | H10: =H$2*H$5 | I10: =I$2*I$5 | ... CM10: =CM$2*CM$5 | CN10: =CN15*CN20*6+(CH10+CI10+CJ10+CK10+CL10+CM10) | CO10: =CO15*CO20*12 | CP10: =CP15*CP20*12
A11: Doanh thu Khac | AW11: =AW$2*AW$6 | AX11: =AX$2*AX$6 | AY11: =AY$2*AY$6 | AZ11: =AZ$2*AZ$6 | BA11: =BA$2*BA$6 | BB11: =BB$2*BB$6 | BC11: =BC$2*BC$6 | BD11: =BD$2*BD$6 | ... BI11: =BI$2*BI$6 | BL11: =BL$2*BL$6 | BM11: =BM$2*BM$6 | BN11: =BN$2*BN$6 | BO11: =BO$2*BO$6 | BP11: =BP$2*BP$6 | BQ11: =BQ$2*BQ$6 | BR11: =BR$2*BR$6 | BS11: =BS$2*BS$6 | ... CM11: =CM$2*CM$6 | CN11: =CN16*CN21*6+(CH11+CI11+CJ11+CK11+CL11+CM11) | CO11: =CO16*CO21*12 | CP11: =CP16*CP21*12
A13: SL TGDD | B13: 1029 | C13: 1027 | D13: 1023 | E13: 1021 | F13: 1017 | G13: 1011 | H13: 1006 | I13: 1000 | J13: 1011 | K13: 1009 | L13: 1008 | M13: 996 | Q13: 1003 | R13: 998 | T13: 966 | U13: 964 | V13: 962 | W13: 948 | X13: 933 | AA13: 908 | AB13: 909 | AC13: 923 | AD13: 927 | AE13: 936 | AF13: 949 | AG13: 949 | AH13: 950 | AI13: 958 | AJ13: 966 | AL13: 976 | AM13: 976 | AN13: 985 | AO13: 1012 | AP13: 1040 | AQ13: 1067 | AR13: 1070 | AS13: 1086 | AT13: 1116 | AU13: 1163 | AV13: 1169 | AW13: 1190 | AX13: 1189 | AY13: 1189 | AZ13: 1188 | BA13: 1188 | BB13: 1185 | BC13: 1180 | BD13: 1172 | BE13: 1171 | BF13: 1165 | BG13: 1158 | BH13: 1100 | BI13: 1078 | BJ13: 1077 | BK13: 1077 | BL13: 1071 | BM13: 1071 | BN13: 1070 | BO13: 1046 | BP13: 1028 | BQ13: 1023 | BR13: 1023 | BS13: 1022 | BT13: 1022 | BU13: 1021 | BV13: 1018 | BW13: 1018 | BX13: 1017 | BY13: 1017 | BZ13: 1015 | CA13: 1015 | CB13: 1014 | CC13: 1014 | CD13: 1013 | CE13: 1012 | CF13: 1012 | CG13: 1012 | CH13: 1014 | CI13: 1014 | CJ13: 1014 | CK13: 1012 | CL13: 1012 | CM13: 1008 | CN13: ='02_Assumptions'!G7 | CO13: ='02_Assumptions'!H7 | CP13: ='02_Assumptions'!I7
A14: SL DMX | B14: 764 | C14: 766 | D14: 774 | E14: 791 | F14: 809 | G14: 838 | H14: 865 | I14: 886 | J14: 907 | K14: 937 | L14: 983 | M14: 1018 | N14: 1028 | O14: 1028 | P14: 1030 | Q14: 1031 | R14: 1038 | T14: 1065 | U14: 1083 | V14: 1124 | W14: 1198 | Y14: 1400 | AA14: 1531 | AB14: 1553 | AC14: 1628 | AD14: 1699 | AE14: 1731 | AF14: 1763 | AG14: 1768 | AH14: 1781 | AI14: 1802 | AJ14: 1863 | AL14: 2038 | AM14: 2038 | AN14: 2077 | AO14: 2095 | AP14: 2113 | AQ14: 2131 | AR14: 2185 | AS14: 2222 | AT14: 2246 | AU14: 2269 | AV14: 2277 | AW14: 2284 | AX14: 2287 | AY14: 2287 | AZ14: 2291 | BA14: 2292 | BB14: 2290 | BC14: 2289 | BD14: 2287 | BE14: 2286 | BF14: 2286 | BG14: 2281 | BH14: 2210 | BI14: 2190 | BJ14: 2189 | BK14: 2189 | BL14: 2184 | BM14: 2184 | BN14: 2180 | BO14: 2093 | BP14: 2034 | BQ14: 2031 | BR14: 2030 | BS14: 2030 | BT14: 2030 | BU14: 2026 | BV14: 2027 | BW14: 2027 | BX14: 2027 | BY14: 2025 | BZ14: 2025 | CA14: 2023 | CB14: 2022 | CC14: 2023 | CD14: 2018 | CE14: 2017 | CF14: 2017 | CG14: 2008 | CH14: 2008 | CI14: 2008 | CJ14: 2006 | CK14: 2005 | CL14: 2004 | CM14: 2005 | CN14: ='02_Assumptions'!G8 | CO14: ='02_Assumptions'!H8 | CP14: ='02_Assumptions'!I8
A15: SL BHX | B15: 421 | C15: 423 | D15: 469 | E15: 512 | F15: 545 | G15: 600 | H15: 659 | I15: 725 | J15: 788 | K15: 866 | L15: 938 | M15: 1008 | N15: 1041 | O15: 1068 | P15: 1158 | Q15: 1234 | R15: 1365 | T15: 1561 | U15: 1595 | V15: 1623 | W15: 1656 | X15: 1687 | AA15: 1756 | AB15: 1767 | AC15: 1803 | AD15: 1851 | AE15: 1888 | AF15: 1919 | AG15: 1928 | AH15: 1934 | AI15: 1976 | AJ15: 2026 | AL15: 2122 | AM15: 2122 | AN15: 2127 | AO15: 2140 | AP15: 2014 | AQ15: 1889 | AR15: 1735 | AS15: 1726 | AT15: 1727 | AU15: 1729 | AV15: 1729 | AW15: 1728 | AX15: 1729 | AY15: 1729 | AZ15: 1710 | BA15: 1708 | BB15: 1704 | BC15: 1706 | BD15: 1706 | BE15: 1706 | BF15: 1706 | BG15: 1706 | BH15: 1697 | BI15: 1698 | BJ15: 1698 | BK15: 1698 | BL15: 1696 | BM15: 1696 | BN15: 1698 | BO15: 1701 | BP15: 1704 | BQ15: 1721 | BR15: 1726 | BS15: 1735 | BT15: 1735 | BU15: 1770 | BV15: 1864 | BW15: 1864 | BX15: 2002 | BY15: 2129 | BZ15: 2180 | CA15: 2184 | CB15: 2204 | CC15: 2233 | CD15: 2290 | CE15: 2370 | CF15: 2482 | CG15: 2559 | CH15: 2758 | CI15: 2758 | CJ15: 2839 | CK15: 2962 | CL15: 3051 | CM15: 3191 | CN15: ='02_Assumptions'!G9 | CO15: ='02_Assumptions'!H9 | CP15: ='02_Assumptions'!I9
A16: SL Khac | AL16: 255 | AM16: 255 | AN16: 261 | AO16: 550 | AQ16: 418 | AS16: 589 | AT16: 600 | AU16: 600 | AV16: 573 | AW16: 564 | AX16: 568 | AY16: 568 | AZ16: 574 | BA16: 587 | BB16: 599 | BC16: 603 | BD16: 604 | BE16: 607 | BF16: 607 | BG16: 606 | BH16: 591 | BI16: 629 | BJ16: 643 | BK16: 643 | BL16: 645 | BM16: 646 | BN16: 649 | BO16: 606 | BP16: 516 | BQ16: 460 | BR16: 464 | BS16: 468 | BT16: 470 | BU16: 475 | BV16: 483 | BW16: 483 | BX16: 483 | BY16: 487 | BZ16: 495 | CA16: 503 | CB16: 514 | CC16: 523 | CD16: 558 | CE16: 586 | CF16: 619 | CG16: 646 | CH16: 995 | CI16: 995 | CJ16: 621 | CK16: 559 | CL16: 756 | CM16: 590 | CN16: ='02_Assumptions'!G10 | CO16: ='02_Assumptions'!H10 | CP16: ='02_Assumptions'!I10
A18: DT/CH/th TGDD | B18: =B$8/B$13 | C18: =C$8/C$13 | D18: =D$8/D$13 | E18: =E$8/E$13 | F18: =F$8/F$13 | G18: =G$8/G$13 | H18: =H$8/H$13 | I18: =I$8/I$13 | ... M18: =M$8/M$13 | Q18: =Q$8/Q$13 | R18: =R$8/R$13 | T18: =T$8/T$13 | U18: =U$8/U$13 | V18: =V$8/V$13 | W18: =W$8/W$13 | X18: =X$8/X$13 | AA18: =AA$8/AA$13 | AB18: =AB$8/AB$13 | AC18: =AC$8/AC$13 | AD18: =AD$8/AD$13 | AE18: =AE$8/AE$13 | AF18: =AF$8/AF$13 | AG18: =AG$8/AG$13 | AH18: =AH$8/AH$13 | ... AJ18: =AJ$8/AJ$13 | AL18: =AL$8/AL$13 | AM18: =AM$8/AM$13 | AN18: =AN$8/AN$13 | AO18: =AO$8/AO$13 | AP18: =AP$8/AP$13 | AQ18: =AQ$8/AQ$13 | AR18: =AR$8/AR$13 | AS18: =AS$8/AS$13 | ... CM18: =CM$8/CM$13 | CN18: =AVERAGE(CK18,CL18,CM18) | CO18: =CN18*(1+'02_Assumptions'!$B$17) | CP18: =CO18*(1+'02_Assumptions'!$B$17)
A19: DT/CH/th DMX | B19: =B$9/B$14 | C19: =C$9/C$14 | D19: =D$9/D$14 | E19: =E$9/E$14 | F19: =F$9/F$14 | G19: =G$9/G$14 | H19: =H$9/H$14 | I19: =I$9/I$14 | ... R19: =R$9/R$14 | T19: =T$9/T$14 | U19: =U$9/U$14 | V19: =V$9/V$14 | W19: =W$9/W$14 | Y19: =Y$9/Y$14 | AA19: =AA$9/AA$14 | AB19: =AB$9/AB$14 | AC19: =AC$9/AC$14 | AD19: =AD$9/AD$14 | AE19: =AE$9/AE$14 | AF19: =AF$9/AF$14 | AG19: =AG$9/AG$14 | AH19: =AH$9/AH$14 | ... AJ19: =AJ$9/AJ$14 | AL19: =AL$9/AL$14 | AM19: =AM$9/AM$14 | AN19: =AN$9/AN$14 | AO19: =AO$9/AO$14 | AP19: =AP$9/AP$14 | AQ19: =AQ$9/AQ$14 | AR19: =AR$9/AR$14 | AS19: =AS$9/AS$14 | ... CM19: =CM$9/CM$14 | CN19: =AVERAGE(CK19,CL19,CM19) | CO19: =CN19*(1+'02_Assumptions'!$B$18) | CP19: =CO19*(1+'02_Assumptions'!$B$18)
A20: DT/CH/th BHX | B20: =B$10/B$15 | C20: =C$10/C$15 | D20: =D$10/D$15 | E20: =E$10/E$15 | F20: =F$10/F$15 | G20: =G$10/G$15 | H20: =H$10/H$15 | I20: =I$10/I$15 | ... R20: =R$10/R$15 | T20: =T$10/T$15 | U20: =U$10/U$15 | V20: =V$10/V$15 | W20: =W$10/W$15 | X20: =X$10/X$15 | AA20: =AA$10/AA$15 | AB20: =AB$10/AB$15 | AC20: =AC$10/AC$15 | AD20: =AD$10/AD$15 | AE20: =AE$10/AE$15 | AF20: =AF$10/AF$15 | AG20: =AG$10/AG$15 | AH20: =AH$10/AH$15 | ... AJ20: =AJ$10/AJ$15 | AL20: =AL$10/AL$15 | AM20: =AM$10/AM$15 | AN20: =AN$10/AN$15 | AO20: =AO$10/AO$15 | AP20: =AP$10/AP$15 | AQ20: =AQ$10/AQ$15 | AR20: =AR$10/AR$15 | AS20: =AS$10/AS$15 | ... CM20: =CM$10/CM$15 | CN20: =AVERAGE(CK20,CL20,CM20) | CO20: =CN20*(1+'02_Assumptions'!$B$19) | CP20: =CO20*(1+'02_Assumptions'!$B$19)
A21: DT/CH/th Khac | AW21: =AW$11/AW$16 | AX21: =AX$11/AX$16 | AY21: =AY$11/AY$16 | AZ21: =AZ$11/AZ$16 | BA21: =BA$11/BA$16 | BB21: =BB$11/BB$16 | BC21: =BC$11/BC$16 | BD21: =BD$11/BD$16 | ... BI21: =BI$11/BI$16 | BL21: =BL$11/BL$16 | BM21: =BM$11/BM$16 | BN21: =BN$11/BN$16 | BO21: =BO$11/BO$16 | BP21: =BP$11/BP$16 | BQ21: =BQ$11/BQ$16 | BR21: =BR$11/BR$16 | BS21: =BS$11/BS$16 | ... CM21: =CM$11/CM$16 | CN21: =AVERAGE(CK21,CL21,CM21) | CO21: =CN21*(1+'02_Assumptions'!$B$20) | CP21: =CO21*(1+'02_Assumptions'!$B$20)

Sheet 03_Revenue_Model
A1: Doanh thu theo mảng (tỷ VND) | B1: 2021A | C1: 2022A | D1: 2023A | E1: 2024A | F1: 2025A | G1: 2026E | H1: 2027F | I1: 2028F | J1: Ghi chú
A2: ── TGDD ──
A3: Số cửa hàng cuối kỳ | E3: 1021 | F3: 1012 | G3: ='02_Assumptions'!G7 | H3: ='02_Assumptions'!H7 | I3: ='02_Assumptions'!I7
A4: Hiệu quả DT/CH/tháng (tỷ VND) | G4: ='03a_Monthly_Data'!CN18 | H4: ='03a_Monthly_Data'!CO18 | I4: ='03a_Monthly_Data'!CP18
A5: Doanh thu mảng | D5: 28037 | E5: 30000 | F5: 37300 | G5: ='03a_Monthly_Data'!CN8 | H5: ='03a_Monthly_Data'!CO8 | I5: ='03a_Monthly_Data'!CP8
A6: ── DMX ──
A7: Số cửa hàng cuối kỳ | E7: 2026 | F7: 2008 | G7: ='02_Assumptions'!G8 | H7: ='02_Assumptions'!H8 | I7: ='02_Assumptions'!I8
A8: Hiệu quả DT/CH/tháng (tỷ VND) | G8: ='03a_Monthly_Data'!CN19 | H8: ='03a_Monthly_Data'!CO19 | I8: ='03a_Monthly_Data'!CP19
A9: Doanh thu mảng | D9: 55607 | E9: 59500 | F9: 68400 | G9: ='03a_Monthly_Data'!CN9 | H9: ='03a_Monthly_Data'!CO9 | I9: ='03a_Monthly_Data'!CP9
A10: ── BHX ──
A11: Số cửa hàng cuối kỳ | E11: 1770 | F11: 2559 | G11: ='02_Assumptions'!G9 | H11: ='02_Assumptions'!H9 | I11: ='02_Assumptions'!I9
A12: Hiệu quả DT/CH/tháng (tỷ VND) | G12: ='03a_Monthly_Data'!CN20 | H12: ='03a_Monthly_Data'!CO20 | I12: ='03a_Monthly_Data'!CP20
A13: Doanh thu mảng | D13: 31538 | E13: 41000 | F13: 46900 | G13: ='03a_Monthly_Data'!CN10 | H13: ='03a_Monthly_Data'!CO10 | I13: ='03a_Monthly_Data'!CP10
A14: ── Khac ──
A15: Số cửa hàng cuối kỳ | G15: ='02_Assumptions'!G10 | H15: ='02_Assumptions'!H10 | I15: ='02_Assumptions'!I10
A16: Hiệu quả DT/CH/tháng (tỷ VND) | G16: ='03a_Monthly_Data'!CN21 | H16: ='03a_Monthly_Data'!CO21 | I16: ='03a_Monthly_Data'!CP21
A17: Doanh thu mảng | D17: 3098 | E17: 3841.2 | F17: 3566 | G17: ='03a_Monthly_Data'!CN11 | H17: ='03a_Monthly_Data'!CO11 | I17: ='03a_Monthly_Data'!CP11
A18: TỔNG DOANH THU | B18: =B5+B9+B13+B17 | C18: =C5+C9+C13+C17 | D18: =D5+D9+D13+D17 | E18: =E5+E9+E13+E17 | F18: =F5+F9+F13+F17 | G18: =G5+G9+G13+G17 | H18: =H5+H9+H13+H17 | I18: =I5+I9+I13+I17
A19: Tăng trưởng DT YoY (%) | C19: =IFERROR(C18/B18-1,"") | D19: =IFERROR(D18/C18-1,"") | E19: =IFERROR(E18/D18-1,"") | F19: =IFERROR(F18/E18-1,"") | G19: =IFERROR(G18/F18-1,"") | H19: =IFERROR(H18/G18-1,"") | I19: =IFERROR(I18/H18-1,"")

Sheet 04_PnL
A1: Chỉ tiêu (tỷ VND) | B1: 2021A | C1: 2022A | D1: 2023A | E1: 2024A | F1: 2025A | G1: 2026E | H1: 2027F | I1: 2028F | J1: Ghi chú | K1: 2026 Base (chưa blend quý thực tế)
A2: Doanh thu thuần | B2: 122958.1 | C2: 133404.8 | D2: 118279.8 | E2: 134341.2 | F2: 155928.1 | G2: ='02_Assumptions'!$B$54+K2*(4-'02_Assumptions'!$B$53)/4 | H2: ='03_Revenue_Model'!H18 | I2: ='03_Revenue_Model'!I18 | J2: 2026: đã blend lũy kế quý thực tế + Base (cột bên phải) | K2: ='03_Revenue_Model'!G18
A3: Tăng trưởng YoY (%) | C3: 0.085 | D3: -0.1134 | E3: 0.1358 | F3: 0.1607 | G3: =G2/F2-1 | H3: =H2/G2-1 | I3: =I2/H2-1
A4: Giá vốn hàng bán | B4: -95326 | C4: -102542.7 | D4: -95759.2 | E4: -106841.9 | F4: -124926.3 | G4: ='02_Assumptions'!$B$55+K4*(4-'02_Assumptions'!$B$53)/4 | H4: =-H2*(1-'02_Assumptions'!H23) | I4: =-I2*(1-'02_Assumptions'!I23) | K4: =-K2*(1-'02_Assumptions'!G23)
A5: Lợi nhuận gộp | B5: 27632.1 | C5: 30862.1 | D5: 22520.6 | E5: 27499.3 | F5: 31001.8 | G5: =G2+G4 | H5: =H2+H4 | I5: =I2+I4 | K5: =K2+K4
A6: Biên LNG (%) | B6: 0.2247 | C6: 0.2313 | D6: 0.1904 | E6: 0.2047 | F6: 0.1988 | G6: =G5/G2 | H6: =H5/H2 | I6: =I5/I2
A7: Chi phí bán hàng & QLDN | B7: -21737.6 | C7: -24217.8 | D7: -22084.4 | E7: -23415.6 | F7: -23927 | G7: ='02_Assumptions'!$B$56+K7*(4-'02_Assumptions'!$B$53)/4 | H7: =-H2*'02_Assumptions'!H24 | I7: =-I2*'02_Assumptions'!I24 | K7: =-K2*'02_Assumptions'!G24
A8: EBIT | B8: 5894.5 | C8: 6644.3 | D8: 436.2 | E8: 4083.7 | F8: 7074.8 | G8: =G5+G7 | H8: =H5+H7 | I8: =I5+I7 | K8: =K5+K7
A9: Biên EBIT (%) | B9: 0.0479 | C9: 0.0498 | D9: 0.0037 | E9: 0.0304 | F9: 0.0454 | G9: =G8/G2 | H9: =H8/H2 | I9: =I8/I2
A10: D&A | B10: 2920.7 | C10: 3540.3 | D10: 3351.3 | E10: 2913.4 | F10: 1890.9 | G10: =G2*'02_Assumptions'!$B$33 | H10: =H2*'02_Assumptions'!$B$33 | I10: =I2*'02_Assumptions'!$B$33
A11: EBITDA | B11: 8815.2 | C11: 10184.6 | D11: 3787.5 | E11: 6997.1 | F11: 8965.7 | G11: =G8+G10 | H11: =H8+H10 | I11: =I8+I10
A12: DT/CP tài chính ròng | B12: 573.3 | C12: -69.5 | D12: 610.9 | E12: 1188 | F12: 1564.8 | G12: ='02_Assumptions'!$B$57+K12*(4-'02_Assumptions'!$B$53)/4 | H12: =H2*'02_Assumptions'!$B$26 | I12: =I2*'02_Assumptions'!$B$26 | K12: =K2*'02_Assumptions'!$B$26
A13: Lợi nhuận trước thuế (EBT) | B13: 6471.6 | C13: 6056.4 | D13: 689.7 | E13: 4825.8 | F13: 8633.1 | G13: =G8+G12 | H13: =H8+H12 | I13: =I8+I12 | K13: =K8+K12
A14: Thuế TNDN | B14: 1570.2 | C14: 1954.7 | D14: 521.9 | E14: 1092.5 | F14: 1560.5 | G14: ='02_Assumptions'!$B$59+K14*(4-'02_Assumptions'!$B$53)/4 | H14: =H13*'02_Assumptions'!$B$25 | I14: =I13*'02_Assumptions'!$B$25 | K14: =K13*'02_Assumptions'!$B$25
A15: LNST hợp nhất | B15: 4901.4 | C15: 4101.7 | D15: 167.8 | E15: 3733.3 | F15: 7072.6 | G15: =G13-G14 | H15: =H13-H14 | I15: =I13-I14 | K15: =K13-K14
A16: LNST Cổ đông Công ty mẹ | B16: 4898.9 | C16: 4099.8 | D16: 167.7 | E16: 3721.9 | F16: 7033.7 | G16: ='02_Assumptions'!$B$61+K16*(4-'02_Assumptions'!$B$53)/4 | H16: =H15*0.9957 | I16: =I15*0.9957 | J16: Tỷ lệ phân bổ cổ đông mẹ ~99.6% (TB 2 năm gần nhất); 2026 blend trực tiếp theo LNST mẹ thực tế | K16: =K15*0.9957
A17: EPS (VND/CP) | B17: 6871 | C17: 2800 | D17: 115 | E17: 2546 | F17: 4785 | G17: =G16*1e9/('02_Assumptions'!$B$3*1e6) | H17: =H16*1e9/('02_Assumptions'!$B$3*1e6) | I17: =I16*1e9/('02_Assumptions'!$B$3*1e6)

Sheet 05_Balance_Sheet
A1: Chỉ tiêu (tỷ VND) | B1: 2021A | C1: 2022A | D1: 2023A | E1: 2024A | F1: 2025A | G1: 2026E | H1: 2027F | I1: 2028F | J1: Ghi chú
A2: TÀI SẢN
A3: Tiền & tương đương tiền | B3: 18378.6 | C3: 15130.2 | D3: 24302.7 | E3: 34221.7 | F3: 38874.2 | G3: =F3*(1+'02_Assumptions'!$B$36) | H3: =G3*(1+'02_Assumptions'!$B$36) | I3: =H3*(1+'02_Assumptions'!$B$36)
A4: Hàng tồn kho | B4: 29167.2 | C4: 25696.1 | D4: 21824.2 | E4: 22244.7 | F4: 27266.9 | G4: =-'04_PnL'!G4*'02_Assumptions'!$B$30/365 | H4: =-'04_PnL'!H4*'02_Assumptions'!$B$30/365 | I4: =-'04_PnL'!I4*'02_Assumptions'!$B$30/365
A5: Phải thu khách hàng | B5: 3162.1 | C5: 3000.8 | D5: 5158.9 | E5: 8825.9 | F5: 10182.8 | G5: ='04_PnL'!G2*'02_Assumptions'!$B$31/365 | H5: ='04_PnL'!H2*'02_Assumptions'!$B$31/365 | I5: ='04_PnL'!I2*'02_Assumptions'!$B$31/365
A6: Tài sản khác | B6: 12263.5 | C6: 12007 | D6: 8825.4 | E6: 5145.5 | F6: 7621.7 | G6: ='04_PnL'!G2*0.043590653499396254 | H6: ='04_PnL'!H2*0.043590653499396254 | I6: ='04_PnL'!I2*0.043590653499396254
A7: TỔNG TÀI SẢN | B7: 62971.4 | C7: 55834.1 | D7: 60111.2 | E7: 70437.8 | F7: 83945.6 | G7: =G3+G4+G5+G6 | H7: =H3+H4+H5+H6 | I7: =I3+I4+I5+I6
A9: NGUỒN VỐN
A10: Nợ vay (NH+DH) | B10: 24647.5 | C10: 16589.3 | D10: 25113.7 | E10: 27300.2 | F10: 29930.9 | G10: =F10*(1+'02_Assumptions'!$B$35) | H10: =G10*(1+'02_Assumptions'!$B$35) | I10: =H10*(1+'02_Assumptions'!$B$35)
A11: Phải trả người bán | B11: 12179.8 | C11: 8745.8 | D11: 7927.1 | E11: 9179.6 | F11: 13113.9 | G11: =-'04_PnL'!G4*'02_Assumptions'!$B$32/365 | H11: =-'04_PnL'!H4*'02_Assumptions'!$B$32/365 | I11: =-'04_PnL'!I4*'02_Assumptions'!$B$32/365
A12: Vốn chủ sở hữu | B12: 20378.2 | C12: 23932.6 | D12: 23359.6 | E12: 28121.6 | F12: 33176.1 | G12: =F12+'04_PnL'!G15*(1-'02_Assumptions'!$B$27) | H12: =G12+'04_PnL'!H15*(1-'02_Assumptions'!$B$27) | I12: =H12+'04_PnL'!I15*(1-'02_Assumptions'!$B$27)
A13: Nợ khác (plug cân bằng) | B13: 5765.9 | C13: 6566.4 | D13: 3710.8 | E13: 5836.4 | F13: 7724.7 | G13: =G7-G10-G11-G12 | H13: =H7-H10-H11-H12 | I13: =I7-I10-I11-I12
A14: TỔNG NGUỒN VỐN | B14: 62971.4 | C14: 55834.1 | D14: 60111.2 | E14: 70437.8 | F14: 83945.6 | G14: =G10+G11+G13+G12 | H14: =H10+H11+H13+H12 | I14: =I10+I11+I13+I12
A16: Net Debt (Nợ vay - Tiền mặt) | B16: 6268.9 | C16: 1459.1 | D16: 811 | E16: -6921.5 | F16: -8943.3 | G16: =G10-G3 | H16: =H10-H3 | I16: =I10-I3
A17: D/E (Net Debt/VCSH) | B17: 0.308 | C17: 0.061 | D17: 0.035 | E17: -0.246 | F17: -0.27 | G17: =G16/G12 | H17: =H16/H12 | I17: =I16/I12

Sheet 06_Cash_Flow
A1: Chỉ tiêu (tỷ VND) | B1: 2026E | C1: 2027F | D1: 2028F | E1: Ghi chú
A2: LNST hợp nhất | B2: ='04_PnL'!G15 | C2: ='04_PnL'!H15 | D2: ='04_PnL'!I15
A3: + D&A | B3: ='04_PnL'!G10 | C3: ='04_PnL'!H10 | D3: ='04_PnL'!I10
A4: +/- Thay đổi vốn lưu động | B4: =('05_Balance_Sheet'!F4-'05_Balance_Sheet'!G4)+('05_Balance_Sheet'!F5-'05_Balance_Sheet'!G5)+('05_Balance_Sheet'!G11-'05_Balance_Sheet'!F11) | C4: =('05_Balance_Sheet'!G4-'05_Balance_Sheet'!H4)+('05_Balance_Sheet'!G5-'05_Balance_Sheet'!H5)+('05_Balance_Sheet'!H11-'05_Balance_Sheet'!G11) | D4: =('05_Balance_Sheet'!H4-'05_Balance_Sheet'!I4)+('05_Balance_Sheet'!H5-'05_Balance_Sheet'!I5)+('05_Balance_Sheet'!I11-'05_Balance_Sheet'!H11)
A5: Dòng tiền HĐKD (CFO) | B5: =B2+B3+B4 | C5: =C2+C3+C4 | D5: =D2+D3+D4
A6: CAPEX (CFI) | B6: =-'04_PnL'!G2*'02_Assumptions'!$B$34 | C6: =-'04_PnL'!H2*'02_Assumptions'!$B$34 | D6: =-'04_PnL'!I2*'02_Assumptions'!$B$34
A7: FCFF (CFO+CAPEX) | B7: =B5+B6 | C7: =C5+C6 | D7: =D5+D6
A8: FCF Yield (%) | B8: =B7/'02_Assumptions'!$B$4 | C8: =C7/'02_Assumptions'!$B$4 | D8: =D7/'02_Assumptions'!$B$4

Sheet 07_Valuation
A1: ĐỊNH GIÁ MWG — 4 PHƯƠNG PHÁP TỔNG HỢP (skill ban-le)
A2: Chi phí vốn CSH (COE) | B2: =B28
A3: Tăng trưởng dài hạn (g) | B3: =B29
A5: Phương pháp | B5: Trọng số | C5: Giá mục tiêu (VND)
A6: P/E Median | B6: ='02_Assumptions'!$B$47 | C6: =B20
A7: P/B Median | B7: ='02_Assumptions'!$B$48 | C7: =B25
A8: Residual Income (cả công ty) | B8: ='02_Assumptions'!$B$49 | C8: =B39
A9: P/S+P/E theo mảng (cả 4 mảng) | B9: ='02_Assumptions'!$B$50 | C9: =B47
A11: GIÁ MỤC TIÊU (bình quân trọng số) | C11: =SUMPRODUCT(B6:B9,C6:C9)
A12: Giá hiện tại | C12: ='02_Assumptions'!$B$2
A13: Upside/Downside | C13: =C11/C12-1
A17: 1) P/E MEDIAN (trọng số 20%)
A18: P/E median lịch sử (x) | B18: ='02_Assumptions'!$B$39
A19: EPS 2026E (VND/CP) | B19: ='04_PnL'!G17
A20: → P/E Target Price | B20: =B18*B19
A22: 2) P/B MEDIAN (trọng số 20%)
A23: P/B median lịch sử (x) | B23: ='02_Assumptions'!$B$40
A24: BVPS 2026E (VND/CP) | B24: ='05_Balance_Sheet'!G12*1e9/('02_Assumptions'!$B$3*1e6)
A25: → P/B Target Price | B25: =B23*B24
A27: 3) RESIDUAL INCOME — cả công ty (trọng số 10%)
A28: Chi phí vốn CSH (COE) | B28: ='02_Assumptions'!$B$45
A29: Tăng trưởng dài hạn (g) | B29: ='02_Assumptions'!$B$46
A30: BVPS hiện tại (gốc) | B30: ='05_Balance_Sheet'!F12*1e9/('02_Assumptions'!$B$3*1e6)
A31: EPS dự phóng 3 năm (VND) | B31: ='04_PnL'!G17 | C31: ='04_PnL'!H17 | D31: ='04_PnL'!I17
A32: BVPS đầu kỳ mỗi năm (VND) | B32: =B30 | C32: =B32+B31*(1-'02_Assumptions'!$B$27) | D32: =C32+C31*(1-'02_Assumptions'!$B$27)
A33: Capital Charge (BVPS đầu kỳ × COE) | B33: =B32*$B$28 | C33: =C32*$B$28 | D33: =D32*$B$28
A34: Residual Income (EPS - Capital Charge) | B34: =B31-B33 | C34: =C31-C33 | D34: =D31-D33
A35: PV of RI | B35: =B34/(1+$B$28)^1 | C35: =C34/(1+$B$28)^2 | D35: =D34/(1+$B$28)^3
A36: Tổng PV(RI) | B36: =SUM(B35:D35)
A37: Continuing Value (CV) | B37: =D34*(1+$B$29)/($B$28-$B$29)
A38: PV of CV | B38: =B37/(1+$B$28)^3
A39: → RI Target Price | B39: =B30+B36+B38
A41: 4) P/S + P/E theo mảng (trọng số 50%) — P/E: TGDĐ/ĐMX/Khác | P/S: BHX
A42: Mảng | B42: Phương pháp | C42: DT 2026E (tỷ) | D42: Biên LNST (%) | E42: P/E hoặc P/S áp dụng (x) | F42: Giá trị mảng (tỷ)
A43: TGDD | B43: P/E | C43: ='03_Revenue_Model'!G5 | D43: 0.045 | E43: 10 | F43: =C43*D43*E43
A44: DMX | B44: P/E | C44: ='03_Revenue_Model'!G9 | D44: 0.04 | E44: 15 | F44: =C44*D44*E44
A45: BHX | B45: P/S | C45: ='03_Revenue_Model'!G13 | E45: 0.85 | F45: =C45*E45
A46: Khac | B46: P/E | C46: ='03_Revenue_Model'!G17 | D46: 0.01 | E46: 12 | F46: =C46*D46*E46
A47: → P/S+P/E Target Price (tổng giá trị mảng / SL CP) | B47: =(F43+F44+F45+F46)*1e9/('02_Assumptions'!$B$3*1e6)

Sheet 08_Sensitivity
A1: MA TRẬN NHẠY CẢM: P/E × EPS 2026E
A2: P/E \ EPS | B2: ='07_Valuation'!$B$19*(1+-0.1) | C2: ='07_Valuation'!$B$19*(1+-0.05) | D2: ='07_Valuation'!$B$19*(1+0) | E2: ='07_Valuation'!$B$19*(1+0.05) | F2: ='07_Valuation'!$B$19*(1+0.1)
A3: ='07_Valuation'!$B$18+-2 | B3: =$A3*B$2 | C3: =$A3*C$2 | D3: =$A3*D$2 | E3: =$A3*E$2 | F3: =$A3*F$2
A4: ='07_Valuation'!$B$18+-1 | B4: =$A4*B$2 | C4: =$A4*C$2 | D4: =$A4*D$2 | E4: =$A4*E$2 | F4: =$A4*F$2
A5: ='07_Valuation'!$B$18+0 | B5: =$A5*B$2 | C5: =$A5*C$2 | D5: =$A5*D$2 | E5: =$A5*E$2 | F5: =$A5*F$2
A6: ='07_Valuation'!$B$18+1 | B6: =$A6*B$2 | C6: =$A6*C$2 | D6: =$A6*D$2 | E6: =$A6*E$2 | F6: =$A6*F$2
A7: ='07_Valuation'!$B$18+2 | B7: =$A7*B$2 | C7: =$A7*C$2 | D7: =$A7*D$2 | E7: =$A7*E$2 | F7: =$A7*F$2
A10: MA TRẬN NHẠY CẢM: P/B × BVPS 2026E
A11: P/B \ BVPS | B11: ='07_Valuation'!$B$24*(1+-0.1) | C11: ='07_Valuation'!$B$24*(1+-0.05) | D11: ='07_Valuation'!$B$24*(1+0) | E11: ='07_Valuation'!$B$24*(1+0.05) | F11: ='07_Valuation'!$B$24*(1+0.1)
A12: ='07_Valuation'!$B$23+-0.5 | B12: =$A12*B$11 | C12: =$A12*C$11 | D12: =$A12*D$11 | E12: =$A12*E$11 | F12: =$A12*F$11
A13: ='07_Valuation'!$B$23+-0.25 | B13: =$A13*B$11 | C13: =$A13*C$11 | D13: =$A13*D$11 | E13: =$A13*E$11 | F13: =$A13*F$11
A14: ='07_Valuation'!$B$23+0 | B14: =$A14*B$11 | C14: =$A14*C$11 | D14: =$A14*D$11 | E14: =$A14*E$11 | F14: =$A14*F$11
A15: ='07_Valuation'!$B$23+0.25 | B15: =$A15*B$11 | C15: =$A15*C$11 | D15: =$A15*D$11 | E15: =$A15*E$11 | F15: =$A15*F$11
A16: ='07_Valuation'!$B$23+0.5 | B16: =$A16*B$11 | C16: =$A16*C$11 | D16: =$A16*D$11 | E16: =$A16*E$11 | F16: =$A16*F$11

Sheet 09_PESTLE
A1: Yếu tố | B1: Nội dung | C1: Tác động | D1: Mức độ
A2: Political | B2: Nhà nước kiểm soát chặt giá thuốc (An Khang) và an toàn thực phẩm (BHX); chính sách thuế VAT hàng điện máy/ICT ổn định, không có thay đổi lớn gần đây. | C2: Trung tính — không có rủi ro chính sách đột biến trong ngắn hạn. | D2: Trung tính
A3: Economic | B3: Sức mua hồi phục sau giai đoạn khó khăn 2022-2023 (lãi suất cao, thất nghiệp), CPI ổn định quanh 3-4%/năm hỗ trợ tiêu dùng không thiết yếu (ICT/điện máy) tăng trở lại. | C3: Tích cực — SSSG TGDĐ/ĐMX +33% (5T2026) phản ánh sức mua phục hồi rõ rệt. | D3: Tích cực
A4: Social | B4: Xu hướng mua sắm hiện đại hoá (siêu thị mini, tiện lợi) thay thế chợ truyền thống hỗ trợ BHX; tầng lớp trung lưu tăng thúc đẩy nhu cầu điện thoại/laptop cao cấp hơn. | C4: Tích cực — dư địa dài hạn cho BHX thay thế kênh GT truyền thống. | D4: Tích cực
A5: Technological | B5: Chu kỳ nâng cấp iPhone/Samsung, xu hướng AI trên thiết bị di động thúc đẩy nhu cầu thay máy; MWG đầu tư Super App/thanh toán trả chậm để tăng biên lợi nhuận dịch vụ tài chính. | C5: Tích cực — doanh thu Super App/trả chậm tăng trưởng 2 chữ số. | D5: Tích cực
A6: Legal | B6: Yêu cầu hoá đơn điện tử/truy xuất nguồn gốc thực phẩm ngày càng chặt với BHX/An Khang — chi phí tuân thủ tăng nhưng cũng là rào cản gia nhập với đối thủ nhỏ lẻ. | C6: Trung tính — chi phí tuân thủ tăng nhẹ, bù lại bằng lợi thế quy mô. | D6: Trung tính
A7: Environmental | B7: Áp lực giảm rác thải nhựa/bao bì tại chuỗi BHX, yêu cầu chuỗi lạnh (cold chain) tiêu tốn năng lượng cho hàng tươi sống — chi phí vận hành có thể tăng theo quy định môi trường mới. | C7: Tiêu cực nhẹ — chi phí tuân thủ môi trường tăng dần theo thời gian. | D7: Tiêu cực

Sheet 10_Leading_Indicators
A1: Chỉ báo | B1: Ngưỡng tích cực | C1: Ngưỡng tiêu cực | D1: Giá trị hiện tại | E1: Trạng thái
A2: SSSG (tăng trưởng cửa hàng hiện hữu) | B2: > 10% | C2: < 0% | D2: 33% | E2: Tích cực
A3: Tăng trưởng DT YoY 5T2026 | B3: > 15% | C3: < 5% | D3: 29.3% | E3: Tích cực
A4: Số cửa hàng BHX mở mới/năm | B4: > 800 | C4: < 300 | D4: ~632/5T | E4: Tích cực
A5: Biên LNG (%) | B5: > 20% | C5: < 17% | D5: 20.8% | E5: Tích cực
A6: SG&A/DT (%) | B6: < 14% | C6: > 17% | D6: 14.5% | E6: Theo dõi
A7: Tỷ trọng DT online/tổng | B7: > 12% | C7: < 8% | D7: ~11% | E7: Trung tính
A8: Chu kỳ iPhone mới (tháng 9 hàng năm) | B8: Ra mắt đúng hẹn | C8: Trì hoãn/thiếu hàng | D8: Đang chuẩn bị (T9/2026) | E8: Theo dõi
A9: CPI Việt Nam YoY | B9: 2-4% | C9: > 5% hoặc < 0% | D9: ~3.5% | E9: Tích cực

Sheet 11_Investment_Thesis
A1: Tầng đánh giá | B1: Kết luận | C1: Rating
A2: 1. Mô hình kinh doanh | B2: Nhà bán lẻ đa ngành lớn nhất VN (ICT/điện máy qua TGDĐ+ĐMX, FMCG qua BHX), tận dụng quy mô mạng lưới >6.700 cửa hàng để đàm phán giá tốt với NCC và phủ khắp thị trường. | C2: Tốt
A3: 2. Vị thế cạnh tranh | B3: TGDĐ/ĐMX dẫn đầu thị phần ICT/điện máy VN; BHX đứng đầu chuỗi bán lẻ FMCG hiện đại về quy mô cửa hàng, đang mở rộng nhanh và đã có lãi từ 2023. | C3: Tốt
A4: 3. Sức khoẻ tài chính | B4: Đòn bẩy thấp, xu hướng nợ vay giảm/tiền mặt tăng nhờ FCF chuyển dương khi BHX hoà vốn; biên LNG ổn định quanh 20-21%. | C4: Tốt
A5: 4. Định giá | B5: Giá mục tiêu bình quân trọng số 100,016 VND, upside 33.0% so với giá hiện tại 75,200 VND — định giá hợp lý, không quá đắt so với median lịch sử. | C5: Trung lập-Tốt
A6: 5. Chất lượng ban lãnh đạo | B6: Lịch sử liên tục vượt kế hoạch kinh doanh tự đề ra nhiều năm liền (thận trọng khi đặt mục tiêu đầu năm); minh bạch công bố KQKD hàng tháng qua IR — hiếm có ở DN bán lẻ VN. | C6: Tốt
A7: 6. Rủi ro & Catalyst | B7: Rủi ro: TGDĐ/ĐMX đã bão hòa khó tăng trưởng thêm; BHX vẫn cần chứng minh duy trì lãi bền vững khi mở rộng nhanh. Catalyst: chu kỳ iPhone mới, BHX đạt quy mô lãi ổn định, EraBlue nhân rộng quốc tế. | C7: Theo dõi

Sheet 12_Summary_Snapshot
A1: Chỉ tiêu | B1: 2021A | C1: 2022A | D1: 2023A | E1: 2024A | F1: 2025A | G1: 2026E | H1: 2027F | I1: 2028F | J1: CAGR 3Y
A2: Doanh thu thuần | B2: 122958.1 | C2: 133404.8 | D2: 118279.8 | E2: 134341.2 | F2: 155928.1 | G2: ='04_PnL'!G2 | H2: ='04_PnL'!H2 | I2: ='04_PnL'!I2 | J2: =(I2/F2)^(1/2)-1
A3: Lợi nhuận gộp | B3: 27632.1 | C3: 30862.1 | D3: 22520.6 | E3: 27499.3 | F3: 31001.8 | G3: ='04_PnL'!G5 | H3: ='04_PnL'!H5 | I3: ='04_PnL'!I5 | J3: =(I3/F3)^(1/2)-1
A4: EBITDA | B4: 8815.2 | C4: 10184.6 | D4: 3787.5 | E4: 6997.1 | F4: 8965.7 | G4: ='04_PnL'!G11 | H4: ='04_PnL'!H11 | I4: ='04_PnL'!I11 | J4: =(I4/F4)^(1/2)-1
A5: LNST Cổ đông Công ty mẹ | B5: 4898.9 | C5: 4099.8 | D5: 167.7 | E5: 3721.9 | F5: 7033.7 | G5: ='04_PnL'!G16 | H5: ='04_PnL'!H16 | I5: ='04_PnL'!I16 | J5: =(I5/F5)^(1/2)-1
A6: EPS (VND) | B6: 6871 | C6: 2800 | D6: 115 | E6: 2546 | F6: 4785 | G6: ='04_PnL'!G17 | H6: ='04_PnL'!H17 | I6: ='04_PnL'!I17 | J6: =(I6/F6)^(1/2)-1
A7: CAPEX | B7: 4976.9 | C7: 4465.4 | D7: 523.4 | E7: 303.7 | F7: 888.5 | G7: =-'06_Cash_Flow'!B6 | H7: =-'06_Cash_Flow'!C6 | I7: =-'06_Cash_Flow'!D6
A8: Net Debt | B8: 6268.9 | C8: 1459.1 | D8: 811 | E8: -6921.5 | F8: -8943.3 | G8: ='05_Balance_Sheet'!G16 | H8: ='05_Balance_Sheet'!H16 | I8: ='05_Balance_Sheet'!I16
A9: Vốn chủ sở hữu | B9: 20378.2 | C9: 23932.6 | D9: 23359.6 | E9: 28121.6 | F9: 33176.1 | G9: ='05_Balance_Sheet'!G12 | H9: ='05_Balance_Sheet'!H12 | I9: ='05_Balance_Sheet'!I12 | J9: =(I9/F9)^(1/2)-1
A11: ROE (%) | B11: =B5/B9 | C11: =C5/C9 | D11: =D5/D9 | E11: =E5/E9 | F11: =F5/F9 | G11: =G5/G9 | H11: =H5/H9 | I11: =I5/I9
A12: P/E (x) | B12: ='02_Assumptions'!$B$2*'02_Assumptions'!$B$3/(B5*1000) | C12: ='02_Assumptions'!$B$2*'02_Assumptions'!$B$3/(C5*1000) | D12: ='02_Assumptions'!$B$2*'02_Assumptions'!$B$3/(D5*1000) | E12: ='02_Assumptions'!$B$2*'02_Assumptions'!$B$3/(E5*1000) | F12: ='02_Assumptions'!$B$2*'02_Assumptions'!$B$3/(F5*1000) | G12: ='02_Assumptions'!$B$2*'02_Assumptions'!$B$3/(G5*1000) | H12: ='02_Assumptions'!$B$2*'02_Assumptions'!$B$3/(H5*1000) | I12: ='02_Assumptions'!$B$2*'02_Assumptions'!$B$3/(I5*1000)
A13: P/B (x) | B13: =('02_Assumptions'!$B$2*'02_Assumptions'!$B$3/1000)/B9 | C13: =('02_Assumptions'!$B$2*'02_Assumptions'!$B$3/1000)/C9 | D13: =('02_Assumptions'!$B$2*'02_Assumptions'!$B$3/1000)/D9 | E13: =('02_Assumptions'!$B$2*'02_Assumptions'!$B$3/1000)/E9 | F13: =('02_Assumptions'!$B$2*'02_Assumptions'!$B$3/1000)/F9 | G13: =('02_Assumptions'!$B$2*'02_Assumptions'!$B$3/1000)/G9 | H13: =('02_Assumptions'!$B$2*'02_Assumptions'!$B$3/1000)/H9 | I13: =('02_Assumptions'!$B$2*'02_Assumptions'!$B$3/1000)/I9

Sheet 13_PE_PB_History
A1: Quý | B1: P/E (x) | C1: P/B (x) | D1: EV/EBITDA (x)
A2: 2018Q1 | B2: 14.72 | C2: 5.16 | D2: 10.96
A3: 2018Q2 | B3: 12.62 | C3: 4.6 | D3: 8.96
A4: 2018Q3 | B4: 12.97 | C4: 4.54 | D4: 8.57
A5: 2018Q4 | B5: 13.08 | C5: 4.19 | D5: 8.09
A6: 2019Q1 | B6: 14.45 | C6: 4.59 | D6: 9.78
A7: 2019Q2 | B7: 16.04 | C7: 5.39 | D7: 10.87
A8: 2019Q3 | B8: 14.32 | C8: 4.75 | D8: 9.91
A9: 2019Q4 | B9: 9.36 | C9: 3.02 | D9: 6.69
A10: 2020Q1 | B10: 8.43 | C10: 2.52 | D10: 6.16
A11: 2020Q2 | B11: 12.24 | C11: 3.25 | D11: 8.13
A12: 2020Q3 | B12: 15.6 | C12: 4.03 | D12: 10.1
A13: 2020Q4 | B13: 16.3 | C13: 4.3 | D13: 10.44
... A22: 2023Q2 | B22: 45.28 | C22: 3.05 | D22: 13.98
A23: 2023Q3 | C23: 2.63 | D23: 16.92
A24: 2023Q4 | C24: 3.26 | D24: 25.51
A25: 2024Q1 | C25: 3.75 | D25: 24.97
A26: 2024Q2 | B26: 42.21 | C26: 3.56 | D26: 18.84
A27: 2024Q3 | B27: 28.21 | C27: 3.11 | D27: 14.82
A28: 2024Q4 | B28: 22.44 | C28: 3.01 | D28: 14.01
A29: 2025Q1 | B29: 23.18 | C29: 3.46 | D29: 17.14
A30: 2025Q2 | B30: 25.48 | C30: 4.2 | D30: 20.37
A31: 2025Q3 | B31: 21.6 | C31: 4.02 | D31: 19.1
A32: 2025Q4 | B32: 16.75 | C32: 3.6 | D32: 15.73
A33: 2026Q1 | B33: 13.83 | C33: 3.2 | D33: 13.52
A34: 2026Q2 | B34: 13.55 | C34: 3.14 | D34: 13.29
A36: MEDIAN (loại quý bất thường P/E>50x hoặc ≤0) | B36: =MEDIAN(B2:B34) | C36: =MEDIAN(C2:C34) | D36: =MEDIAN(D2:D34)
A38: Ghi chú: MEDIAN ở dòng trên tính trên TOÀN BỘ quý có dữ liệu (đã loại quý bất thường P/E>50x hoặc ≤0). Đây CHÍNH LÀ số P/E Median/P/B Median dùng để định giá ở 02_Assumptions (liên kết công thức trực tiếp về đúng dòng MEDIAN này) — sửa/thêm dữ liệu quý ở bảng trên sẽ tự động cập nhật giá mục tiêu, không có phép tính nào khác ẩn ở nơi khác.

Sheet 14_Quarterly_Ratios
A1: Quý | B1: Doanh thu | C1: LNG | D1: LNST | E1: Biên LNG (%) | F1: Biên LNST (%) | G1: ROE (quy đổi năm) | H1: Tăng trưởng LNG YoY (%) | I1: Tăng trưởng LNST YoY (%)
A2: 2018Q1 | B2: 22763.5 | C2: 3974.8 | D2: 807.4 | E2: 0.1746 | F2: 0.0355 | G2: 0.4443
A3: 2018Q2 | B3: 21806.9 | C3: 3861.6 | D3: 732 | E3: 0.1771 | F3: 0.0336 | G3: 0.3961
A4: 2018Q3 | B4: 20907.6 | C4: 3702.6 | D4: 647.4 | E4: 0.1771 | F4: 0.031 | G4: 0.3303
A5: 2018Q4 | B5: 21038.3 | C5: 3753.2 | D5: 692 | E5: 0.1784 | F5: 0.0329 | G5: 0.3229
A6: 2019Q1 | B6: 25017.4 | C6: 4433.8 | D6: 1040.4 | E6: 0.1772 | F6: 0.0416 | G6: 0.4381 | H6: 0.1155 | I6: 0.2887
A7: 2019Q2 | B7: 26603.8 | C7: 4748.4 | D7: 1079.2 | E7: 0.1785 | F7: 0.0406 | G7: 0.4222 | H7: 0.2296 | I7: 0.4744
A8: 2019Q3 | B8: 25142.1 | C8: 4940.6 | D8: 855.1 | E8: 0.1965 | F8: 0.034 | G8: 0.3149 | H8: 0.3344 | I8: 0.3209
A9: 2019Q4 | B9: 25411 | C9: 5365 | D9: 859.6 | E9: 0.2111 | F9: 0.0338 | G9: 0.2935 | H9: 0.4294 | I9: 0.2421
A10: 2020Q1 | B10: 29353.2 | C10: 6160 | D10: 1131.5 | E10: 0.2099 | F10: 0.0385 | G10: 0.3547 | H10: 0.3893 | I10: 0.0875
A11: 2020Q2 | B11: 26285.6 | C11: 5770.1 | D11: 893.9 | E11: 0.2195 | F11: 0.034 | G11: 0.2586 | H11: 0.2152 | I11: -0.1717
A12: 2020Q3 | B12: 25713.6 | C12: 5749.7 | D12: 950.5 | E12: 0.2236 | F12: 0.037 | G12: 0.2578 | H12: 0.1638 | I12: 0.1116
A13: 2020Q4 | B13: 27193.7 | C13: 6274.7 | D13: 941.8 | E13: 0.2307 | F13: 0.0346 | G13: 0.2454 | H13: 0.1696 | I13: 0.0957
A14: 2021Q1 | B14: 30828.1 | C14: 7024.9 | D14: 1338 | E14: 0.2279 | F14: 0.0434 | G14: 0.33 | H14: 0.1404 | I14: 0.1825
A15: 2021Q2 | B15: 31658.4 | C15: 7143.6 | D15: 1213 | E15: 0.2256 | F15: 0.0383 | G15: 0.2756 | H15: 0.238 | I15: 0.357
A16: 2021Q3 | B16: 24333.2 | C16: 6088.7 | D16: 785.4 | E16: 0.2502 | F16: 0.0323 | G16: 0.1695 | H16: 0.059 | I16: -0.1737
A17: 2021Q4 | B17: 36138.3 | C17: 7374.9 | D17: 1562.5 | E17: 0.2041 | F17: 0.0432 | G17: 0.319 | H17: 0.1753 | I17: 0.659
... A34: 2026Q1 | B34: 46462 | C34: 9710.1 | D34: 2714.4 | E34: 0.209 | F34: 0.0584 | G34: 0.3142 | H34: 0.3486 | I34: 0.7558

Sheet 15_Asset_Quality
A1: Chỉ tiêu kiểm tra | B1: Giá trị/So sánh | C1: Đánh giá
A2: Phải thu KH tăng nhanh hơn Doanh thu | B2: Phải thu +15.4% vs DT +16.1% | C2: Bình thường
A3: Hàng tồn kho tăng nhanh hơn Doanh thu | B3: Tồn kho +22.6% vs DT +16.1% | C3: Bình thường
A4: DIO (số ngày tồn kho) xu hướng quý gần nhất | B4: 68 ngày (quý 2026Q1) vs 72 ngày (4 quý trước) | C4: Bình thường
A5: Net Debt (Nợ vay - Tiền mặt) | B5: -8,943 tỷ (net cash dương) | C5: Bình thường
