Workbook

Sheet 00_TongQuan
A1: NT2 — CTCP Điện lực Dầu khí Nhơn Trạch 2
A2: Ngành: Nhiệt điện (Thermal Power Generation)
A3: Ngày lập báo cáo: 2026-07-12
A5: Giá thị trường hiện tại (VND/cp) | B5: 21800
A6: Số lượng cổ phiếu lưu hành (cp) | B6: 287876029 | C6: =Vốn điều lệ (bsa80, năm gần nhất) / 10.000 VND mệnh giá
A7: Vốn hóa thị trường (tỷ VND) | B7: =B5*B6/1000000000
A9: TÓM TẮT ĐỊNH GIÁ
A10: Phương pháp | B10: Trọng số | C10: Fair Value (VND/cp) | D10: Nguồn công thức
A11: DCF (FCFF chiết khấu WACC) | B11: 0.5 | C11: ='05_DinhGia'!$C$4
A12: EV/EBITDA (peer median) | B12: 0.2 | C12: ='05_DinhGia'!$C$5
A13: P/B (peer median) | B13: 0.15 | C13: ='05_DinhGia'!$C$6
A14: Asset-based (Book Value of Equity) | B14: 0.15 | C14: ='05_DinhGia'!$C$7
A15: FAIR VALUE BLEND | B15: =SUMPRODUCT(B11:B14,C11:C14)
A16: Upside/Downside so với giá hiện tại | B16: =B15/B5-1

Sheet 01_LichSuTaiChinh
A1: NT2 — Lịch sử tài chính (tỷ VND, nguồn Vietcap)
A3: Chỉ tiêu | B3: 2021 | C3: 2022 | D3: 2023 | E3: 2024 | F3: 2025 | G3: Nguồn/Ghi chú
A4: Doanh thu thuần (isa3) | B4: 6149.58 | C4: 8787.69 | D4: 6385.88 | E4: 5943.68 | F4: 7958.22 | H4: Vietcap — BCTC hợp nhất
A5: Giá vốn hàng bán (isa4) | B5: 5473.78 | C5: 7706.17 | D5: 5875.59 | E5: 5892.17 | F5: 6710.41 | H5: Vietcap
A6: Lợi nhuận gộp (isa5) | B6: 675.81 | C6: 1081.53 | D6: 510.29 | E6: 51.51 | F6: 1247.81 | H6: Vietcap
A7: CP bán hàng + QLDN (isa9+isa10, ÂM) | B7: -82.92 | C7: -131.43 | D7: -69 | E7: -81.17 | F7: -84.91 | H7: Vietcap — đã âm sẵn
A8: EBIT (= LN gộp + CP bán hàng+QLDN, đã âm) | B8: =B6+B7 | C8: =C6+C7 | D8: =D6+D7 | E8: =E6+E7 | F8: =F6+F7 | H8: CÔNG THỨC — KHÔNG dùng isa11 (đã trừ lãi vay, xem project_fcf)
A9: Biên EBIT (%) | B9: =B8/B4 | C9: =C8/C4 | D9: =D8/D4 | E9: =E8/E4 | F9: =F8/F4 | H9: =EBIT / Doanh thu
A10: Biên lợi nhuận gộp (%) | B10: =B6/B4 | C10: =C6/C4 | D10: =D6/D4 | E10: =E6/E4 | F10: =F6/F4 | H10: =LN gộp / Doanh thu
A11: Khấu hao (cfa2) | B11: 690.46 | C11: 688.84 | D11: 687.21 | E11: 687.07 | F11: 556.35 | H11: Vietcap — Báo cáo LCTT
A12: EBITDA (= EBIT + Khấu hao) | B12: =B8+B11 | C12: =C8+C11 | D12: =D8+D11 | E12: =E8+E11 | F12: =F8+F11 | H12: CÔNG THỨC
A13: CAPEX (cfa19, trị tuyệt đối) | B13: 2.53 | C13: 1.46 | D13: 3.41 | E13: 3.56 | F13: 9.17 | H13: Vietcap — Báo cáo LCTT
A14: Chi phí lãi vay (isa8, trị tuyệt đối) | B14: 20.35 | C14: 15.37 | D14: 33.84 | E14: 34.93 | F14: 64.69 | H14: Vietcap
A15: LNST cổ đông công ty mẹ (isa22) | B15: 533.79 | C15: 883.42 | D15: 473.08 | E15: 82.89 | F15: 1130.28 | H15: Vietcap
A16: Biên LNST (%) | B16: =B15/B4 | C16: =C15/C4 | D16: =D15/D4 | E16: =E15/E4 | F16: =F15/F4 | H16: =LNST mẹ / Doanh thu
A17: VCSH thuộc cổ đông mẹ (bsa78-bsa210) | B17: 4233.57 | C17: 4613.84 | D17: 4335.85 | E17: 4189.08 | F17: 4859.4 | H17: Vietcap — Bảng CĐKT
A18: Tổng nợ vay (bsa56+bsa71) | B18: 210 | C18: 630.51 | D18: 1200 | E18: 996.39 | F18: 1762.31 | H18: Vietcap
A19: Tiền và tương đương tiền (bsa2) | B19: 0.99 | C19: 384.3 | D19: 1.15 | E19: 56.96 | F19: 22.3 | H19: Vietcap
A20: ROE (= LNST mẹ / VCSH mẹ) | B20: =B15/B17 | C20: =C15/C17 | D20: =D15/D17 | E20: =E15/E17 | F20: =F15/F17 | H20: CÔNG THỨC

Sheet 02_WACC_DCF
A1: NT2 — WACC & Định giá DCF
A3: ① CHI PHÍ VỐN (WACC)
A4: Lãi suất phi rủi ro Rf | B4: 0.045 | C4: Nguồn: investing.com VN 10Y bond yield / worldgovernmentbonds.com
A5: Beta (β) | B5: 0.8397 | C5: Tự tính hồi quy giá CP vs VNINDEX (≥250 phiên) hoặc Vietstock/Vietcap API
A6: Phần bù rủi ro thị trường (ERP) | B6: 0.07 | C6: Giả định chuẩn thị trường VN (~7%/năm)
A7: Chi phí vốn CSH (COE = Rf + β×ERP) | B7: =B4+B5*B6
A8: Nợ vay năm 2025 (tỷ VND) | B8: ='01_LichSuTaiChinh'!F18
A9: Chi phí lãi vay năm 2025 (tỷ VND) | B9: ='01_LichSuTaiChinh'!F14
A10: Chi phí nợ vay (COD = Lãi vay / Nợ vay, kẹp [2%,12%]) | B10: =MAX(0.02,MIN(0.12,B9/MAX(B8,1)))
A11: Thuế suất TNDN | B11: 0.2
A12: Vốn hóa thị trường (tỷ VND) | B12: ='00_TongQuan'!$B$5*'00_TongQuan'!$B$6/1000000000
A13: Tỷ trọng vốn CSH (E/(D+E)) | B13: =B12/(B12+B8)
A14: Tỷ trọng nợ vay (D/(D+E)) | B14: =1-B13
A15: WACC = we×COE + wd×COD×(1-thuế), sàn 8%/trần 18% | B15: =MAX(0.08,MIN(0.18,B13*B7+B14*B10*(1-B11)))
A17: ② GIẢ ĐỊNH DỰ PHÓNG (từ mô hình kinh doanh — không phải ước lượng tùy ý)
A18: Tăng trưởng doanh thu dài hạn (CAGR lịch sử, kẹp [-5%,+15%]) | B18: 0.066577834 | C18: CAGR doanh thu 5 năm lịch sử ('01_LichSuTaiChinh')
A19: Biên EBIT dự phóng (TB 2-3 năm gần nhất) | B19: 0.070080158
A20: Khấu hao / Doanh thu (TB lịch sử) | B20: 0.096757014
A21: CAPEX / Doanh thu (TB lịch sử) | B21: 0.00057232
A22: ⚠ Năm 2026 đã có 1/4 quý báo cáo thực tế (lũy kế DT=2172 tỷ). Bảng dự phóng bên dưới dùng công thức THUẦN (Doanh thu năm trước × (1+g)) để giữ minh bạch/dễ kiểm tra công thức — số Fair Value công bố trên PDF/web có thể lệch nhẹ vì đã BLEND thêm lũy kế thực tế của năm 2026 (xem blend_annual_estimate trong code).
A24: ③ DỰ PHÓNG FCFF 5 NĂM (công thức sống)
A25: Chỉ tiêu | B25: Năm +1 | C25: Năm +2 | D25: Năm +3 | E25: Năm +4 | F25: Năm +5
A26: Doanh thu (tỷ VND) | B26: ='01_LichSuTaiChinh'!F4*(1+B18) | C26: =B26*(1+B18) | D26: =C26*(1+B18) | E26: =D26*(1+B18) | F26: =E26*(1+B18)
A27: EBIT (= Doanh thu × Biên EBIT) | B27: =B26*B19 | C27: =C26*B19 | D27: =D26*B19 | E27: =E26*B19 | F27: =F26*B19
A28: NOPAT (= EBIT × (1-thuế)) | B28: =B27*(1-B11) | C28: =C27*(1-B11) | D28: =D27*(1-B11) | E28: =E27*(1-B11) | F28: =F27*(1-B11)
A29: Khấu hao (= Doanh thu × %DT) | B29: =B26*B20 | C29: =C26*B20 | D29: =D26*B20 | E29: =E26*B20 | F29: =F26*B20
A30: CAPEX (= Doanh thu × %DT) | B30: =B26*B21 | C30: =C26*B21 | D30: =D26*B21 | E30: =E26*B21 | F30: =F26*B21
A31: FCFF (= NOPAT + Khấu hao - CAPEX) | B31: =B28+B29-B30 | C31: =C28+C29-C30 | D31: =D28+D29-D30 | E31: =E28+E29-E30 | F31: =F28+F29-F30
A32: PV(FCFF) chiết khấu về hiện tại ở WACC | B32: =B31/(1+$B$15)^1 | C32: =C31/(1+$B$15)^2 | D32: =D31/(1+$B$15)^3 | E32: =E31/(1+$B$15)^4 | F32: =F31/(1+$B$15)^5
A34: ④ TERMINAL VALUE (trung bình Gordon-growth + Exit-multiple)
A35: Tăng trưởng dài hạn g_term (=40% growth ngắn hạn, kẹp [0%,3%]) | B35: =MAX(0,MIN(0.03,B18*0.4))
A36: Terminal Value (Gordon-growth) = FCFF cuối×(1+g)/(WACC-g) | B36: =F31*(1+B35)/MAX(B15-B35,0.03)
A37: EV/EBITDA mục tiêu (peer median — xem sheet 03) | B37: ='03_PeerComps_EV_PE_PB'!$B$3
A38: EBITDA năm cuối dự phóng (= EBIT + Khấu hao) | B38: =F27+F29
A39: Terminal Value (Exit-multiple) = EBITDA cuối × EV/EBITDA mục tiêu | B39: =B38*B37
A40: Terminal Value (trung bình 2 phương pháp) | B40: =AVERAGE(B36,B39)
A41: PV(Terminal Value) | B41: =B40/(1+B15)^5
A43: ⑤ TỪ ENTERPRISE VALUE RA FAIR VALUE/CP
A44: Enterprise Value (= ΣPV(FCFF) + PV(Terminal Value)) | B44: =SUM(B32:F32)+B41
A45: Nợ vay ròng năm 2025 (= Nợ vay - Tiền mặt) | B45: ='01_LichSuTaiChinh'!F18-'01_LichSuTaiChinh'!F19
...

Sheet 03_PeerComps_EV_PE_PB
A1: So sánh tương quan nhóm Nhiệt điện (POW/NT2/PPC/QTP)
A3: MEDIAN CẢ NHÓM (target multiple áp dụng đồng nhất — không tự đặt biên số)
B4: EV/EBITDA | C4: P/B | D4: P/E
A5: MEDIAN | B5: =MEDIAN(B6:B9) | C5: =MEDIAN(C6:C9) | D5: =MEDIAN(D6:D9)
A6: Mã | B6: EV/EBITDA | C6: P/B | D6: P/E | E6: Năm BC | F6: Giá (VND) | G6: Vốn hóa (tỷ)
A7: POW | B7: 10.09 | C7: 1.15 | D7: 16.19 | E7: 2025 | F7: 14100 | G7: 39294.2
A8: NT2 | B8: 4.66 | C8: 1.29 | D8: 5.69 | E8: 2025 | F8: 21800 | G8: 6275.7
A9: PPC | B9: 13.37 | C9: 0.67 | D9: 17.94 | E9: 2025 | F9: 9240 | G9: 3014.4
A10: QTP | B10: 2.61 | C10: 0.87 | D10: 4.95 | E10: 2025 | F10: 11400 | G10: 5130
A12: Nguồn: Vietcap BCTC hợp nhất kỳ báo cáo gần nhất mỗi mã + giá thị trường hiện tại — tính P/E=Giá/EPS, P/B=Giá/BVPS, EV/EBITDA=(Vốn hóa+Nợ vay ròng)/EBITDA.

Sheet 04_GiaNhienLieu
A1: Giá nhiên liệu đầu vào & tỷ giá (tham chiếu rủi ro)
A3: Chỉ tiêu | B3: Giá trị | C3: Đơn vị | D3: Nguồn
A4: Giá than nhiệt (Newcastle coal) | B4: 110 | C4: USD/tấn | D4: Fallback (manual)
A5: Giá khí tự nhiên (Henry Hub) | B5: 3 | C5: USD/MMBtu | D5: Fallback (manual)
A6: Giá dầu thô (Brent) | B6: 75 | C6: USD/thùng | D6: Fallback (manual)
A7: Tỷ giá USD/VND | B7: 26200 | C7: VND/USD | D7: Fallback (manual)
A9: Lưu ý (tài liệu hướng dẫn mục 6.2): than tăng 20% → LNST giảm ước 30-40%; khí đắt hơn than nên nhà máy khí (NT2) nhạy cảm hơn với giá LNG/Henry Hub.

Sheet 05_DinhGia
A1: NT2 — Định giá kết hợp: DCF 50% + EV/EBITDA 20% + P/B 15% + Asset 15%
A3: Phương pháp | B3: Trọng số | C3: Fair Value (VND/cp) | D3: Ghi chú
A4: DCF (FCFF chiết khấu WACC) | B4: 0.5 | C4: ='02_WACC_DCF'!$B$47 | D4: Terminal Value = TB(Gordon-growth, Exit-multiple EV/EBITDA)
A5: EV/EBITDA (peer median) | B5: 0.2 | C5: =('03_PeerComps_EV_PE_PB'!$B$3*'02_WACC_DCF'!$B$27+'03_PeerComps_EV_PE_PB'!$B$3*'02_WACC_DCF'!$B$29-'02_WACC_DCF'!$B$45)*1000000000/'00_TongQuan'!$B$6 | D5: =(EV/EBITDA mục tiêu × EBITDA năm+1 - Nợ vay ròng) × 1 tỷ / Số CP
A6: P/B (peer median) | B6: 0.15 | C6: ='02_WACC_DCF'!$B$50 | D6: =BVPS hiện tại × P/B mục tiêu (peer median)
A7: Asset-based (Book Value of Equity) | B7: 0.15 | C7: ='02_WACC_DCF'!$B$51 | D7: =BVPS mẹ hiện tại (bsa78-bsa210)/CP — sàn giá trị thanh lý
A8: FAIR VALUE BLEND | B8: =SUM(B4:B7) | C8: =SUMPRODUCT(B4:B7,C4:C7)
A9: Giá thị trường hiện tại | C9: ='00_TongQuan'!$B$5
A10: Upside/Downside | C10: =C8/C9-1
