Workbook

Sheet Kinh doanh
B3: 2019 | C3: =B3+1 -> 2020 | D3: =C3+1 -> 2021 | E3: =D3+1 -> 2022 | F3: =E3+1 -> 2023 | G3: 2024 | H3: 2025 | L3: 2020 | M3: =L3+1 -> 2021 | N3: =M3+1 -> 2022 | O3: =N3+1 -> 2023 | P3: =O3+1 -> 2024 | Q3: 2025 | S3: Q1 | T3: Q2
A4: Tiền | B4: 3115237 | C4: 7347857 | D4: 4142016 | E4: 5061021 | F4: 5365705 | G4: 4897332 | H4: 4999925 | K4: Dòng tiền SXKD | L4: 10792 | M4: 171 | N4: 7976 | O4: 3436 | P4: 8517 | Q4: =SUM(S4:T4)*2 -> 7866 | S4: 2490 | T4: 1443
A5: DTTC | B5: 3137000 | C5: 8057319 | D5: 14236626 | E5: 10069250 | F5: 18937008 | G5: 29324442 | H5: 33874270 | K5: Dòng tiền DT | L5: -8574 | M5: -11255 | N5: 1549 | O5: -10831 | P5: -11743 | Q5: =SUM(S5:T5)*2 -> -14512 | S5: -3698 | T5: -3558
A6: PTNH | B6: 1815086 | C6: 1595251 | D6: 3162122 | E6: 3000817 | F6: 5158853 | G6: 8825896 | H6: 10153065 | K6: Dòng tiền TC | L6: 2014 | M6: 7877 | N6: -8606 | O6: 7700 | P6: 2757 | Q6: =SUM(S6:T6)*2 -> 8912 | S6: -1031 | T6: 5487
A7: HTK | B7: 25745428 | C7: 19422177 | D7: 29167232 | E7: 25696078 | F7: 21824236 | G7: 22244676 | H7: 27266851 | K7: RÒng | L7: =SUM(L4:L6) -> 4232 | M7: =SUM(M4:M6) -> -3207 | N7: =SUM(N4:N6) -> 919 | O7: =SUM(O4:O6) -> 305 | P7: =SUM(P4:P6) -> -469 | Q7: =SUM(Q4:Q6) -> 2266
A8: DTTC DH | H8: 3136315
A9: Nợ vay NH | B9: 13031016 | C9: 15625180 | D9: 24647474 | E9: 10688139 | F9: 19128542 | G9: 27300247 | H9: 29930942
A10: Nợ vay DH | B10: 1122137 | C10: 1126677 | E10: 5901250 | F10: 5985250
A11: VCSH | B11: 12143592 | C11: 15481690 | D11: 20378246 | E11: 23932582 | F11: 23359558 | G11: 28121576 | H11: 33179015
A13: Tỉ lệ nợ vay | B13: =(B10+B9)/B11 -> 1.1654832 | C13: =(C10+C9)/C11 -> 1.0820432 | D13: =(D10+D9)/D11 -> 1.2094993 | E13: =(E10+E9)/E11 -> 0.69317172 | F13: =(F10+F9)/F11 -> 1.0750971 | G13: =(G10+G9)/G11 -> 0.97079364 | H13: =(H10+H9)/H11 -> 0.9021046
A14: Tỉ lệ nợ vay ròng | B14: =(B10+B9-B4-B5)/B11 -> 0.6506243 | C14: =(C10+C9-C4-C5)/C11 -> 0.0869854 | D14: =(D10+D9-D4-D5)/D11 -> 0.30762373 | E14: =(E10+E9-E4-E5)/E11 -> 0.060967847 | F14: =(F10+F9-F4-F5)/F11 -> 0.034721505 | G14: =(G10+G9-G4-G5-G8)/G11 -> -0.2461287 | H14: =(H10+H9-H4-H5-H8)/H11 -> -0.36407253
L15: =L27/L21 -> 0.12887089 | M15: =M27/M21 -> 0.13461264 | N15: =N27/N21 -> 0.14597308 | O15: =O27/O21 -> 0.15662341 | P15: =P27/P21 -> 0.13770309 | Q15: =Q27/Q21 -> 0.14038735 | R15: =R27/R21 -> 0.17549807 | S15: =S27/S21 -> 0.13428978 | ... AH15: =AH27/AH21 -> 0.11469374
B16: =(B5+B6+C5+C6)/2 -> 7302328 | C16: =(C5+C6+D5+D6)/2 -> 13525659 | D16: =(D5+D6+E5+E6)/2 -> 15234408 | E16: =(E5+E6+F5+F6)/2 -> 18582964 | F16: =(F5+F6+G5+G6)/2 -> 31123100 | G16: =(G6+G5+I5+I6)/2 -> 19075169 | L16: =L28/L21 -> 0.026564652 | M16: =M28/M21 -> 0.038068246 | N16: =N28/N21 -> 0.032680692 | O16: =O28/O21 -> 0.028818891 | P16: =P28/P21 -> 0.035304295 | Q16: =Q28/Q21 -> 0.037949223 | R16: =R28/R21 -> 0.040076198 | S16: =S28/S21 -> 0.01842807 | ... AH16: =AH28/AH21 -> 0.028088923
B17: =C24/B16 -> 0.10874916 | C17: =D24/C16 -> 0.095223161 | D17: =E24/D16 -> 0.086195476 | E17: =F24/E16 -> 0.11661025 | F17: =G24/F16 -> 0.07635818 | G17: =H24/G16 -> 0.16290487
B19: =(B24-B25)/B30*0.8 -> 0.012815582 | C19: =(C24-C25)/C30*0.8 -> 0.040833454 | D19: =(D24-D25)/D30*0.8 -> 0.093613281 | E19: =(E24-E25)/E30*0.8 -> -0.013558442 | F19: =(F24-F25)/F30*0.8 -> 2.9143992 | G19: =(G24-G25)/G30*0.8 -> 0.25462634 | H19: =(H24-H25)/H30*0.8 -> 0.17763242 | I19: =(I24-I25)/I30*0.8 -> 0.15819397
B20: 2019 | C20: =B20+1 -> 2020 | D20: =C20+1 -> 2021 | E20: =D20+1 -> 2022 | F20: =E20+1 -> 2023 | G20: 2024 | H20: 2025 | I20: 2026 | L20: Q1-2020 | M20: Q2-2020 | N20: Q3-2020 | O20: Q4-2020 | P20: Q1-2021 | Q20: Q2-2021 | R20: Q3-2021 | S20: Q4-2021 | T20: Q1-2022 | U20: Q2-2022 | V20: Q3-2022 | W20: Q4-2022 | X20: Q1-2023 | Y20: Q2-2023 | Z20: Q3-2023 | AA20: Q4-2023 | AB20: Q1-2024 | AC20: Q2-2024 | AD20: Q3-2024 | AE20: Q4-2024 | AF20: Q1-2025 | AG20: Q2-2025 | AH20: Q3-2025 | AI20: Q4-2025
A21: Doanh thu | B21: 102174244 | C21: 108546020 | D21: 122958106 | E21: 133404778 | F21: 118279788 | G21: =SUM(AB21:AE21) -> 1.3434115e+08 | H21: =SUM(AF21:AI21) -> 156457826 | I21: ='Diễn biến'!AJ14*1000 -> 172760000 | K21: Doanh thu | L21: 29353213 | M21: 26285559 | N21: 25713554 | O21: 27193693 | P21: 30828144 | Q21: 31658419 | R21: 24333214 | S21: 36138330 | T21: 36466677 | U21: 34337740 | V21: 32011980 | W21: 30588381 | X21: 27105812 | Y21: 29464830 | Z21: 30287657 | AA21: 31421489 | AB21: 31486492 | AC21: 34134072 | AD21: 34146669 | AE21: 34573921 | AF21: 36134958 | AG21: 37619969 | AH21: 39852507 | AI21: 42850392
A22: Giá vốn | B22: 82686445 | C22: 84591522 | D22: 95325974 | E22: 102542735 | F22: 95759175 | G22: =SUM(AB22:AE22) -> 1.0684194e+08 | H22: =SUM(AF22:AI22) -> 126164283 | K22: Giá vốn | L22: 23193243 | M22: 20515417 | N22: 19963834 | O22: 20919028 | P22: 23803198 | Q22: 24514835 | R22: 18244500 | S22: 28763440 | T22: 28342413 | U22: 27001322 | V22: 24619955 | W22: 22658872 | X22: 21891312 | Y22: 24023662 | Z22: 25644730 | AA22: 25235028 | AB22: 24773876 | AC22: 26826358 | AD22: 27254758 | AE22: 27986952 | AF22: 28934548 | AG22: 30051268 | AH22: 32374320 | AI22: 34804147
A23: LNG | B23: 19487799 | C23: 23954497 | D23: 27632132 | E23: 30862042 | F23: 22520613 | G23: =SUM(AB23:AE23) -> 27499210 | H23: =SUM(AF23:AI23) -> 30293542 | I23: =I21*I44 -> 35415800 | K23: LNG | L23: 6159970.4 | M23: 5770141.8 | N23: 5749720 | O23: 6274665.1 | P23: 7024945.6 | Q23: 7143583.4 | R23: 6088713.3 | S23: 7374889.7 | T23: 8124264.1 | U23: 7336418.2 | V23: 7392024.4 | W23: 7929508.7 | X23: 5214499.9 | Y23: 5441168 | Z23: 4642927.7 | AA23: 6186460.5 | AB23: 6712616.1 | AC23: 7307714 | AD23: 6891911 | AE23: 6586969 | AF23: 7200411 | AG23: 7568701 | AH23: 7478186 | AI23: 8046244
A24: DTTC | B24: 631178 | C24: 794122 | D24: 1287956 | E24: 1313137 | F24: 2166964 | G24: =SUM(AB24:AE24) -> 2376503.2 | H24: =SUM(AF24:AI24) -> 3107438 | I24: =(H5+H8)*5% -> 1850529.2 | K24: DTTC | L24: 124886.15 | M24: 169372.88 | N24: 256718.66 | O24: 243144.09 | P24: 288290.51 | Q24: 304726.4 | R24: 288605.72 | S24: 384466.25 | T24: 354859.21 | U24: 297757.55 | V24: 348740.4 | W24: 311780.14 | X24: 359084.89 | Y24: 585368.72 | Z24: 619115.61 | AA24: 603394.49 | AB24: 585309.45 | AC24: 580108.78 | AD24: 575389 | AE24: 635696 | AF24: 693294 | AG24: 768832 | AH24: 809068 | AI24: 836244
A25: CPTC | B25: 569755 | C25: 594152 | D25: 714707 | E25: 1382620 | F25: 1556146 | G25: =SUM(AB25:AE25) -> 1188466 | H25: =SUM(AF25:AI25) -> 1542517 | K25: CPTC | L25: 178248.21 | M25: 137081.24 | N25: 132146.27 | O25: 146675.8 | P25: 152802.4 | Q25: 170842.22 | R25: 164678.84 | S25: 225421.69 | T25: 206279.13 | U25: 360157.35 | V25: 434637.15 | W25: 381546.83 | X25: 295779.23 | Y25: 396875.09 | Z25: 444911.06 | AA25: 418580.73 | AB25: 375235.77 | AC25: 293717.25 | AD25: 330441 | AE25: 189072 | AF25: 339023 | AG25: 402454 | AH25: 410743 | AI25: 390297
A26: CPLV | B26: 568137 | C26: 594004 | D26: 674428 | E26: 1362144 | F26: 1447718 | G26: =SUM(AB26:AE26) -> 1137235.6 | H26: =SUM(AF26:AI26) -> 1470674 | K26: CPLV | L26: 178228.12 | M26: 136986.55 | N26: 132177.34 | O26: 146611.81 | P26: 152706.97 | Q26: 169881.59 | R26: 163932.69 | S26: 187425.45 | T26: 200473.74 | U26: 365962.74 | V26: 434637.15 | W26: 361070.28 | X26: 295778.73 | Y26: 384520.98 | Z26: 438383.49 | AA26: 329035.16 | AB26: 266979.95 | AC26: 243089.63 | AD26: 303696 | AE26: 323470 | AF26: 322793 | AG26: 375178 | AH26: 388038 | AI26: 384665
A27: CPBH | B27: 12437283 | C27: 15333799 | D27: 17914173 | E27: 22336838 | F27: 20916711 | G27: =SUM(AB27:AE27) -> 19849837 | H27: =SUM(AF27:AI27) -> 18619233 | I27: =I46*I21 -> 20731200 | K27: CPBH | L27: 3782774.6 | M27: 3538368.4 | N27: 3753486.7 | O27: 4259169.1 | P27: 4245130.6 | Q27: 4444441.4 | R27: 4270432 | S27: 4853008.4 | T27: 5036030.6 | U27: 5070491.1 | V27: 5342606.3 | W27: 6603486.4 | X27: 4784685.9 | Y27: 5211133.5 | Z27: 4278767.1 | AA27: 5607079.6 | AB27: 4821343.3 | AC27: 5056436.1 | AD27: 4848950 | AE27: 5123108 | AF27: 4403006 | AG27: 4703283 | AH27: 4570833 | AI27: 4942111
A28: QLDN | B28: 2073783 | C28: 3404432 | D28: 3823390 | E28: 1881028 | F28: 1167652 | G28: =SUM(AB28:AE28) -> 3565768 | H28: =SUM(AF28:AI28) -> 4596074 | I28: =I47*I21 -> 4837280 | K28: QLDN | L28: 779757.89 | M28: 1000645.1 | N28: 840336.74 | O28: 783692.08 | P28: 1088365.9 | Q28: 1201412.4 | R28: 975182.68 | S28: 665959.68 | T28: 1239442.4 | U28: 500331.31 | V28: 316220.81 | W28: 292045.06 | X28: 324692.29 | Y28: 229156.81 | Z28: 341530.62 | AA28: 300975.91 | AB28: 868456.24 | AC28: 813335.77 | AD28: 967619 | AE28: 916357 | AF28: 1214600 | AG28: 1201666 | AH28: 1119414 | AI28: 1060394
A29: LNTT | B29: 5053447 | C29: 5409735 | D29: 6471584 | E29: 6056355 | F29: 689692 | G29: =SUM(AB29:AE29) -> 4825762.4 | H29: =SUM(AF29:AI29) -> 8636401 | I29: =I23+I24-I25-I27-I28 -> 11697849 | K29: LNTT | L29: 1544061.3 | M29: 1253662.4 | N29: 1278279.9 | O29: 1333731.8 | P29: 1827568.9 | Q29: 1625970.5 | R29: 968131.16 | S29: 2049913.1 | T29: 2002993.6 | U29: 1702143.3 | V29: 1417840.1 | W29: 933378.27 | X29: 158966.58 | Y29: 129784.48 | Z29: 182016.09 | AA29: 218925.22 | AB29: 1206203.3 | AC29: 1516043.1 | AD29: 1068045 | AE29: 1035471 | AF29: 1934661 | AG29: 2028205 | AH29: 2172351 | AI29: 2501184
A30: LNST | B30: 3834270 | C30: 3917768 | D30: 4898869 | E30: 4099763 | F30: 167669 | G30: =SUM(AB30:AE30) -> 3732645.1 | H30: =SUM(AF30:AI30) -> 7047907 | I30: =I29*0.8 -> 9358279.4 | K30: LNST | L30: 1131519 | M30: 893911.69 | N30: 950539.86 | O30: 941797.23 | P30: 1337968.6 | Q30: 1213029.7 | R30: 785385.4 | S30: 1562485.6 | T30: 1444465.3 | U30: 1130011 | V30: 906246 | W30: 619040.75 | X30: 21281.314 | Y30: 17413.949 | Z30: 38739.226 | AA30: 90257.558 | AB30: 902437.17 | AC30: 1172276.9 | AD30: 805787 | AE30: 852144 | AF30: 1547834 | AG30: 1657529 | AH30: 1770898 | AI30: 2071646
A32: Lợi nhuận tài chính | B32: =B24-B25 -> 61423 | C32: =C24-C25 -> 199970 | D32: =D24-D25 -> 573249 | E32: =E24-E25 -> -69483 | F32: =F24-F25 -> 610818 | G32: =G24-G25 -> 1188037.2 | H32: =H24-H25 -> 1564921
A33: Hiệu suất LN | B33: =B32/(B5+B8) -> 0.019580172 | C33: =C32/(C5+C8) -> 0.024818429 | D33: =D32/(D5+D8) -> 0.040265791 | E33: =E32/(E5+E8) -> -0.0069005139 | F33: =F32/(F5+F8) -> 0.032255254 | G33: =G32/(G5+G8) -> 0.040513549 | H33: =H32/(H5+H8) -> 0.042283066
A34: Tỷ trọng trong LN tổng | B34: =B32/(B23+B24-B25) -> 0.0031419665 | C34: =C32/(C23+C24-C25) -> 0.0082787999 | D34: =D32/(D23+D24-D25) -> 0.020324101 | E34: =E32/(E23+E24-E25) -> -0.0022564867 | F34: =F32/(F23+F24-F25) -> 0.026406408 | G34: =G32/(G23+G24-G25) -> 0.041413427 | H34: =H32/(H23+H24-H25) -> 0.049121045
A36: Lỗ BHX | B36: 978365 | C36: 1733535 | D36: 966454 | E36: 2961477 | F36: 1256523 | K36: Lỗ BHX | T36: =U36/2 -> 716129.5 | U36: 1432259 | V36: 2246267 | W36: 2744058 | X36: 353723 | Y36: 658659 | Z36: 904910 | AA36: 1210999 | AB36: 105382 | AC36: 98402 | AD36: 8433 | AE36: -102738 | AF36: 1733535 | AG36: 1535418
A37: Lỗ An Khang | B37: 5947 | C37: 6437 | E37: 306214 | F37: 342942 | K37: Lỗ An Khang | T37: =W37/4 -> 76553.5 | U37: =W37/4*2 -> 153107 | V37: =W37/4*3 -> 229660.5 | W37: 306214 | X37: 74283 | Y37: 150561 | Z37: 234417 | AA37: 342942 | AB37: 69758 | AC37: 172128 | AD37: 320612 | AE37: 346722 | AF37: =1033530-1002316 -> 31214 | AG37: 57288 | AH37: 85157 | AI37: 112959
A38: TỔNG | B38: =SUM(B36:B37) -> 984312 | C38: =SUM(C36:C37) -> 1739972 | D38: =SUM(D36:D37) -> 966454 | E38: =SUM(E36:E37) -> 3267691 | F38: =SUM(F36:F37) -> 1599465 | K38: TỔNG số lũy kế
B40: =B30+B38 -> 4818582 | C40: =C30+C38 -> 5657740 | D40: =D30+D38 -> 5865323 | E40: =E30+E38 -> 7367454 | F40: =F30+F38 -> 1767134
A41: ROE | B41: =B30/B11 -> 0.3157443 | C41: =C30/(B11+C11)*2 -> 0.28363642 | D41: =D30/(C11+D11)*2 -> 0.27322241 | E41: =E30/(D11+E11)*2 -> 0.18504565 | F41: =F30/(E11+F11)*2 -> 0.0070907766 | G41: =G30/(F11+G11)*2 -> 0.14501021 | H41: =H30/(G11+H11)*2 -> 0.22994581 | I41: =I30/H11 -> 0.28205417 | K41: Lỗ BHX | T41: =T36 -> 716129.5 | U41: =U36-T36 -> 716129.5 | V41: =V36-U36 -> 814008 | W41: =W36-V36 -> 497791 | X41: =X36 -> 353723 | Y41: =Y36-X36 -> 304936 | Z41: =Z36-Y36 -> 246251 | AA41: =AA36-Z36 -> 306089 | AB41: =AB36 -> 105382 | AC41: =AC36-AB36 -> -6980 | AD41: =AD36-AC36 -> -89969 | AE41: =AE36-AD36 -> -111171 | AF41: =1733535-1733535 -> 0 | AG41: =AG36-AF36 -> -198117 | AH41: -306793.5 | AI41: -207735
K42: Lỗ An Khang | T42: =T37 -> 76553.5 | U42: =U37-T37 -> 76553.5 | V42: =V37-U37 -> 76553.5 | W42: =W37-V37 -> 76553.5 | X42: =X37 -> 74283 | Y42: =Y37-X37 -> 76278 | Z42: =Z37-Y37 -> 83856 | AA42: =AA37-Z37 -> 108525 | AB42: =AB37 -> 69758 | AC42: =AC37-AB37 -> 102370 | AD42: =AD37-AC37 -> 148484 | AE42: =AE37-AD37 -> 26110 | AF42: 31214 | AG42: =AG37-AF37 -> 26074 | AH42: =AH37-AG37 -> 27869 | AI42: =AI37-AH37 -> 27802
K43: TỔNG | T43: =SUM(T41:T42) -> 792683 | U43: =SUM(U41:U42) -> 792683 | V43: =SUM(V41:V42) -> 890561.5 | W43: =SUM(W41:W42) -> 574344.5 | X43: =SUM(X41:X42) -> 428006 | Y43: =SUM(Y41:Y42) -> 381214 | Z43: =SUM(Z41:Z42) -> 330107 | AA43: =SUM(AA41:AA42) -> 414614 | ... AI43: =SUM(AI41:AI42) -> -179933
A44: Biên LNG | B44: =B23/B21 -> 0.19073103 | C44: =C23/C21 -> 0.22068517 | D44: =D23/D21 -> 0.22472802 | E44: =E23/E21 -> 0.23134135 | F44: =F23/F21 -> 0.1904012 | G44: =G23/G21 -> 0.20469684 | H44: 0.205 | I44: 0.205 | K44: Biên LNG | L44: =L23/L21 -> 0.20985677 | M44: =M23/M21 -> 0.21951756 | N44: =N23/N21 -> 0.22360659 | O44: =O23/O21 -> 0.23073972 | P44: =P23/P21 -> 0.22787443 | Q44: =Q23/Q21 -> 0.22564561 | R44: =R23/R21 -> 0.25022233 | S44: =S23/S21 -> 0.20407389 | ... AI44: =AI23/AI21 -> 0.18777527
A45: Biên LNR | B45: =B30/B21 -> 0.037526776 | C45: =C30/C21 -> 0.036093152 | D45: =D30/D21 -> 0.039841773 | E45: =E30/E21 -> 0.030731755 | F45: =F30/F21 -> 0.0014175626 | G45: =G30/G21 -> 0.027784822 | K45: Biên LNR | L45: =L30/L21 -> 0.038548386 | M45: =M30/M21 -> 0.034007711 | N45: =N30/N21 -> 0.036966491 | O45: =O30/O21 -> 0.034632928 | P45: =P30/P21 -> 0.043400881 | Q45: =Q30/Q21 -> 0.03831618 | R45: =R30/R21 -> 0.032276271 | S45: =S30/S21 -> 0.043236242 | ... AI45: =AI30/AI21 -> 0.048346022
A46: Tỉ lệ CPBH | B46: =B27/B21 -> 0.12172621 | C46: =C27/C21 -> 0.14126542 | D46: =D27/D21 -> 0.14569331 | E46: =E27/E21 -> 0.16743657 | F46: =F27/F21 -> 0.17684096 | G46: =G27/G21 -> 0.14775694 | H46: 0.13 | I46: 0.12 | K46: Tỉ lệ CPBH | L46: =L27/L21 -> 0.12887089 | M46: =M27/M21 -> 0.13461264 | N46: =N27/N21 -> 0.14597308 | O46: =O27/O21 -> 0.15662341 | P46: =P27/P21 -> 0.13770309 | Q46: =Q27/Q21 -> 0.14038735 | R46: =R27/R21 -> 0.17549807 | S46: =S27/S21 -> 0.13428978 | ... AI46: =AI27/AI21 -> 0.11533409
A47: Tỉ lệ QLDN | B47: =B28/B21 -> 0.020296534 | C47: =C28/C21 -> 0.031363951 | D47: =D28/D21 -> 0.031095063 | E47: =E28/E21 -> 0.014100155 | F47: =F28/F21 -> 0.0098719487 | G47: =G28/G21 -> 0.026542634 | H47: 0.032 | I47: 0.028 | K47: Tỉ lệ QLDN | L47: =L28/L21 -> 0.026564652 | M47: =M28/M21 -> 0.038068246 | N47: =N28/N21 -> 0.032680692 | O47: =O28/O21 -> 0.028818891 | P47: =P28/P21 -> 0.035304295 | Q47: =Q28/Q21 -> 0.037949223 | R47: =R28/R21 -> 0.040076198 | S47: =S28/S21 -> 0.01842807 | ... AI47: =AI28/AI21 -> 0.024746425
...

Sheet Diễn biến
A4: Doanh thu | B4: 22763.52 | C4: 21806.934 | D4: 20907.583 | E4: 21038.251 | F4: 25017.41 | G4: 26603.759 | H4: 25142.086 | I4: 25410.989 | J4: 29353.213 | K4: 26285.559 | L4: 25713.554 | M4: 27193.693 | N4: 30828.144 | O4: 31658.419 | P4: 24333.214 | Q4: 36138.33 | R4: 36466.677 | S4: 34337.74 | T4: 32011.98 | U4: 30588.381 | V4: 27335.087 | W4: 29725.047 | X4: 30287.657 | Y4: 31421.489 | Z4: 31486.492 | AA4: 34134.072 | AB4: =99767-Z4-AA4 -> 34146.437 | AC4: 34573 | AD4: 36134 | AE4: 37619 | AF4: ='Kinh doanh'!AH21/1000 -> 39852.507 | AG4: 42850
A5: LNG | B5: 3974.7634 | C5: 3861.6416 | D5: 3702.5512 | E5: 3753.1716 | F5: 4433.7779 | G5: 4748.4172 | H5: 4940.557 | I5: 5365.0472 | J5: 6159.9704 | K5: 5770.1418 | L5: 5749.72 | M5: 6274.6651 | N5: 7024.9456 | O5: 7143.5834 | P5: 6088.7133 | Q5: 7374.8897 | R5: 8124.2641 | S5: 7336.4182 | T5: 7392.0244 | U5: 7929.5087 | V5: 5214.4999 | W5: 5441.168 | X5: 4642.9277 | Y5: 6186.4605 | Z5: 6712.6161 | AA5: 7307.714 | AB5: 6891 | AC5: 6586 | AD5: 7200 | AE5: 7568 | AF5: ='Kinh doanh'!AH23/1000 -> 7478.186 | AG5: ='Kinh doanh'!AI23/1000 -> 8046.244
A6: LNST | B6: 807.36427 | C6: 731.96838 | D6: 647.36535 | E6: 692.02613 | F6: 1040.4408 | G6: 1079.1785 | H6: 855.08093 | I6: 859.56933 | J6: 1131.519 | K6: 893.91169 | L6: 950.53986 | M6: 941.79723 | N6: 1337.9686 | O6: 1213.0297 | P6: 785.3854 | Q6: 1562.4856 | R6: 1444.4653 | S6: 1130.011 | T6: 906.246 | U6: 619.04075 | V6: 21.266944 | W6: 17.405666 | X6: 38.739226 | Y6: 90.257558 | Z6: 902.43717 | AA6: 1172.2769 | AB6: 805 | AC6: 852 | AD6: 1547 | AE6: 1657 | AF6: ='Kinh doanh'!AH30/1000 -> 1770.898 | AG6: ='Kinh doanh'!AI30/1000 -> 2071.646
A7: Tăng trưởng doanh thu | F7: =F4/B4-1 -> 0.099013243 | G7: =G4/C4-1 -> 0.21996789 | H7: =H4/D4-1 -> 0.20253433 | I7: =I4/E4-1 -> 0.20784706 | J7: =J4/F4-1 -> 0.17331146 | K7: =K4/G4-1 -> -0.011960714 | L7: =L4/H4-1 -> 0.022729536 | M7: =M4/I4-1 -> 0.070154842 | ... AG7: =AG4/AC4-1 -> 0.23940647
A8: Tăng trưởng LNST | F8: =F6/B6-1 -> 0.28868815 | G8: =G6/C6-1 -> 0.47435128 | H8: =H6/D6-1 -> 0.32086299 | I8: =I6/E6-1 -> 0.2421053 | J8: =J6/F6-1 -> 0.087538133 | K8: =K6/G6-1 -> -0.17167395 | L8: =L6/H6-1 -> 0.11163731 | M8: =M6/I6-1 -> 0.095661743 | ... Y8: =Y6/U6-1 -> -0.85419771 | AD8: =AD6/Z6-1 -> 0.71424677 | AE8: =AE6/AA6-1 -> 0.41348856 | AF8: =AF6/AB6-1 -> 1.1998733 | AG8: =AG6/AC6-1 -> 1.4315094
A10: Tỉ trọng doanh thu | B10: Q1-2018 | C10: Q2-2018 | D10: Q3-2018 | E10: Q4-2018 | F10: Q1-2019 | G10: Q2-2019 | H10: Q3-2019 | I10: Q4-2019 | J10: Q1-2020 | K10: Q2-2020 | L10: Q3-2020 | M10: Q4-2020 | N10: Q1-2021 | O10: Q2-2021 | P10: Q3-2021 | Q10: Q4-2021 | R10: Q1-2022 | S10: Q2-2022 | T10: Q3-2022 | U10: Q4-2022 | V10: Q1-2023 | W10: Q2-2023 | X10: Q3-2023 | Y10: Q4-2023 | Z10: Q1-2024 | AA10: Q2-2024 | AB10: Q3-2024 | AC10: Q4-2024 | AD10: Q1-2025 | AE10: Q2-2025 | AF10: Q3-2025 | AG10: Q4-2025 | AI10: 2025 | AJ10: 2026 | AK10: T11-2025 | AL10: 2024 | AM10: 2025 | AN10: 2026
A11: TGDD | B11: 0.42 | C11: 0.41 | D11: 0.4 | E11: 0.4 | F11: 0.35 | G11: =G16/$G$14 -> 0.31901415 | H11: =H16/H14 -> 0.3309339 | I11: =I16/I14 -> 0.30083314 | J11: 0.285 | K11: =K16/K14 -> 0.23208506 | L11: =L16/L14 -> 0.29163847 | M11: =M16/M14 -> 0.27800295 | N11: 0.268 | O11: =O16/O14 -> 0.23444622 | P11: =P16/P14 -> 0.20104808 | Q11: =Q16/Q14 -> 0.30504914 | R11: 0.274 | S11: =S16/S14 -> 0.25956577 | T11: =T16/T14 -> 0.26057641 | U11: =U16/U14 -> 0.24319396 | V11: 0.246 | W11: =W16/W14 -> 0.22687559 | X11: =X16/X14 -> 0.24173547 | Y11: =Y16/Y14 -> 0.24176424 | Z11: 0.216 | AA11: =AA16/AA14 -> 0.19680135 | AB11: 0.217 | AC11: 0.224 | AD11: 0.23 | AE11: 0.225 | AF11: 0.23 | AG11: 0.239
A12: DMX | B12: 0.55 | C12: 0.56 | D12: 0.54 | E12: 0.55 | F12: 0.58 | G12: =G17/$G$14 -> 0.59355631 | H12: =H17/H14 -> 0.54714064 | I12: =I17/I14 -> 0.55791657 | J12: 0.562 | K12: =K17/K14 -> 0.57893278 | L12: =L17/L14 -> 0.48773998 | M12: =M17/M14 -> 0.49598229 | N12: 0.539 | O12: =O17/O14 -> 0.53110499 | P12: =P17/P14 -> 0.4172562 | Q12: =Q17/Q14 -> 0.52921966 | R12: 0.549 | S12: =S17/S14 -> 0.52631765 | T12: =T17/T14 -> 0.49945845 | U12: =U17/U14 -> 0.48674913 | V12: 0.493 | W12: =W17/W14 -> 0.50447465 | X12: =X17/X14 -> 0.44451301 | Y12: =Y17/Y14 -> 0.43106486 | Z12: 0.462 | AA12: =AA17/AA14 -> 0.47543906 | AB12: 0.452 | AC12: 0.443 | AD12: 0.442 | AE12: 0.446 | AF12: 0.444 | AG12: 0.438
A13: BHX | B13: 0.03 | C13: 0.03 | D13: 0.04 | E13: 0.05 | F13: 0.07 | G13: =G18/$G$14 -> 0.087429539 | H13: =H18/H14 -> 0.12192547 | I13: =I18/I14 -> 0.14125029 | J13: 0.153 | K13: =K18/K14 -> 0.18898216 | L13: =L18/L14 -> 0.22062155 | M13: =M18/M14 -> 0.22601476 | N13: 0.193 | O13: =O18/O14 -> 0.23444878 | P13: =P18/P14 -> 0.38169572 | Q13: =Q18/Q14 -> 0.15212137 | R13: 0.166 | S13: =S18/S14 -> 0.18771366 | T13: =T18/T14 -> 0.22275334 | U13: =U18/U14 -> 0.23325087 | V13: 0.236 | W13: =W18/W14 -> 0.24746247 | X13: =X18/X14 -> 0.28501605 | Y13: =Y18/Y14 -> 0.29464242 | Z13: 0.291 | AA13: =AA18/AA14 -> 0.30251919 | AB13: 0.304 | AC13: 0.306 | AD13: 0.305 | AE13: 0.307 | AF13: 0.303 | AG13: 0.3
A14: Doanh thu | B14: 22764 | C14: =C16+C17+C18 -> 21789 | D14: 20925 | E14: 21038 | F14: 25017 | G14: 26710 | H14: 25036 | I14: 25411 | J14: 29352 | K14: 26287 | L14: 25713 | M14: 27104 | N14: 30828 | O14: 31659 | P14: 24333 | Q14: 36138 | R14: 36467 | S14: 34337 | T14: 32012 | U14: 30589 | V14: 26990 | W14: 29580 | X14: 30288 | Y14: 31422 | Z14: 31441 | AA14: 34180 | AB14: 34146 | AC14: 34573 | AD14: 36134 | AE14: 37619 | AF14: =113436-AE14-AD14 -> 39683 | AG14: 42850 | AI14: =SUM(AI16:AI18)*12 -> 157800 | AJ14: =SUM(AJ16:AJ18)*12 -> 172760
A15: Doanh thu online | B15: 2781 | C15: 2719 | D15: 3352 | E15: 3498 | F15: 4650 | G15: 3070 | H15: 2348 | I15: 2614 | J15: 2019 | K15: =4993-2019 -> 2974 | L15: =7244-K15-J15 -> 2251 | M15: 2142 | N15: 2495 | O15: 2805 | P15: 4250.2 | Q15: 4819.8 | R15: 5935 | S15: =O15*1.94 -> 5441.7 | T15: 3017.54 | U15: 4282.46 | V15: 3700 | W15: 4502.65 | X15: 3957.47 | Y15: 4839.88 | Z15: 3626 | AA15: 2174 | AB15: =7300-Z15-AA15 -> 1500 | AC15: =9600-7300 -> 2300 | AD15: 1400 | AE15: =2700-AD15 -> 1300 | AF15: =4300-AD15-AE15 -> 1600 | AG15: =4300-AE15-AF15 -> 1400
A16: TGDD | B16: 9554 | C16: 8485 | D16: 8570 | E16: =E11*E14 -> 8415.2 | F16: =F11*F14 -> 8755.95 | G16: 8520.868 | H16: 8285.261 | I16: 7644.471 | J16: =J11*J14 -> 8365.32 | K16: 6100.82 | L16: 7498.9 | M16: 7534.992 | N16: =N11*N14 -> 8261.904 | O16: 7422.333 | P16: 4892.103 | Q16: 11023.866 | R16: =R11*R14 -> 9991.958 | S16: 8912.71 | T16: 8341.572 | U16: 7439.06 | V16: =V11*V14 -> 6639.54 | W16: 6710.98 | X16: 7321.684 | Y16: 7596.716 | Z16: =Z14*Z11 -> 6791.256 | AA16: 6726.67 | AB16: =AB11*AB14 -> 7409.682 | AC16: =AC11*AC14 -> 7744.352 | AD16: =AD11*AD14 -> 8310.82 | AE16: =AE11*AE14 -> 8464.275 | AF16: =AF11*AF14 -> 9127.09 | AG16: =AG11*AG14 -> 10241.15 | AI16: =AI23*AI30 -> 2828 | AJ16: =AJ23*AJ30 -> 3000 | AL16: =Z16+AA16+AB16+AC16 -> 28671.96 | AM16: =AD16+AE16+AF16+AF16 -> 35029.275 | AN16: =AJ16*12 -> 36000
A17: DMX | B17: =11777+814 -> 12591 | C17: 12358 | D17: 11068 | E17: =E12*E14 -> 11570.9 | F17: =F12*F14 -> 14509.86 | G17: 15853.889 | H17: 13698.213 | I17: 14177.218 | J17: =J12*J14 -> 16495.824 | K17: 15218.406 | L17: 12541.258 | M17: 13443.104 | N17: =N12*N14 -> 16616.292 | O17: 16814.253 | P17: 10153.095 | Q17: 19124.94 | R17: =R12*R14 -> 20020.383 | S17: 18072.169 | T17: 15988.664 | U17: 14889.169 | V17: =V12*V14 -> 13306.07 | W17: 14922.36 | X17: 13463.41 | Y17: 13544.92 | Z17: =Z14*Z12 -> 14525.742 | AA17: 16250.507 | AB17: =AB12*AB14 -> 15433.992 | AC17: =AC12*AC14 -> 15315.839 | AD17: =AD12*AD14 -> 15971.228 | AE17: =AE12*AE14 -> 16778.074 | AF17: =AF12*AF14 -> 17619.252 | AG17: =AG12*AG14 -> 18768.3 | AI17: =AI24*AI31 -> 5642 | AJ17: =AJ24*AJ31 -> 6030 | AL17: =Z17+AA17+AB17+AC17 -> 61526.08 | AM17: =AD17+AE17+AF17+AF17 -> 67987.806 | AN17: =AJ17*12 -> 72360
A18: BHX | B18: 606 | C18: 946 | D18: 1248 | E18: =E13*E14 -> 1051.9 | F18: =F13*F14 -> 1751.19 | G18: 2335.243 | H18: 3052.526 | I18: 3589.311 | J18: =J13*J14 -> 4490.856 | K18: 4967.774 | L18: 5672.842 | M18: 6125.904 | N18: =N13*N14 -> 5949.804 | O18: 7422.414 | P18: 9287.802 | Q18: 5497.362 | R18: 6370 | S18: 6445.524 | T18: 7130.78 | U18: 7134.911 | V18: 6370 | W18: 7319.94 | X18: 8632.566 | Y18: 9258.254 | Z18: =Z14*Z13 -> 9149.331 | AA18: 10340.106 | AB18: =AB13*AB14 -> 10380.384 | AC18: =AC13*AC14 -> 10579.338 | AD18: =AD13*AD14 -> 11020.87 | AE18: =AE13*AE14 -> 11549.033 | AF18: =AF13*AF14 -> 12023.949 | AG18: =AG13*AG14 -> 12855 | AI18: =AI25*AI32 -> 4680 | AJ18: =(AI25*2+AJ25)/3*AJ32 -> 5366.6667 | AL18: =Z18+AA18+AB18+AC18 -> 40449.159 | AM18: =AD18+AE18+AF18+AF18 -> 46617.801 | AN18: =AJ18*12 -> 64400
AI19: =AA16/W16 -> 1.002338 | AJ19: =AA23/W23 -> 0.88644068
A20: LNG | B20: 4007 | AI20: =AA17/W17 -> 1.0890038 | AJ20: =AA24/W24 -> 0.91437309
A21: LNST | B21: 808
A22: Số lượng cửa hàng
A23: TGDD | B23: 1071 | C23: 1058 | D23: 1038 | E23: 1032 | F23: 1023 | G23: =2449-838-600 -> 1011 | H23: =2706-H24-H25 -> 1011 | I23: 996 | J23: 1009 | K23: 971 | L23: 962 | M23: 913 | N23: 909 | O23: 936 | P23: =950+50 -> 1000 | Q23: =970+50+10 -> 1030 | R23: =985+29 -> 1014 | S23: 1067 | T23: 1116 | U23: 1190 | V23: =1088+100 -> 1188 | W23: 1180 | X23: 1165 | Y23: 1078 | Z23: 1071 | AA23: 1046 | AB23: 1023 | AC23: 1021 | AD23: =932+85 -> 1017 | AE23: 1015 | AF23: 1013 | AG23: 1012 | AI23: 1010 | AJ23: 1000 | AK23: 1012
A24: DMX | B24: 711 | C24: 724 | D24: 737 | E24: 750 | F24: 774 | G24: 838 | H24: 907 | I24: 1018 | J24: 1030 | K24: 1044 | L24: 1124 | M24: 1427 | N24: 1553 | O24: 1731 | P24: 1781 | Q24: 1992 | R24: =2077+44 -> 2121 | S24: 2131 | T24: 2246 | U24: 2284 | V24: 2291 | W24: 2289 | X24: 2286 | Y24: 2190 | Z24: 2184 | AA24: 2093 | AB24: 2030 | AC24: 2026 | AD24: 2027 | AE24: 2023 | AF24: 2018 | AG24: 2008 | AI24: 2015 | AJ24: 2010 | AK24: 2017
A25: BHX | B25: 355 | C25: 384 | D25: 409 | E25: 405 | F25: 469 | G25: 600 | H25: 788 | I25: 1008 | J25: 1158 | K25: 1486 | L25: 1623 | M25: 1719 | N25: 1767 | O25: 1888 | P25: 1934 | Q25: 1992 | R25: 2127 | S25: 1889 | T25: 1727 | U25: 1728 | V25: 1710 | W25: 1706 | X25: 1706 | Y25: 1698 | Z25: 1696 | AA25: 1701 | AB25: 1726 | AC25: 1770 | AD25: 2002 | AE25: 2184 | AF25: 2290 | AG25: 2559 | AI25: 2600 | AJ25: 4000 | AK25: 2482
A26: An khang | R26: 211 | S26: 365 | T26: 529 | U26: 500 | V26: 510 | W26: 537 | X26: 540 | Y26: 527 | Z26: 526 | AA26: 481 | AB26: 326 | AC26: 326 | AD26: 326 | AE26: 326 | AF26: 347 | AG26: 382 | AK26: 371
A27: AVA | R27: 24 | S27: 53 | T27: 71 | U27: 64 | V27: 64 | W27: 66 | X27: 67 | Y27: 64 | Z27: 64 | AA27: 64 | AB27: 62 | AC27: 62 | AD27: 62 | AE27: 62 | AF27: 67 | AG27: 83 | AK27: 80
A28: Trong đó Erablue | U28: 5 | Y28: 38 | Z28: 55 | AA28: 61 | AB28: 76 | AC28: 87 | AD28: 95 | AE28: 115 | AF28: 144 | AG28: 181 | AK28: 168
A30: DT/CH TGDD | B30: =B16/B23/3 -> 2.973545 | C30: =C16/C23/3 -> 2.6732829 | D30: =D16/D23/3 -> 2.7520873 | E30: =E16/E23/3 -> 2.7180879 | F30: =F16/F23/3 -> 2.8530303 | G30: =G16/G23/3 -> 2.8093861 | H30: =H16/H23/3 -> 2.7317049 | I30: =I16/I23/3 -> 2.5583906 | ... AG30: =AG16/AG23/3 -> 3.3732378 | AI30: 2.8 | AJ30: 3 | AL30: =AA30/W30 -> 1.1307445
A31: DT/CH DMX | B31: =B17/B24/3 -> 5.9029536 | C31: =C17/C24/3 -> 5.6896869 | D31: =D17/D24/3 -> 5.0058797 | E31: =E17/E24/3 -> 5.1426222 | F31: =F17/F24/3 -> 6.248863 | G31: =G17/G24/3 -> 6.3062407 | H31: =H17/H24/3 -> 5.0342569 | I31: =I17/I24/3 -> 4.6421801 | ... AG31: =AG17/AG24/3 -> 3.1155876 | AI31: 2.8 | AJ31: 3 | AL31: =AA31/W31 -> 1.1909841
A32: DT/CH BHX | B32: =B18/B25/3 -> 0.56901408 | C32: =C18/C25/3 -> 0.82118056 | D32: =D18/D25/3 -> 1.0171149 | E32: =E18/E25/3 -> 0.86576132 | F32: =F18/F25/3 -> 1.2446269 | G32: =G18/G25/3 -> 1.2973572 | H32: =H18/H25/3 -> 1.2912547 | I32: =I18/I25/3 -> 1.1869415 | ... AG32: =AG18/AG25/3 -> 1.6744822 | AI32: 1.8 | AJ32: 1.75
AK138: rẻ | AL138: 2.5
AK139: ok | AL139: 3
AK140: trung vị | AL140: 4
AK141: đặt | AL141: 5

Sheet Sheet3
