Workbook

Sheet 01_Cover
A1: PHÂN TÍCH CỔ PHIẾU HPG — CTCP Tập đoàn Hòa Phát
A2: Ticker | B2: HPG
A3: Sàn | B3: HOSE
A4: Ngành | B4: Thép (Sản xuất Commodity)
A5: Giá hiện tại (VND) | B5: 23600
A6: Số CP lưu hành | B6: 8444740856
A7: Vốn hóa (tỷ) | B7: 199295.88
A8: P/E TTM | B8: ='02_Assumptions'!J22
A9: P/B | B9: ='02_Assumptions'!J23
A10: EV/EBITDA | B10: ='02_Assumptions'!J24
A11: 52W Cao/Thấp | B11: 28,045 / 19,789
A12: Room ngoại | B12: 20.6%
A13: Khuyến nghị | B13: MUA
A14: Giá mục tiêu Base | B14: ='07_Valuation'!C10
A15: Upside | B15: ='07_Valuation'!C13
A16: Ngày phân tích | B16: 03/07/2026 21:58
A17: EPS TTM (VND) | B17: 1862
A18: BVPS (VND) | B18: 15539
A19: KLGD BQ 20 phiên (cp) | B19: 33200000
A20: KLGD BQ 20 phiên (tỷ) | B20: 890.7
A21: Cổ đông sáng lập | B21: 35.7% (Ông Trần Đình Long & gia đình)
A22: Biến động 1 tháng | B22: +3.3%
A23: Biến động 3 tháng | B23: +6.9%
A24: Biến động YTD | B24: +6.1%
A25: VNINDEX 1 tháng | B25: +4.4%
A26: VNINDEX 3 tháng | B26: -6.3%
A27: VNINDEX YTD | B27: -1.9%

Sheet 02_Assumptions
A1: Giả định | B1: 2021A | C1: 2022A | D1: 2023A | E1: 2024A | F1: 2025A | G1: 2026E | H1: 2027E | I1: 2028E | J1: Ghi chú
A2: Giá HPG (VND) | B2: 23600 | C2: 23600 | D2: 23600 | E2: 23600 | F2: 23600 | G2: 23600 | H2: 23600 | I2: 23600 | J2: Giá 24/06/2026. Broker targets: SSI 36k, VND 37k, SHS 38k, VCBS 38k, BVSC 38.65k
A3: Số CP lưu hành (triệu) | B3: 4473 | C3: 5815 | D3: 5815 | E3: 6396 | F3: 7675 | G3: 8445 | H3: 8445 | I3: 8445 | J3: Vốn điều lệ từng năm / 10,000. Post-split 1.1:1 T05/2026
A4: Doanh thu (tỷ) | B4: 149680 | C4: 141410 | D4: 118950 | E4: 138860 | F4: 156120 | G4: ='03_Revenue_Model'!G2 | H4: ='03_Revenue_Model'!H2 | I4: ='03_Revenue_Model'!I2 | J4: Bottom-up = SL HRC/XD x Giá x FX + Doanh thu khác (Sheet 03_Revenue_Model)
A5: Tăng trưởng DT (%) | B5: 48 | C5: -5.5 | D5: -15.9 | E5: 16.7 | F5: 12.4 | G5: =(G4/F4-1)*100 | H5: =(H4/G4-1)*100 | I5: =(I4/H4-1)*100 | J5: =Doanh thu(t) / Doanh thu(t-1) - 1, tính từ Doanh thu bottom-up
A6: Biên LNG (%) | B6: 27.46 | C6: 11.85 | D6: 10.88 | E6: 13.32 | F6: 15.69 | G6: 15.9 | H6: 15.5 | I6: 13.1 | J6: Bottom-up từ Spread (Giá - Quặng*1.6 - Than*0.5 - CP khác) x Sản lượng — khớp Profit Bridge 03_Revenue_Model
A7: EBIT Margin (%) | B7: 24.1 | C7: 7.8 | D7: 6.5 | E7: 9.3 | F7: 11.84 | G7: 12.4 | H7: 12 | I7: 9.6 | J7: =EBIT / Doanh thu, EBIT = LN gộp - CP BH&QLDN (khớp 04_PnL)
A8: Thuế TNDN (%) | B8: 4 | C8: 13.5 | D8: 10.5 | E8: 4 | F8: 12.5 | G8: 12 | H8: 12 | I8: 12 | J8: HPG ưu đãi Dung Quất
A9: D&A (tỷ) | B9: 6077 | C9: 6759 | D9: 6762 | E9: 6916 | F9: 8471 | G9: =F9*(1+G5/100) | H9: =G9*(1+H5/100) | I9: =H9*(1+I5/100) | J9: Khấu hao TSCĐ & BĐSĐT (cfa2) — số THẬT từ Vietcap. Dự phóng = công thức sống tăng theo DT
A10: CAPEX (tỷ) | B10: 11621 | C10: 17888 | D10: 17374 | E10: 35495 | F10: 25748 | G10: 15000 | H10: 18000 | I10: 20000 | J10: Số THẬT từ Vietcap (cfa19). 2024 đỉnh CAPEX DQ2 (~35.5k tỷ). Dự phóng giảm hậu-DQ2
A11: Nợ vay (tỷ) | B11: 57213 | C11: 57900 | D11: 65381 | E11: 82963 | F11: 92174 | G11: 89870 | H11: 86413 | I11: 82956 | J11: Vay NH+DH (bsa56+71) — số THẬT. Q1/2026: 90,6k giảm 2k so với 2025A; dự phóng giữ %YoY giảm dần cũ, neo gốc thật
A12: Tiền mặt (tỷ) | B12: 40708 | C12: 34593 | D12: 34429 | E12: 25862 | F12: 27785 | G12: 34731 | H12: 41677 | I12: 48623 | J12: Tiền&TĐT (bsa2) + Đầu tư ngắn hạn (bsa5, chủ yếu tiền gửi kỳ hạn) — số THẬT, dùng cho Net Debt
A13: VCSH (tỷ) | B13: 75000 | C13: 90000 | D13: 105000 | E13: 115000 | F13: 130000 | G13: =F13+'04_PnL'!G13-G14*G3/1000 | H13: =G13+'04_PnL'!H13-H14*H3/1000 | I13: =H13+'04_PnL'!I13-I14*I3/1000 | J13: Roll-forward: VCSH(t-1) + NI(t) - Cổ tức tiền mặt(t)
A14: Cổ tức (VND/CP) | B14: 0 | C14: 0 | D14: 0 | E14: 0 | F14: 0 | G14: 0 | H14: 800 | I14: 1200 | J14: 2026: 15% (10% CP + 5% TM)
A15: Tỷ lệ CP BH&QLDN/DT (%) | B15: 3.4 | C15: 4 | D15: 4.3 | E15: 4 | F15: 3.8 | G15: 3.5 | H15: 3.5 | I15: 3.5 | J15: Giảm nhờ DQ2 biên lớn
A16: P/B mục tiêu (x) | B16: =B23 | C16: =C23 | D16: =D23 | E16: =E23 | F16: =F23 | G16: =K30 | H16: =K30 | I16: =K30 | J16: HPG lịch sử median 1.64x (TTM 2018-2025) | K16: K30
A17: EV/EBITDA mục tiêu (x) | B17: =B24 | C17: =C24 | D17: =D24 | E17: =E24 | F17: =F24 | G17: =K31 | H17: =K31 | I17: =K31 | J17: HPG lịch sử median 8.43x (TTM 2018-2025) | K17: K31
A18: P/E mục tiêu (x) | B18: =B22 | C18: =C22 | D18: =D22 | E18: =E22 | F18: =F22 | G18: =K29 | H18: =K29 | I18: =K29 | J18: Tham khảo - HPG median 10.3x (TTM 2018-2025) | K18: K29
A19: Quặng sắt 62% Fe (USD/t) | B19: ='17_Gia_Hang_Hoa'!B32 | C19: ='17_Gia_Hang_Hoa'!C32 | D19: ='17_Gia_Hang_Hoa'!D32 | E19: ='17_Gia_Hang_Hoa'!E32 | F19: ='17_Gia_Hang_Hoa'!F32 | G19: ='17_Gia_Hang_Hoa'!G32 | H19: ='17_Gia_Hang_Hoa'!H32 | I19: ='17_Gia_Hang_Hoa'!I32 | J19: Giá CFR Trung Quốc — link '17_Gia_Hang_Hoa' (median quý/năm)
A20: Than cốc luyện kim (USD/t) | B20: ='17_Gia_Hang_Hoa'!B33 | C20: ='17_Gia_Hang_Hoa'!C33 | D20: ='17_Gia_Hang_Hoa'!D33 | E20: ='17_Gia_Hang_Hoa'!E33 | F20: ='17_Gia_Hang_Hoa'!F33 | G20: ='17_Gia_Hang_Hoa'!G33 | H20: ='17_Gia_Hang_Hoa'!H33 | I20: ='17_Gia_Hang_Hoa'!I33 | J20: FOB Úc — link '17_Gia_Hang_Hoa' (median quý/năm)
A21: Chi phí SX khác (USD/t) | B21: 100 | C21: 100 | D21: 100 | E21: 100 | F21: 100 | G21: 100 | H21: 100 | I21: 100 | J21: Cố định — gồm nhân công, nhiên liệu, điện, khấu hao, CPQL
A22: Doanh thu TC (tỷ) | B22: 1500 | C22: 2100 | D22: 1800 | E22: 1950 | F22: 2200 | G22: 7813 | H22: 2800 | I22: 3000
A23: Chi phí TC (tỷ) | B23: 1800 | C23: 3500 | D23: 2100 | E23: 2500 | F23: 3200 | G23: 4719 | H23: 4000 | I23: 4200
A24: Thu nhập khác (tỷ) | B24: 0 | C24: 0 | D24: 0 | E24: 0 | F24: 0 | G24: 0 | H24: 0 | I24: 0 | J24: Q1/2026: ~4,915 tỷ từ Phố Nối
A25: Tỷ giá USD/VND (VND) | B25: 23100 | C25: 23600 | D25: 24000 | E25: 24900 | F25: 26000 | G25: 26200 | H25: 26724 | I25: 27258 | J25: 2021-25: bình quân năm tham khảo Vietcombank/SBV; 2026E: fetch investing.com; 2027-28E: +2%/năm
A27: Bước 2: P/E, P/B, EV/EBITDA — Median từng năm (tham chiếu quý ở Sheet 08_Hist_Multiples)
A28: Chỉ tiêu | B28: 2018 | C28: 2019 | D28: 2020 | E28: 2021 | F28: 2022 | G28: 2023 | H28: 2024 | I28: 2025 | J28: Hiện tại (công thức) | K28: Trung vị LS
A29: P/E (x) | B29: =MEDIAN('08_Hist_Multiples'!C2:C5) | C29: =MEDIAN('08_Hist_Multiples'!C6:C9) | D29: =MEDIAN('08_Hist_Multiples'!C10:C13) | E29: =MEDIAN('08_Hist_Multiples'!C14:C17) | F29: =MEDIAN('08_Hist_Multiples'!C18:C21) | G29: =MEDIAN('08_Hist_Multiples'!C22:C25) | H29: =MEDIAN('08_Hist_Multiples'!C26:C29) | I29: =MEDIAN('08_Hist_Multiples'!C30:C33) | J29: =('02_Assumptions'!$B$2*'02_Assumptions'!$B$3*1000000)/('04_PnL'!F13*1000000000) | K29: =MEDIAN(B29:I29)
A30: P/B (x) | B30: =MEDIAN('08_Hist_Multiples'!D2:D5) | C30: =MEDIAN('08_Hist_Multiples'!D6:D9) | D30: =MEDIAN('08_Hist_Multiples'!D10:D13) | E30: =MEDIAN('08_Hist_Multiples'!D14:D17) | F30: =MEDIAN('08_Hist_Multiples'!D18:D21) | G30: =MEDIAN('08_Hist_Multiples'!D22:D25) | H30: =MEDIAN('08_Hist_Multiples'!D26:D29) | I30: =MEDIAN('08_Hist_Multiples'!D30:D33) | J30: =('02_Assumptions'!$B$2*'02_Assumptions'!$B$3*1000000)/('02_Assumptions'!F13*1000000000) | K30: =MEDIAN(B30:I30)
A31: EV/EBITDA (x) | B31: =MEDIAN('08_Hist_Multiples'!E2:E5) | C31: =MEDIAN('08_Hist_Multiples'!E6:E9) | D31: =MEDIAN('08_Hist_Multiples'!E10:E13) | E31: =MEDIAN('08_Hist_Multiples'!E14:E17) | F31: =MEDIAN('08_Hist_Multiples'!E18:E21) | G31: =MEDIAN('08_Hist_Multiples'!E22:E25) | H31: =MEDIAN('08_Hist_Multiples'!E26:E29) | I31: =MEDIAN('08_Hist_Multiples'!E30:E33) | J31: =('02_Assumptions'!$B$2*'02_Assumptions'!$B$3*1000000+('02_Assumptions'!F11-'02_Assumptions'!F12)*1000000000)/('04_PnL'!F16*1000000000) | K31: =MEDIAN(B31:I31)
A33: GIÁ TRỊ ĐỊNH GIÁ THEO TỪNG PHƯƠNG PHÁP
A34: Phương pháp | G34: 2026E | J34: Giá trị CP | K34: Ghi chú
A35: EV/EBITDA (2026E) | J35: =(('04_PnL'!G16*K31-('02_Assumptions'!G11-'02_Assumptions'!G12))*1000000000)/('02_Assumptions'!G3*1000000) | K35: EV/EBITDA target = K31
A36: P/B (2026E) | J36: =K30*('02_Assumptions'!G13*1000000000)/('02_Assumptions'!G3*1000000) | K36: P/B target = K30
A37: P/E (2026E) | J37: =K29*'04_PnL'!G15 | K37: P/E target = K29
A40: Q1/2026 Doanh thu (tỷ) | G40: 52900.847
A41: Q1/2026 LN gộp (tỷ) | G41: 8365.0686
A42: Q1/2026 Biên LNG (%) | G42: =G41/G40*100
A43: Spread All quý gần nhất đã biết (1 quý 2026, USD/t) | G43: ='17_Gia_Hang_Hoa'!L22
A45: Spread hàng năm (USD/t) | B45: ='17_Gia_Hang_Hoa'!B35 | C45: ='17_Gia_Hang_Hoa'!C35 | D45: ='17_Gia_Hang_Hoa'!D37 | E45: ='17_Gia_Hang_Hoa'!E37 | F45: ='17_Gia_Hang_Hoa'!F37 | G45: ='17_Gia_Hang_Hoa'!G37 | H45: ='17_Gia_Hang_Hoa'!H37 | I45: ='17_Gia_Hang_Hoa'!I37 | J45: ≤2022: Spread HRC (chưa có SL tách quý để tính All); ≥2023: Spread All — link '17_Gia_Hang_Hoa'
...

Sheet 03_Revenue_Model
A1: Chỉ tiêu | B1: 2021A | C1: 2022A | D1: 2023A | E1: 2024A | F1: 2025A | G1: 2026E | H1: 2027E | I1: 2028E
A2: Doanh thu (tỷ) | B2: 149679.79 | C2: 141409.27 | D2: 118953.03 | E2: 138855.11 | F2: 156116.09 | G2: =G8+G9+G10 | H2: =H8+H9+H10 | I2: =I8+I9+I10
A3: YoY Growth (%) | B3: - | C3: =(C2/B2-1)*100 | D3: =(D2/C2-1)*100 | E3: =(E2/D2-1)*100 | F3: =(F2/E2-1)*100 | G3: =(G2/F2-1)*100 | H3: =(H2/G2-1)*100 | I3: =(I2/H2-1)*100
A4: Sản lượng HRC (triệu tấn) | B4: 2 | C4: 2.2 | D4: =SUM('15_Quarterly_Data'!B59:E59)/1000 | E4: =SUM('15_Quarterly_Data'!F59:I59)/1000 | F4: =SUM('15_Quarterly_Data'!J59:M59)/1000 | G4: ='15_Quarterly_Data'!B87 | H4: 6.3 | I4: 6.62
A5: Sản lượng thép XD (triệu tấn) | B5: 2.8 | C5: 2.6 | D5: =SUM('15_Quarterly_Data'!B60:E60)/1000 | E5: =SUM('15_Quarterly_Data'!F60:I60)/1000 | F5: =SUM('15_Quarterly_Data'!J60:M60)/1000 | G5: ='15_Quarterly_Data'!B88 | H5: 5.73 | I5: 6.02
A6: Giá HRC bq (USD/tấn) | B6: ='17_Gia_Hang_Hoa'!B31 | C6: ='17_Gia_Hang_Hoa'!C31 | D6: ='17_Gia_Hang_Hoa'!D31 | E6: ='17_Gia_Hang_Hoa'!E31 | F6: ='17_Gia_Hang_Hoa'!F31 | G6: ='17_Gia_Hang_Hoa'!G31 | H6: ='17_Gia_Hang_Hoa'!H31 | I6: ='17_Gia_Hang_Hoa'!I31
A7: Giá thép XD bq (USD/tấn) | B7: 720 | C7: 580 | D7: 520 | E7: 550 | F7: 590 | G7: 610 | H7: 620 | I7: 630
A8: Doanh thu HRC (tỷ) | B8: =B4*B6*'02_Assumptions'!B25/1000 | C8: =C4*C6*'02_Assumptions'!C25/1000 | D8: =D4*D6*'02_Assumptions'!D25/1000 | E8: =E4*E6*'02_Assumptions'!E25/1000 | F8: =F4*F6*'02_Assumptions'!F25/1000 | G8: =G4*G6*'02_Assumptions'!G25/1000 | H8: =H4*H6*'02_Assumptions'!H25/1000 | I8: =I4*I6*'02_Assumptions'!I25/1000
A9: Doanh thu thép XD (tỷ) | B9: =B5*B7*'02_Assumptions'!B25/1000 | C9: =C5*C7*'02_Assumptions'!C25/1000 | D9: =D5*D7*'02_Assumptions'!D25/1000 | E9: =E5*E7*'02_Assumptions'!E25/1000 | F9: =F5*F7*'02_Assumptions'!F25/1000 | G9: =G5*G7*'02_Assumptions'!G25/1000 | H9: =H5*H7*'02_Assumptions'!H25/1000 | I9: =I5*I7*'02_Assumptions'!I25/1000
A10: Doanh thu khác (tỷ) | B10: =B2-B8-B9 | C10: =C2-C8-C9 | D10: =D2-D8-D9 | E10: =E2-E8-E9 | F10: =F2-F8-F9 | G10: =F10*(1+0.12) | H10: =G10*(1+0.12) | I10: =H10*(1+0.12)
B12: ='04_PnL'!B13 | C12: ='04_PnL'!C13 | D12: ='04_PnL'!D13 | E12: ='04_PnL'!E13 | F12: ='04_PnL'!F13 | G12: ='04_PnL'!G13 | H12: ='04_PnL'!H13 | I12: ='04_PnL'!I13
B13: ='04_PnL'!B5 | C13: ='04_PnL'!C5 | D13: ='04_PnL'!D5 | E13: ='04_PnL'!E5 | F13: ='04_PnL'!F5 | G13: ='04_PnL'!G5 | H13: ='04_PnL'!H5 | I13: ='04_PnL'!I5
B15: ='04_PnL'!B15 | C15: ='04_PnL'!C15 | D15: ='04_PnL'!D15 | E15: ='04_PnL'!E15 | F15: ='04_PnL'!F15 | G15: ='04_PnL'!G15 | H15: ='04_PnL'!H15 | I15: ='04_PnL'!I15
A20: B. PHÂN TÍCH LỢI NHUẬN TỪ SPREAD (công thức nội bộ)
A21: Tổng CF SX/tấn (USD) | B21: ='02_Assumptions'!B19*1.6+'02_Assumptions'!B20*0.6+'02_Assumptions'!B21 | C21: ='02_Assumptions'!C19*1.6+'02_Assumptions'!C20*0.6+'02_Assumptions'!C21 | D21: ='02_Assumptions'!D19*1.6+'02_Assumptions'!D20*0.6+'02_Assumptions'!D21 | E21: ='02_Assumptions'!E19*1.6+'02_Assumptions'!E20*0.6+'02_Assumptions'!E21 | F21: ='02_Assumptions'!F19*1.6+'02_Assumptions'!F20*0.6+'02_Assumptions'!F21 | G21: ='02_Assumptions'!G19*1.6+'02_Assumptions'!G20*0.6+'02_Assumptions'!G21 | H21: ='02_Assumptions'!H19*1.6+'02_Assumptions'!H20*0.6+'02_Assumptions'!H21 | I21: ='02_Assumptions'!I19*1.6+'02_Assumptions'!I20*0.6+'02_Assumptions'!I21 | J21: Quặng*1.6 + Than*0.6 + CP SX khác (200, cố định)
A22: Spread HRC (USD/t) | B22: =B6-B21 | C22: =C6-C21 | D22: =D6-D21 | E22: =E6-E21 | F22: =F6-F21 | G22: =G6-G21 | H22: =H6-H21 | I22: =I6-I21 | J22: Giá HRC bq - CF/tấn
A23: Spread XD (USD/t) | B23: =B7-B21 | C23: =C7-C21 | D23: =D7-D21 | E23: =E7-E21 | F23: =F7-F21 | G23: =G7-G21 | H23: =H7-H21 | I23: =I7-I21 | J23: Giá XD bq - CF/tấn
A24: LN gộp thép (tỷ) | B24: =(B4*B22+B5*B23)*'02_Assumptions'!B25/1000 | C24: =(C4*C22+C5*C23)*'02_Assumptions'!C25/1000 | D24: =(D4*D22+D5*D23)*'02_Assumptions'!D25/1000 | E24: =(E4*E22+E5*E23)*'02_Assumptions'!E25/1000 | F24: =(F4*F22+F5*F23)*'02_Assumptions'!F25/1000 | G24: =(G4*G22+G5*G23)*'02_Assumptions'!G25/1000 | H24: =(H4*H22+H5*H23)*'02_Assumptions'!H25/1000 | I24: =(I4*I22+I5*I23)*'02_Assumptions'!I25/1000 | J24: (SL_HRC*Spr_HRC + SL_XD*Spr_XD)*25400/1000
A25: LN gộp KD khác (tỷ) | B25: =B10*0.15 | C25: =C10*0.15 | D25: =D10*0.15 | E25: =E10*0.15 | F25: =F10*0.15 | G25: =G10*0.15 | H25: =H10*0.15 | I25: =I10*0.15 | J25: Giả định biên 15% cho ống/tôn/KCN
A26: Tổng LN gộp ước tính (tỷ) | B26: =B24+B25 | C26: =C24+C25 | D26: =D24+D25 | E26: =E24+E25 | F26: =F24+F25 | G26: =G24+G25 | H26: =H24+H25 | I26: =I24+I25 | J26: Đối chiếu PnL!GP
A27: Biên LNG ước tính (%) | B27: =B26/B2*100 | C27: =C26/C2*100 | D27: =D26/D2*100 | E27: =E26/E2*100 | F27: =F26/F2*100 | G27: =G26/G2*100 | H27: =H26/H2*100 | I27: =I26/I2*100
A28: CP QLDN (tỷ) | B28: =B2*'02_Assumptions'!B15/100 | C28: =C2*'02_Assumptions'!C15/100 | D28: =D2*'02_Assumptions'!D15/100 | E28: =E2*'02_Assumptions'!E15/100 | F28: =F2*'02_Assumptions'!F15/100 | G28: =G2*'02_Assumptions'!G15/100 | H28: =H2*'02_Assumptions'!H15/100 | I28: =I2*'02_Assumptions'!I15/100 | J28: =DT * SGKA%
A29: EBIT ước tính (tỷ) | B29: ='04_PnL'!B7 | C29: ='04_PnL'!C7 | D29: ='04_PnL'!D7 | E29: ='04_PnL'!E7 | F29: ='04_PnL'!F7 | G29: =G26-G28 | H29: =H26-H28 | I29: =I26-I28 | J29: Forecast: LN gộp - CP QL

Sheet 04_PnL
A1: Chỉ tiêu | B1: 2021A | C1: 2022A | D1: 2023A | E1: 2024A | F1: 2025A | G1: 2026E | H1: 2027E | I1: 2028E
A2: Doanh thu thuần | B2: 149679.79 | C2: 141409.27 | D2: 118953.03 | E2: 138855.11 | F2: 156116.09 | G2: ='03_Revenue_Model'!G2 | H2: ='03_Revenue_Model'!H2 | I2: ='03_Revenue_Model'!I2
A3: Giá vốn hàng bán | B3: 108578 | C3: 124652 | D3: 106011 | E3: 120360 | F3: 131621 | G3: =G2*(1-'02_Assumptions'!G6/100) | H3: =H2*(1-'02_Assumptions'!H6/100) | I3: =I2*(1-'02_Assumptions'!I6/100)
A4: Lợi nhuận gộp | B4: 41101.79 | C4: 16757.274 | D4: 12942.028 | E4: 18495.112 | F4: 24495.095 | G4: =G2-G3 | H4: =H2-H3 | I4: =I2-I3
A5: Biên LNG (%) | B5: 27.46 | C5: 11.85 | D5: 10.88 | E5: 13.32 | F5: 15.69 | G5: =G4/G2*100 | H5: =H4/H2*100 | I5: =I4/I2*100
A6: Chi phí BH & QLDN | B6: 5688 | C6: 5374 | D6: 4520 | E6: 5276 | F6: 5932 | G6: =G2*'02_Assumptions'!G15/100 | H6: =H2*'02_Assumptions'!H15/100 | I6: =I2*'02_Assumptions'!I15/100
A7: EBIT | B7: 35413.79 | C7: 11383.274 | D7: 8422.0279 | E7: 13219.112 | F7: 18563.095 | G7: =G4-G6 | H7: =H4-H6 | I7: =I4-I6
A8: Biên EBIT (%) | B8: 23.7 | C8: 8 | D8: 7.1 | E8: 9.5 | F8: 11.9 | G8: =G7/G2*100 | H8: =H7/H2*100 | I8: =I7/I2*100
A9: Doanh thu tài chính | B9: 1500 | C9: 2100 | D9: 1800 | E9: 1950 | F9: 2200 | G9: 7813 | H9: 2800 | I9: 3000
A10: Chi phí tài chính | B10: 1800 | C10: 3500 | D10: 2100 | E10: 2500 | F10: 3200 | G10: 4719 | H10: 4000 | I10: 4200
A11: EBT | B11: =B7+B9-B10 | C11: =C7+C9-C10 | D11: =D7+D9-D10 | E11: =E7+E9-E10 | F11: =F7+F9-F10 | G11: =G7+G9-G10 | H11: =H7+H9-H10 | I11: =I7+I9-I10
A12: Thuế TNDN | B12: 4389 | C12: 1248 | D12: 1015 | E12: 1584 | F12: 2195 | G12: =G11*'02_Assumptions'!G8/100 | H12: =H11*'02_Assumptions'!H8/100 | I12: =I11*'02_Assumptions'!I8/100
A13: LNST | B13: =B11-B12 | C13: =C11-C12 | D13: =D11-D12 | E13: =E11-E12 | F13: =F11-F12 | G13: =G11-G12 | H13: =H11-H12 | I13: =I11-I12
A14: Biên LNST (%) | B14: =B13/B2*100 | C14: =C13/C2*100 | D14: =D13/D2*100 | E14: =E13/E2*100 | F14: =F13/F2*100 | G14: =G13/G2*100 | H14: =H13/H2*100 | I14: =I13/I2*100
A15: EPS (VND) | B15: =B13*1000000000/('02_Assumptions'!B3*1000000) | C15: =C13*1000000000/('02_Assumptions'!C3*1000000) | D15: =D13*1000000000/('02_Assumptions'!D3*1000000) | E15: =E13*1000000000/('02_Assumptions'!E3*1000000) | F15: =F13*1000000000/('02_Assumptions'!F3*1000000) | G15: =G13*1000000000/('02_Assumptions'!G3*1000000) | H15: =H13*1000000000/('02_Assumptions'!H3*1000000) | I15: =I13*1000000000/('02_Assumptions'!I3*1000000)
A16: EBITDA | B16: =B7+'02_Assumptions'!B9 | C16: =C7+'02_Assumptions'!C9 | D16: =D7+'02_Assumptions'!D9 | E16: =E7+'02_Assumptions'!E9 | F16: =F7+'02_Assumptions'!F9 | G16: =G7+'02_Assumptions'!G9 | H16: =H7+'02_Assumptions'!H9 | I16: =I7+'02_Assumptions'!I9

Sheet 05_Balance_Sheet
A1: Chỉ tiêu | B1: 2021A | C1: 2022A | D1: 2023A | E1: 2024A | F1: 2025A | G1: 2026E | H1: 2027E | I1: 2028E
A2: Tài sản ngắn hạn
A3: Tiền & tương đương | B3: 22471.376 | C3: 8324.5889 | D3: 12252.001 | E3: 6887.6461 | F3: 8300.8903 | G3: 25000 | H3: 30000 | I3: 35000
A4: Đầu tư tài chính NH | B4: 3000 | C4: 4000 | D4: 5000 | E4: 6000 | F4: 7000 | G4: 8000 | H4: 9000 | I4: 10000
A5: Phải thu NH | B5: 7662.6808 | C5: 9892.8674 | D5: 10702.136 | E5: 7647.8003 | F5: 15042.323 | G5: 18000 | H5: 20000 | I5: 22000
A6: Hàng tồn kho | B6: 42134.494 | C6: 34491.111 | D6: 34504.487 | E6: 46091.222 | F6: 52828.227 | G6: 45000 | H6: 48000 | I6: 50000
A7: TSNH khác | B7: 2000 | C7: 2500 | D7: 3000 | E7: 3500 | F7: 4000 | G7: 4500 | H7: 5000 | I7: 5500
A8: Tài sản dài hạn
A9: TSCĐ hữu hình | B9: 68744 | C9: 70199 | D9: 71787 | E9: 67244 | F9: 133421 | G9: 150000 | H9: 160000 | I9: 170000
A10: XDCB DD (CIP) | B10: 8289 | C10: 13334 | D10: 26053 | E10: 63656 | F10: 10721 | G10: 15000 | H10: 10000 | I10: 8000
A11: TSCĐ vô hình | B11: 5000 | C11: 6000 | D11: 7000 | E11: 8000 | F11: 9000 | G11: 10000 | H11: 11000 | I11: 12000
A12: Đầu tư TC dài hạn | B12: 10000 | C12: 12000 | D12: 13000 | E12: 14000 | F12: 15000 | G12: 16000 | H12: 17000 | I12: 18000
A13: TSDH khác | B13: 2000 | C13: 2500 | D13: 3000 | E13: 3500 | F13: 4000 | G13: 4500 | H13: 5000 | I13: 5500
A14: Tổng tài sản | B14: =B3+B4+B5+B6+B7+B9+B10+B11+B12+B13 | C14: =C3+C4+C5+C6+C7+C9+C10+C11+C12+C13 | D14: =D3+D4+D5+D6+D7+D9+D10+D11+D12+D13 | E14: =E3+E4+E5+E6+E7+E9+E10+E11+E12+E13 | F14: =F3+F4+F5+F6+F7+F9+F10+F11+F12+F13 | G14: =G3+G4+G5+G6+G7+G9+G10+G11+G12+G13 | H14: =H3+H4+H5+H6+H7+H9+H10+H11+H12+H13 | I14: =I3+I4+I5+I6+I7+I9+I10+I11+I12+I13
A15: Nợ ngắn hạn
A16: Phải trả NH | B16: 23729 | C16: 11107 | D16: 12387 | E16: 14047 | F16: 21183 | G16: 20000 | H16: 22000 | I16: 24000
A17: Vay ngắn hạn | B17: 43748 | C17: 46749 | D17: 54982 | E17: 55883 | F17: 64695 | G17: 60000 | H17: 55000 | I17: 50000
A18: Nợ NH khác | B18: 5000 | C18: 6000 | D18: 7000 | E18: 8000 | F18: 9000 | G18: 10000 | H18: 11000 | I18: 12000
A19: Nợ dài hạn
A20: Vay dài hạn | B20: 13465 | C20: 11152 | D20: 10399 | E20: 27080 | F20: 27479 | G20: 30000 | H20: 28000 | I20: 26000
A21: Nợ DH khác | B21: 3000 | C21: 4000 | D21: 5000 | E21: 6000 | F21: 7000 | G21: 8000 | H21: 9000 | I21: 10000
A22: Tổng nợ | B22: =B16+B17+B18+B20+B21 | C22: =C16+C17+C18+C20+C21 | D22: =D16+D17+D18+D20+D21 | E22: =E16+E17+E18+E20+E21 | F22: =F16+F17+F18+F20+F21 | G22: =G16+G17+G18+G20+G21 | H22: =H16+H17+H18+H20+H21 | I22: =I16+I17+I18+I20+I21
A23: VCSH
A24: Vốn điều lệ | B24: 12000 | C24: 15000 | D24: 18000 | E24: 20000 | F24: 22000 | G24: 25000 | H24: 28000 | I24: 31000
A25: Thặng dư | B25: 8000 | C25: 10000 | D25: 12000 | E25: 15000 | F25: 18000 | G25: 20000 | H25: 22000 | I25: 24000
A26: LN chưa PP | B26: 40000 | C26: 48000 | D26: 55000 | E26: 60000 | F26: 68000 | G26: 82430 | H26: 88090 | I26: 86669
A27: Quỹ & khác | B27: 15000 | C27: 17000 | D27: 20000 | E27: 20000 | F27: 22000 | G27: 25000 | H27: 28000 | I27: 32000
A28: Tổng VCSH | B28: 90780.626 | C28: 96112.94 | D28: 102836.42 | E28: 114647.46 | F28: 131220.01 | G28: 152430 | H28: 166090 | I28: 173669
A29: Tổng nợ + VCSH | B29: =B22+B28 | C29: =C22+C28 | D29: =D22+D28 | E29: =E22+E28 | F29: =F22+F28 | G29: =G22+G28 | H29: =H22+H28 | I29: =I22+I28

Sheet 06_Cash_Flow
A1: Chỉ tiêu | B1: 2021A | C1: 2022A | D1: 2023A | E1: 2024A | F1: 2025A | G1: 2026E | H1: 2027E | I1: 2028E
A2: Dòng tiền từ HĐKD (CFO) | B2: 26720.913 | C2: 12277.637 | D2: 8643.0308 | E2: 6608.3207 | F2: 17365.859 | G2: =G3+G4+G5 | H2: =H3+H4+H5 | I2: =I3+I4+I5
A3: LNST | B3: 34478.143 | C3: 8483.5106 | D3: 6835.0643 | E3: 12021.444 | F3: 15453.174 | G3: ='04_PnL'!G13 | H3: ='04_PnL'!H13 | I3: ='04_PnL'!I13
A4: Khấu hao | B4: 6076.5163 | C4: 6759.4621 | D4: 6761.9335 | E4: 6915.6713 | F4: 8470.6833 | G4: ='02_Assumptions'!G9 | H4: ='02_Assumptions'!H9 | I4: ='02_Assumptions'!I9
A5: Thay đổi VLĐ (ước) | B5: -13833.746 | C5: -2965.336 | D5: -4953.9671 | E5: -12328.795 | F5: -6557.9982 | G5: 0 | H5: 0 | I5: 0
A6: Dòng tiền đầu tư (CFI) | B6: -19669.453 | C6: -24626.213 | D6: -11995.09 | E6: -29788.138 | F6: -25814.393 | G6: =-G7 | H6: =-H7 | I6: =-I7
A7: CAPEX | B7: 11621.47 | C7: 17887.505 | D7: 17373.946 | E7: 35495.027 | F7: 25748.32 | G7: ='02_Assumptions'!G10 | H7: ='02_Assumptions'!H10 | I7: ='02_Assumptions'!I10
A8: Dòng tiền tài trợ (CFF) | B8: -5000 | C8: -2000 | D8: -3000 | E8: -4000 | F8: -5000 | G8: -5000 | H8: -6000 | I8: -7000
A9: FCFF (CFO + CFI) | B9: 7051.4605 | C9: -12348.576 | D9: -3352.0587 | E9: -23179.818 | F9: -8448.5338 | G9: =G2+G6 | H9: =H2+H6 | I9: =I2+I6
A10: Tiền đầu kỳ | B10: 13696 | C10: =B11 | D10: =C11 | E10: =D11 | F10: =E11 | G10: =F11 | H10: =G11 | I10: =H11
A11: Tiền cuối kỳ | B11: =B10+B2+B6+B8 | C11: =C10+C2+C6+C8 | D11: =D10+D2+D6+D8 | E11: =E10+E2+E6+E8 | F11: =F10+F2+F6+F8 | G11: =G10+G2+G6+G8 | H11: =H10+H2+H6+H8 | I11: =I10+I2+I6+I8

Sheet 07_Valuation
A1: Phương pháp | B1: Trọng số | C1: Giá trị CP (VND) | D1: Ghi chú
A2: EV/EBITDA (2026E, HPG median) | B2: 0.4 | C2: ='02_Assumptions'!J35 | D2: 40% — EV/EBITDA dùng median lịch sử HPG
A3: P/B (2026E, HPG median) | B3: 0.4 | C3: ='02_Assumptions'!J36 | D3: 40% — P/B là thước đo chu kỳ tin cậy
A4: P/E (2026E, HPG median) | B4: 0.2 | C4: ='02_Assumptions'!J37 | D4: 20% — P/E tham khảo bổ sung
A7: DCF Model: | B7: Đang phát triển — sẽ thay thế tỷ trọng 70% khi hoàn thiện
A10: Giá mục tiêu (có trọng số) | B10: 1 | C10: =C2*B2+C3*B3+C4*B4
A12: Giá hiện tại | C12: 23600
A13: Upside (%) | C13: =C10/C12-1

Sheet 08_Hist_Multiples
A1: Năm | B1: Quý | C1: P/E (x) | D1: P/B (x) | E1: EV/EBITDA (x) | F1: Nhãn | G1: P/E gốc | H1: P/E hiệu chỉnh
A2: 2018 | B2: 1 | C2: 9.1 | D2: 1.64 | E2: 6.9 | F2: Q1-2018 | G2: 9.1
A3: 2018 | B3: 2 | C3: 9.1 | D3: 2.25 | E3: 7.2 | F3: Q2-2018 | G3: 9.1
A4: 2018 | B4: 3 | C4: 6.7 | D4: 1.58 | E4: 5.9 | F4: Q3-2018 | G4: 6.7
A5: 2018 | B5: 4 | C5: 8.2 | D5: 1.74 | E5: 6.9 | F5: Q4-2018 | G5: 8.2
A6: 2019 | B6: 1 | C6: 7.5 | D6: 1.45 | E6: 6.9 | F6: Q1-2019 | G6: 7.5
A7: 2019 | B7: 2 | C7: 7.5 | D7: 1.36 | E7: 7.1 | F7: Q2-2019 | G7: 7.5
A8: 2019 | B8: 3 | C8: 9.5 | D8: 1.52 | E8: 8.8 | F8: Q3-2019 | G8: 9.5
A9: 2019 | B9: 4 | C9: 8.1 | D9: 1.28 | E9: 7.7 | F9: Q4-2019 | G9: 8.1
A10: 2020 | B10: 1 | C10: 9.7 | D10: 1.56 | E10: 8.1 | F10: Q1-2020 | G10: 9.7
A11: 2020 | B11: 2 | C11: 11.8 | D11: 1.95 | E11: 9.1 | F11: Q2-2020 | G11: 11.8
A12: 2020 | B12: 3 | C12: 12.1 | D12: 2.37 | E12: 9.4 | F12: Q3-2020 | G12: 12.1
A13: 2020 | B13: 4 | C13: 13.6 | D13: 3.09 | E13: 10.2 | F13: Q4-2020 | G13: 13.6
A14: 2021 | B14: 1 | C14: 11.1 | D14: 3.04 | E14: 9.2 | F14: Q1-2021 | G14: 11.1
A15: 2021 | B15: 2 | C15: 11.1 | D15: 3.04 | E15: 9.2 | F15: Q2-2021 | H15: 11.1
A16: 2021 | B16: 3 | C16: 6.2 | D16: 2.34 | E16: 6 | F16: Q3-2021 | G16: 6.2
A17: 2021 | B17: 4 | C17: 5.6 | D17: 2.14 | E17: 5.5 | F17: Q4-2021 | G17: 5.6
A18: 2022 | B18: 1 | C18: 3.6 | D18: 1.31 | E18: 3.7 | F18: Q1-2022 | G18: 3.6
A19: 2022 | B19: 2 | C19: 3.8 | D19: 1.14 | E19: 4 | F19: Q2-2022 | G19: 3.8
A20: 2022 | B20: 3 | C20: 6.5 | D20: 1.18 | E20: 5.6 | F20: Q3-2022 | G20: 6.5
A21: 2022 | B21: 4 | C21: 14.2 | D21: 1.25 | E21: 8.8 | F21: Q4-2022 | G21: 14.2
A22: 2023 | B22: 1 | C22: 14.2 | D22: 1.63 | E22: 18.2 | F22: Q1-2023 | H22: 14.2
A23: 2023 | B23: 2 | C23: 14.2 | D23: 1.53 | E23: 24.3 | F23: Q2-2023 | H23: 14.2
A24: 2023 | B24: 3 | C24: 14.2 | D24: 1.58 | E24: 19.1 | F24: Q3-2023 | H24: 14.2
A25: 2023 | B25: 4 | C25: 25.5 | D25: 1.69 | E25: 13.5 | F25: Q4-2023 | G25: 25.5
A26: 2024 | B26: 1 | C26: 19.6 | D26: 1.73 | E26: 13.2 | F26: Q1-2024 | G26: 19.6
A27: 2024 | B27: 2 | C27: 15.5 | D27: 1.59 | E27: 11.3 | F27: Q2-2024 | G27: 15.5
A28: 2024 | B28: 3 | C28: 13.6 | D28: 1.48 | E28: 10.9 | F28: Q3-2024 | G28: 13.6
A29: 2024 | B29: 4 | C29: 13.8 | D29: 1.45 | E29: 10.9 | F29: Q4-2024 | G29: 13.8
A30: 2025 | B30: 1 | C30: 15.8 | D30: 1.68 | E30: 12.3 | F30: Q1-2025 | G30: 15.8
A31: 2025 | B31: 2 | C31: 16.2 | D31: 1.79 | E31: 12.6 | F31: Q2-2025 | G31: 16.2
A32: 2025 | B32: 3 | C32: 14.5 | D32: 1.67 | E32: 11.7 | F32: Q3-2025 | G32: 14.5
A33: 2025 | B33: 4 | C33: 13.9 | D33: 1.67 | E33: 10.6 | F33: Q4-2025 | G33: 13.9
A34: 2026 | B34: 1 | C34: 9.4 | D34: 1.42 | E34: 8.6 | F34: Q1-2026 | G34: 9.4
A35: 2026 | B35: 2 | C35: 9.4 | D35: 1.42 | E35: 8.6 | F35: Q2-2026 | H35: 9.4
A36: 2026 | B36: 3 | C36: 9.4 | D36: 1.42 | E36: 8.6 | F36: Q3-2026 | H36: 9.4
A37: 2026 | B37: 4 | C37: 9.4 | D37: 1.42 | E37: 8.6 | F37: Q4-2026 | H37: 9.4

Sheet 09_Sensitivity
A1: Sensitivity: EV/EBITDA vs EBITDA 2026E (Target Price VND)
B3: EV/EBITDA 5.5x | C3: EV/EBITDA 6.5x | D3: EV/EBITDA 7.5x | E3: EV/EBITDA 8.5x | F3: EV/EBITDA 9.5x
A4: EBITDA 85% kế hoạch | B4: =(('04_PnL'!$G$16*0.85*5.5-('02_Assumptions'!G11-'02_Assumptions'!G12))*1000000000)/('02_Assumptions'!$B$3*1000000) | C4: =(('04_PnL'!$G$16*0.85*6.5-('02_Assumptions'!G11-'02_Assumptions'!G12))*1000000000)/('02_Assumptions'!$B$3*1000000) | D4: =(('04_PnL'!$G$16*0.85*7.5-('02_Assumptions'!G11-'02_Assumptions'!G12))*1000000000)/('02_Assumptions'!$B$3*1000000) | E4: =(('04_PnL'!$G$16*0.85*8.5-('02_Assumptions'!G11-'02_Assumptions'!G12))*1000000000)/('02_Assumptions'!$B$3*1000000) | F4: =(('04_PnL'!$G$16*0.85*9.5-('02_Assumptions'!G11-'02_Assumptions'!G12))*1000000000)/('02_Assumptions'!$B$3*1000000)
A5: EBITDA 92% kế hoạch | B5: =(('04_PnL'!$G$16*0.925*5.5-('02_Assumptions'!G11-'02_Assumptions'!G12))*1000000000)/('02_Assumptions'!$B$3*1000000) | C5: =(('04_PnL'!$G$16*0.925*6.5-('02_Assumptions'!G11-'02_Assumptions'!G12))*1000000000)/('02_Assumptions'!$B$3*1000000) | D5: =(('04_PnL'!$G$16*0.925*7.5-('02_Assumptions'!G11-'02_Assumptions'!G12))*1000000000)/('02_Assumptions'!$B$3*1000000) | E5: =(('04_PnL'!$G$16*0.925*8.5-('02_Assumptions'!G11-'02_Assumptions'!G12))*1000000000)/('02_Assumptions'!$B$3*1000000) | F5: =(('04_PnL'!$G$16*0.925*9.5-('02_Assumptions'!G11-'02_Assumptions'!G12))*1000000000)/('02_Assumptions'!$B$3*1000000)
A6: EBITDA 100% kế hoạch | B6: =(('04_PnL'!$G$16*1.0*5.5-('02_Assumptions'!G11-'02_Assumptions'!G12))*1000000000)/('02_Assumptions'!$B$3*1000000) | C6: =(('04_PnL'!$G$16*1.0*6.5-('02_Assumptions'!G11-'02_Assumptions'!G12))*1000000000)/('02_Assumptions'!$B$3*1000000) | D6: =(('04_PnL'!$G$16*1.0*7.5-('02_Assumptions'!G11-'02_Assumptions'!G12))*1000000000)/('02_Assumptions'!$B$3*1000000) | E6: =(('04_PnL'!$G$16*1.0*8.5-('02_Assumptions'!G11-'02_Assumptions'!G12))*1000000000)/('02_Assumptions'!$B$3*1000000) | F6: =(('04_PnL'!$G$16*1.0*9.5-('02_Assumptions'!G11-'02_Assumptions'!G12))*1000000000)/('02_Assumptions'!$B$3*1000000)
A7: EBITDA 108% kế hoạch | B7: =(('04_PnL'!$G$16*1.075*5.5-('02_Assumptions'!G11-'02_Assumptions'!G12))*1000000000)/('02_Assumptions'!$B$3*1000000) | C7: =(('04_PnL'!$G$16*1.075*6.5-('02_Assumptions'!G11-'02_Assumptions'!G12))*1000000000)/('02_Assumptions'!$B$3*1000000) | D7: =(('04_PnL'!$G$16*1.075*7.5-('02_Assumptions'!G11-'02_Assumptions'!G12))*1000000000)/('02_Assumptions'!$B$3*1000000) | E7: =(('04_PnL'!$G$16*1.075*8.5-('02_Assumptions'!G11-'02_Assumptions'!G12))*1000000000)/('02_Assumptions'!$B$3*1000000) | F7: =(('04_PnL'!$G$16*1.075*9.5-('02_Assumptions'!G11-'02_Assumptions'!G12))*1000000000)/('02_Assumptions'!$B$3*1000000)
A8: EBITDA 115% kế hoạch | B8: =(('04_PnL'!$G$16*1.15*5.5-('02_Assumptions'!G11-'02_Assumptions'!G12))*1000000000)/('02_Assumptions'!$B$3*1000000) | C8: =(('04_PnL'!$G$16*1.15*6.5-('02_Assumptions'!G11-'02_Assumptions'!G12))*1000000000)/('02_Assumptions'!$B$3*1000000) | D8: =(('04_PnL'!$G$16*1.15*7.5-('02_Assumptions'!G11-'02_Assumptions'!G12))*1000000000)/('02_Assumptions'!$B$3*1000000) | E8: =(('04_PnL'!$G$16*1.15*8.5-('02_Assumptions'!G11-'02_Assumptions'!G12))*1000000000)/('02_Assumptions'!$B$3*1000000) | F8: =(('04_PnL'!$G$16*1.15*9.5-('02_Assumptions'!G11-'02_Assumptions'!G12))*1000000000)/('02_Assumptions'!$B$3*1000000)

Sheet 10_PESTLE
A1: Yếu tố | B1: Nội dung | C1: Tác động
A2: Chính trị - Pháp luật | B2: Thuế CBPG HRC khổ hẹp 19.38-27.83% + AD chống lẩn tránh HRC rộng 27.83% (17/04/2026). Ổn định chính trị VN. | C2: Tích cực
A3: Kinh tế | B3: GDP VN 2026E ~6.5%. Đầu tư công tăng mạnh (cao tốc, Long Thành). LS giảm. | C3: Tích cực
A4: Xã hội | B4: Đô thị hoá ~38%. Nhu cầu nhà ở & hạ tầng tăng. | C4: Tích cực
A5: Công nghệ | B5: DQ2 BOF hiện đại, tự động hoá cao. Tiết kiệm 15-20% chi phí so với cũ. | C5: Tích cực
A6: Môi trường | B6: Áp lực giảm phát thải. HPG đầu tư lọc bụi, xử lý nước thải theo chuẩn quốc tế. | C6: Trung tính
A7: Pháp lý khác | B7: NĐ 153 trái phiếu siết chặt. Room tín dụng ngân hàng mở rộng. | C7: Trung tính
A9: VỊ TRÍ CHU KỲ NGÀNH THÉP
A10: Tiêu chí | B10: Trạng thái | C10: Xu hướng | D10: Ghi chú
A11: Tăng trưởng DT ngành | B11: Cao (HPG DT 2025 +12.4% YoY) | C11: Cao | D11: Phục hồi sau đáy 2023
A12: Công suất ngành | B12: Cân bằng (HPG ~85%, HSG ~75%) | C12: Cân bằng | D12: DQ2 thêm 5.6M tấn
A13: Giá bán (HRC) | B13: 580 USD/tấn (2025), phục hồi từ đáy 480 (2023) | C13: Tăng | D13: Thuế CBPG 27.8% hỗ trợ
A14: CAPEX ngành | B14: DQ2 ~$3 tỷ xong T12/2025. CAPEX 2025: 25.748 tỷ | C14: Giảm từ đỉnh | D14: Giai đoạn thu hoạch sau CAPEX
A15: Số đối thủ | B15: HPG (~70% HRC), Formosa, HSG, NKG | C15: Ổn định | D15: Rào cản gia nhập cao
A16: Kết luận chu kỳ: | B16: Ngành thép VN đang ở giai đoạn PHỤC HỒI → TĂNG TRƯỞNG. Đáy chu kỳ (2022-2023) đã qua. DQ2 hoàn thành đưa HPG vào giai đoạn thu hoạch. Kỳ vọng biên GP mở rộng 2026-2028.
A18: THỊ TRƯỜNG MỤC TIÊU (TAM)
A19: Chỉ tiêu | B19: Giá trị | C19: Nguồn
A20: TAM thép VN (triệu tấn) | B20: ~28-30 | C20: VSA (Hiệp hội Thép VN) 2025
A21: CAGR TAM (3 năm) | B21: ~5-7% | C21: Đầu tư công + BĐS phục hồi
A22: Thị phần HPG (HRC) | B22: ~70% | C22: Độc quyền HRC nội địa
A23: Thị phần HPG (thép XD) | B23: ~40% | C23: Dẫn đầu thị trường
A24: Thị phần tiềm năng (2028) | B24: ~75% HRC, ~45% XD | C24: DQ2 mở rộng công suất

Sheet 11_Leading_Indicators
A1: Chỉ báo | B1: Ngưỡng tích cực | C1: Ngưỡng tiêu cực | D1: Giá trị hiện tại | E1: Trạng thái
A2: Giá HRC (USD/tấn) | B2: 550 | C2: 420 | D2: 475 | E2: Trung tính
A3: Giá quặng sắt (USD/tấn) | B3: 90 | C3: 120 | D3: 100.8 | E3: Trung tính
A4: Giá than cốc (USD/tấn) | B4: 180 | C4: 260 | D4: 220 | E4: Trung tính
A5: Tỷ giá USD/VNĐ | B5: 25500 | C5: 27000 | D5: 26200 | E5: Trung tính
A6: Sản lượng thép VN (triệu tấn/tháng) | B6: 2.5 | C6: 1.5 | D6: 2.92 | E6: Tích cực
A7: SX ngành thép 4M (triệu tấn) | B7: 12.5 | C7: 8 | D7: 11.67 | E7: Phục hồi (+23.5%)
A8: LNST QoQ HPG (tỷ) | B8: 7000 | C8: 3000 | D8: 9056 | E8: Tích cực
A9: D/E | B9: 0.5 | C9: 1.5 | D9: 0.65 | E9: Tích cực
A10: CIP (tỷ) | B10: 10000 | C10: 40000 | D10: 15000 | E10: Tích cực (DQ2 done)
A11: Spread thép (USD/tấn) | B11: 200 | C11: 50 | D11: 180 | E11: Tích cực
A12: Đầu tư công 4M (nghìn tỷ) | B12: 200 | C12: 150 | D12: 187 | E12: Tích cực (+10.4%)
A13: Room ngoại (tỷ USD) | B13: 1.5 | C13: 0.5 | D13: 1.2 | E13: Trung tính
... A16: Biến động giá YTD (%) | B16: 20 | C16: -10 | D16: 6.1 | E16: Trung tính

Sheet 12_Investment_Thesis
A1: Tầng | B1: Nội dung | C1: Đánh giá
A2: 1 | B2: Chuỗi giá trị: HPG tích hợp dọc từ quặng → lò cao → HRC/thép XD. Tự chủ 50% quặng (trữ lượng 320M tấn). DQ2 (5.6M tấn) full công suất từ T12/2025 giúp HPG dẫn đầu chi phí. | C2: Mạnh
A3: 2 | B3: Thị trường: VN nhập khẩu HRC ~8M tấn/năm. Thuế CBPG 27.8% với TQ tạo lợi thế cho HPG. Đầu tư công (cao tốc Bắc-Nam, Long Thành) + BĐS phục hồi kéo nhu cầu thép. | C3: Mạnh
A4: 3 | B4: Moat: Chi phí thấp nhất ngành (lò cao BOF công suất lớn). Quy mô 16M tấn. Mạng lưới phân phối rộng. Khó sao chép do CAPEX khổng lồ (DQ2 ~$3 tỷ). | C4: Rộng
A5: 4 | B5: Tài chính: D/E 0.65x an toàn. ROE TTM 16.5%. FCF cải thiện nhờ DQ2 vận hành. Biên LNG phục hồi từ 10.9% (2023) lên ~15.9% (2026E). | C5: Tốt
A6: 5 | B6: Rủi ro: (1) Giá HRC giảm mạnh do suy giảm TQ, (2) Chi phí nguyên liệu tăng (quặng/than), (3) Tỷ giá USD tăng gây áp lực nợ vay, (4) Cạnh tranh từ HSG/NKG tôn mạ. | C6: Trung bình
A7: 6 | B7: Định giá: P/B 1.56x (dưới median lịch sử 1.61x HPG). EV/EBITDA 2026E ~7.0x. Multiple mục tiêu dựa trên trung vị lịch sử HPG (TTM 2018-2026 từ Vietcap). P/E không dùng (bẫy chu kỳ). P/B buy zone <1.0x, sell >2.0x. | C7: Hấp dẫn
A9: CHI TIẾT TẦNG 1: CHUỖI GIÁ TRỊ NGÀNH THÉP
A10: Bước | B10: Mô tả | C10: Biên ước tính | D10: Ai chi phối | E10: Vị trí HPG
A11: 1 | B11: Nguyên liệu (quặng sắt/than cốc) | C11: 0-5% | D11: Vale, BHP, Rio Tinto | E11: Tự chủ 50% quặng (Quý Xa, 320M tấn)
A12: 2 | B12: Luyện cốc (sản xuất than cốc từ than mỡ) | C12: 6-12% | D12: HPG (tự SX tại DQ) | E12: Trung nguồn — tự SX cốc
A13: 3 | B13: Sản xuất phôi thép (lò cao BOF) | C13: 15-25% | D13: HPG, Formosa (Trung nguồn) | E13: Trung nguồn — mũi nhọn
A14: 4 | B14: Cán thép (HRC / thép xây dựng) | C14: 8-15% | D14: HPG, HSG, NKG | E14: Trung nguồn — thị phần HRC ~70%
A15: 5 | B15: Phân phối (đại lý / dự án) | C15: 2-4% | D15: Đại lý cấp 1, cấp 2 | E15: Hạ nguồn — mạng 300+ đại lý
A16: 6 | B16: Người dùng cuối (XD, BĐS, CN) | C16: — | D16: CTCP, BĐS, CN nhẹ | E16: —
A17: CHI TIẾT TẦNG 3: PHÂN TÍCH MOAT & ROIC
A18: Loại Moat | B18: Mức độ | C18: Bằng chứng định lượng | D18: Kết luận
A19: 1. Lợi thế chi phí (Cost) | B19: Mạnh | C19: DQ2 BOF 6M tấn, ĐMTK thấp nhất ngành. Biên GP 2025: 15.7% > HSG (10.2%). Tự SX cốc giảm 10-15% CP. | D19: Wide — chi phí/tấn thấp nhất VN
A20: 2. Chuyển đổi (Switching) | B20: TB | C20: Khách hàng đại lý lâu năm, chi phí vận chuyển cao khi đổi NCC. Nhưng thép là hàng hóa tiêu chuẩn. | D20: Narrow — rào cản chuyển đổi ở mức vừa
A21: 3. Tài sản vô hình | B21: TB | C21: Thương hiệu Hoà Phát uy tín, không có patent đặc thù. Giấy phép khai thác quặng tại Quý Xa. | D21: Narrow — chỉ có giấy phép khoáng sản
A22: 4. Hiệu ứng mạng | B22: Yếu | C22: Thép là hàng hóa B2B, không có network effect. Khách hàng không tương tác với nhau. | D22: Không có
A23: 5. Quy mô hiệu quả | B23: Mạnh | C23: Thị phần HRC ~70%, thép XD ~40%. CAPEX rào cản ~$3 tỷ cho lò cao mới. Quy mô 16M tấn. | D23: Wide — rào cản vốn khổng lồ
A24: Overall Moat Rating: | B24: WIDE MOAT | ROIC ~10.5% > WACC ~9.0% → Tạo giá trị
A26: CHI TIẾT TẦNG 5: MA TRẬN RỦI RO & CATALYST
A27: Rủi ro | B27: Loại | C27: Xác suất | D27: Tác động | E27: Leading Indicator | F27: Ngưỡng kích hoạt
A28: Giá HRC giảm mạnh | B28: Ngành | C28: TB | D28: −20% DT | E28: Giá HRC SHFE (USD/tấn) | F28: <400 USD/tấn
A29: Chi phí quặng tăng | B29: Ngành | C29: TB | D29: −5% biên GP | E29: Giá quặng 62%Fe (USD/tấn) | F29: >150 USD/tấn
A30: Tỷ giá USD tăng | B30: VM | C30: Thấp | D30: −1.500 tỷ LNST | E30: USD/VND | F30: >26.000
A31: Cạnh tranh Formosa | B31: Ngành | C31: Thấp | D31: −10% thị phần HRC | E31: CS XK HRC TQ vào VN | F31: Công suất Formosa tăng
A32: BĐS suy thoái kéo dài | B32: VM | C32: Thấp | D32: −15% SL thép XD | E32: Giải ngân đầu tư công | F32: Tăng trưởng tín dụng BĐS <5%
A33: CATALYST TĂNG TỐC THESIS
A34: Catalyst | B34: Mô tả | C34: Thời điểm | D34: Tác động giá | E34: Xác suất
A35: KQKD Q1/2026 CB | B35: KQKD khả quan nhờ sản lượng cao & spread nở | C35: 07/2026 | D35: +10-15% | E35: Cao
A36: DQ2 full công suất | B36: Dung Quất 2 chạy hết công suất 6M tấn, giảm ĐMTK | C36: H2/2026 | D36: +5-10% | E36: Cao
A37: Giải ngân đầu tư công | B37: Cao tốc Bắc-Nam, Long Thành thúc đẩy nhu cầu thép | C37: 2026-2027 | D37: +5-10% | E37: TB
A38: Giá HRC phục hồi | B38: Nhu cầu TQ hồi phục + thuế CBPG VN hỗ trợ giá | C38: H2/2026 | D38: +15-25% | E38: TB

Sheet 13_Summary_Snapshot
A1: Chỉ tiêu | B1: 2021A | C1: 2022A | D1: 2023A | E1: 2024A | F1: 2025A | G1: 2026E | H1: 2027E | I1: 2028E | J1: CAGR 25-28E
A2: Doanh thu (tỷ) | B2: ='04_PnL'!B2 | C2: ='04_PnL'!C2 | D2: ='04_PnL'!D2 | E2: ='04_PnL'!E2 | F2: ='04_PnL'!F2 | G2: ='04_PnL'!G2 | H2: ='04_PnL'!H2 | I2: ='04_PnL'!I2 | J2: =(I2/F2)^(1/3)-1
A3: LNST (tỷ) | B3: ='04_PnL'!B13 | C3: ='04_PnL'!C13 | D3: ='04_PnL'!D13 | E3: ='04_PnL'!E13 | F3: ='04_PnL'!F13 | G3: ='04_PnL'!G13 | H3: ='04_PnL'!H13 | I3: ='04_PnL'!I13 | J3: =(I3/F3)^(1/3)-1
A4: Biên LNG (%) | B4: ='04_PnL'!B5 | C4: ='04_PnL'!C5 | D4: ='04_PnL'!D5 | E4: ='04_PnL'!E5 | F4: ='04_PnL'!F5 | G4: ='04_PnL'!G5 | H4: ='04_PnL'!H5 | I4: ='04_PnL'!I5
A5: EBIT (tỷ) | B5: ='04_PnL'!B7 | C5: ='04_PnL'!C7 | D5: ='04_PnL'!D7 | E5: ='04_PnL'!E7 | F5: ='04_PnL'!F7 | G5: ='04_PnL'!G7 | H5: ='04_PnL'!H7 | I5: ='04_PnL'!I7 | J5: =(I5/F5)^(1/3)-1
A6: EBITDA (tỷ) | B6: ='04_PnL'!B16 | C6: ='04_PnL'!C16 | D6: ='04_PnL'!D16 | E6: ='04_PnL'!E16 | F6: ='04_PnL'!F16 | G6: ='04_PnL'!G16 | H6: ='04_PnL'!H16 | I6: ='04_PnL'!I16 | J6: =(I6/F6)^(1/3)-1
A7: Biên LNST (%) | B7: ='04_PnL'!B14 | C7: ='04_PnL'!C14 | D7: ='04_PnL'!D14 | E7: ='04_PnL'!E14 | F7: ='04_PnL'!F14 | G7: ='04_PnL'!G14 | H7: ='04_PnL'!H14 | I7: ='04_PnL'!I14
A8: EPS (VND) | B8: ='04_PnL'!B15 | C8: ='04_PnL'!C15 | D8: ='04_PnL'!D15 | E8: ='04_PnL'!E15 | F8: ='04_PnL'!F15 | G8: ='04_PnL'!G15 | H8: ='04_PnL'!H15 | I8: ='04_PnL'!I15 | J8: =(I8/F8)^(1/3)-1
A9: ROE (%) | B9: ='04_PnL'!B13/'02_Assumptions'!B13*100 | C9: ='04_PnL'!C13/'02_Assumptions'!C13*100 | D9: ='04_PnL'!D13/'02_Assumptions'!D13*100 | E9: ='04_PnL'!E13/'02_Assumptions'!E13*100 | F9: ='04_PnL'!F13/'02_Assumptions'!F13*100 | G9: ='04_PnL'!G13/'02_Assumptions'!G13*100 | H9: ='04_PnL'!H13/'02_Assumptions'!H13*100 | I9: ='04_PnL'!I13/'02_Assumptions'!I13*100 | J9: =(I9/F9)^(1/3)-1
A10: ROA (%) | B10: ='04_PnL'!B13/'05_Balance_Sheet'!B14*100 | C10: ='04_PnL'!C13/'05_Balance_Sheet'!C14*100 | D10: ='04_PnL'!D13/'05_Balance_Sheet'!D14*100 | E10: ='04_PnL'!E13/'05_Balance_Sheet'!E14*100 | F10: ='04_PnL'!F13/'05_Balance_Sheet'!F14*100 | G10: ='04_PnL'!G13/'05_Balance_Sheet'!G14*100 | H10: ='04_PnL'!H13/'05_Balance_Sheet'!H14*100 | I10: ='04_PnL'!I13/'05_Balance_Sheet'!I14*100 | J10: =(I10/F10)^(1/3)-1
A11: D/E (x) | B11: =('02_Assumptions'!B11-'02_Assumptions'!B12)/'02_Assumptions'!B13 | C11: =('02_Assumptions'!C11-'02_Assumptions'!C12)/'02_Assumptions'!C13 | D11: =('02_Assumptions'!D11-'02_Assumptions'!D12)/'02_Assumptions'!D13 | E11: =('02_Assumptions'!E11-'02_Assumptions'!E12)/'02_Assumptions'!E13 | F11: =('02_Assumptions'!F11-'02_Assumptions'!F12)/'02_Assumptions'!F13 | G11: =('02_Assumptions'!G11-'02_Assumptions'!G12)/'02_Assumptions'!G13 | H11: =('02_Assumptions'!H11-'02_Assumptions'!H12)/'02_Assumptions'!H13 | I11: =('02_Assumptions'!I11-'02_Assumptions'!I12)/'02_Assumptions'!I13 | J11: =(I11/F11)^(1/3)-1
A12: P/E (x) | B12: =('02_Assumptions'!$B$2*'02_Assumptions'!$B$3/1000)/'04_PnL'!B13 | C12: =('02_Assumptions'!$B$2*'02_Assumptions'!$B$3/1000)/'04_PnL'!C13 | D12: =('02_Assumptions'!$B$2*'02_Assumptions'!$B$3/1000)/'04_PnL'!D13 | E12: =('02_Assumptions'!$B$2*'02_Assumptions'!$B$3/1000)/'04_PnL'!E13 | F12: =('02_Assumptions'!$B$2*'02_Assumptions'!$B$3/1000)/'04_PnL'!F13 | G12: =('02_Assumptions'!$B$2*'02_Assumptions'!$B$3/1000)/'04_PnL'!G13 | H12: =('02_Assumptions'!$B$2*'02_Assumptions'!$B$3/1000)/'04_PnL'!H13 | I12: =('02_Assumptions'!$B$2*'02_Assumptions'!$B$3/1000)/'04_PnL'!I13 | J12: =(I12/F12)^(1/3)-1
A13: P/B (x) | B13: =('02_Assumptions'!$B$2*'02_Assumptions'!$B$3/1000)/'02_Assumptions'!B13 | C13: =('02_Assumptions'!$B$2*'02_Assumptions'!$B$3/1000)/'02_Assumptions'!C13 | D13: =('02_Assumptions'!$B$2*'02_Assumptions'!$B$3/1000)/'02_Assumptions'!D13 | E13: =('02_Assumptions'!$B$2*'02_Assumptions'!$B$3/1000)/'02_Assumptions'!E13 | F13: =('02_Assumptions'!$B$2*'02_Assumptions'!$B$3/1000)/'02_Assumptions'!F13 | G13: =('02_Assumptions'!$B$2*'02_Assumptions'!$B$3/1000)/'02_Assumptions'!G13 | H13: =('02_Assumptions'!$B$2*'02_Assumptions'!$B$3/1000)/'02_Assumptions'!H13 | I13: =('02_Assumptions'!$B$2*'02_Assumptions'!$B$3/1000)/'02_Assumptions'!I13 | J13: =(I13/F13)^(1/3)-1
A14: EV/EBITDA (x) | B14: =('02_Assumptions'!$B$2*'02_Assumptions'!$B$3/1000+('02_Assumptions'!B11-'02_Assumptions'!B12))/'04_PnL'!B16 | C14: =('02_Assumptions'!$B$2*'02_Assumptions'!$B$3/1000+('02_Assumptions'!C11-'02_Assumptions'!C12))/'04_PnL'!C16 | D14: =('02_Assumptions'!$B$2*'02_Assumptions'!$B$3/1000+('02_Assumptions'!D11-'02_Assumptions'!D12))/'04_PnL'!D16 | E14: =('02_Assumptions'!$B$2*'02_Assumptions'!$B$3/1000+('02_Assumptions'!E11-'02_Assumptions'!E12))/'04_PnL'!E16 | F14: =('02_Assumptions'!$B$2*'02_Assumptions'!$B$3/1000+('02_Assumptions'!F11-'02_Assumptions'!F12))/'04_PnL'!F16 | G14: =('02_Assumptions'!$B$2*'02_Assumptions'!$B$3/1000+('02_Assumptions'!G11-'02_Assumptions'!G12))/'04_PnL'!G16 | H14: =('02_Assumptions'!$B$2*'02_Assumptions'!$B$3/1000+('02_Assumptions'!H11-'02_Assumptions'!H12))/'04_PnL'!H16 | I14: =('02_Assumptions'!$B$2*'02_Assumptions'!$B$3/1000+('02_Assumptions'!I11-'02_Assumptions'!I12))/'04_PnL'!I16 | J14: =(I14/F14)^(1/3)-1
A15: CAPEX (tỷ) | B15: ='02_Assumptions'!B10 | C15: ='02_Assumptions'!C10 | D15: ='02_Assumptions'!D10 | E15: ='02_Assumptions'!E10 | F15: ='02_Assumptions'!F10 | G15: ='02_Assumptions'!G10 | H15: ='02_Assumptions'!H10 | I15: ='02_Assumptions'!I10 | J15: =(I15/F15)^(1/3)-1
A17: KẾ HOẠCH ĐHĐCĐ 2026 vs THỰC HIỆN 2025
A18: Chỉ tiêu | B18: KH 2025 | C18: TH 2025 | D18: % hoàn thành | E18: KH 2026 | F18: Q1/2026 | G18: % KH năm
A19: Doanh thu (tỷ) | B19: 170000 | C19: 156116.09 | D19: 91.8% | E19: 210000 | F19: 52,901 | G19: 25.2%
A20: LNST (tỷ) | B20: 15000 | C20: 15453.174 | D20: 103.0% | E20: 22000 | F20: 8,994 | G20: 40.9%
A21: PHÂN TÍCH CHẤT LƯỢNG LỢI NHUẬN
A22: Chỉ tiêu | B22: 2021A | C22: 2022A | D22: 2023A | E22: 2024A | F22: 2025A | G22: Nhận xét
B23: 0.78 | C23: 1.45 | D23: 1.26 | E23: 0.55 | F23: 1.12
B24: -4.4 | C24: 2.2 | D24: 1 | E24: -2.4 | F24: 0.7
B25: ~60% | C25: ~60% | D25: ~60% | E25: ~70% | F25: ~70%
B26: — | C26: — | D26: — | E26: — | F26: —
A28: BRIDGE ANALYSIS 2025A → 2026E
A29: Chỉ tiêu | B29: Giá trị | C29: Giải thích
A30: Doanh thu 2025A | B30: 156,116 tỷ | C30: Cơ sở
A31: + Tăng từ DQ2 full công suất | B31: +13,308 tỷ | C31: DQ2 5.6M tấn chạy full năm 2026
A32: + Tăng từ giá HRC phục hồi | B32: +~15,000 tỷ | C32: Giá HRC 580→620 USD/tấn
A33: =Doanh thu 2026E | B33: 169,424 tỷ | C33: KH ĐHĐCĐ: 210,000 tỷ
A35: Biên GP 2025A | B35: 15.7% | C35: Cơ sở
A36: + Cải thiện nhờ DQ2 (ĐMTK thấp hơn) | B36: +1.5% | C36: DQ2 BOF hiện đại, tiết kiệm 15-20% CP
A37: + Tồn kho giá rẻ (quặng mua H2/2025) | B37: +0.5% | C37: Giá quặng 105 USD/tấn thấp hơn 2024
A38: =Biên GP 2026E | B38: 15.9% | C38: Spread trend từ Q1/2026
A40: LNST 2025A | B40: 15,453 tỷ | C40: Cơ sở
A41: + Tăng từ DT + biên GP mở rộng | B41: +5,757 tỷ | C41: Operating leverage
A42: - Tăng chi phí lãi vay | B42: -~500 tỷ | C42: Dư nợ tăng nhẹ (DQ2 vốn vay)
A43: =LNST 2026E | B43: 21,210 tỷ | C43: KH ĐHĐCĐ: 22,000 tỷ

Sheet 14_Steel_Analysis
A1: PHÂN TÍCH NGÀNH THÉP — HPG (Skill: thep)
A2: Phân loại: phan-loai-nganh → Nhóm 7: Thép (HPG, HSG, NKG, TVN)
A3: Công thức Spread (lag 1 quý): Giá HRC quý này - 1.6×Quặng 62%Fe quý TRƯỚC - 0.6×Than cốc quý TRƯỚC - 100 USD/tấn (CP SX khác cố định) — do tồn kho HPG bình quân ~90 ngày = ~1 quý. Xem sheet 17_Gia_Hang_Hoa.
A5: 1. GIÁ ĐẦU VÀO & ĐẦU RA (USD/tấn)
A6: Chỉ tiêu | B6: 2021A | C6: 2022A | D6: 2023A | E6: 2024A | F6: 2025A | G6: 2026E | H6: 2027E | I6: 2028E
A7: Giá HRC (USD/tấn) | B7: ='17_Gia_Hang_Hoa'!B31 | C7: ='17_Gia_Hang_Hoa'!C31 | D7: ='17_Gia_Hang_Hoa'!D31 | E7: ='17_Gia_Hang_Hoa'!E31 | F7: ='17_Gia_Hang_Hoa'!F31 | G7: ='17_Gia_Hang_Hoa'!G31 | H7: ='17_Gia_Hang_Hoa'!H31 | I7: ='17_Gia_Hang_Hoa'!I31
A8: Giá quặng sắt 62%Fe (USD/tấn) | B8: ='17_Gia_Hang_Hoa'!B32 | C8: ='17_Gia_Hang_Hoa'!C32 | D8: ='17_Gia_Hang_Hoa'!D32 | E8: ='17_Gia_Hang_Hoa'!E32 | F8: ='17_Gia_Hang_Hoa'!F32 | G8: ='17_Gia_Hang_Hoa'!G32 | H8: ='17_Gia_Hang_Hoa'!H32 | I8: ='17_Gia_Hang_Hoa'!I32
A9: Giá than cốc (USD/tấn) | B9: ='17_Gia_Hang_Hoa'!B33 | C9: ='17_Gia_Hang_Hoa'!C33 | D9: ='17_Gia_Hang_Hoa'!D33 | E9: ='17_Gia_Hang_Hoa'!E33 | F9: ='17_Gia_Hang_Hoa'!F33 | G9: ='17_Gia_Hang_Hoa'!G33 | H9: ='17_Gia_Hang_Hoa'!H33 | I9: ='17_Gia_Hang_Hoa'!I33
A10: Spread thép (USD/tấn) | B10: ='17_Gia_Hang_Hoa'!B35 | C10: ='17_Gia_Hang_Hoa'!C35 | D10: ='17_Gia_Hang_Hoa'!D35 | E10: ='17_Gia_Hang_Hoa'!E35 | F10: ='17_Gia_Hang_Hoa'!F35 | G10: ='17_Gia_Hang_Hoa'!G35 | H10: ='17_Gia_Hang_Hoa'!H35 | I10: ='17_Gia_Hang_Hoa'!I35
A11: Spread / Giá HRC (%) | B11: =B10/B7*100 | C11: =C10/C7*100 | D11: =D10/D7*100 | E11: =E10/E7*100 | F11: =F10/F7*100 | G11: =G10/G7*100 | H11: =H10/H7*100 | I11: =I10/I7*100
A12: 2. SẢN LƯỢNG & THỊ PHẦN
A13: Chỉ tiêu | B13: 2021A | C13: 2022A | D13: 2023A | E13: 2024A | F13: 2025A | G13: 2026E | H13: 2027E | I13: 2028E
A14: Sản lượng HRC HPG (triệu tấn) | B14: ='03_Revenue_Model'!B4 | C14: ='03_Revenue_Model'!C4 | D14: ='03_Revenue_Model'!D4 | E14: ='03_Revenue_Model'!E4 | F14: ='03_Revenue_Model'!F4 | G14: ='03_Revenue_Model'!G4 | H14: ='03_Revenue_Model'!H4 | I14: ='03_Revenue_Model'!I4
A15: Sản lượng thép XD HPG (triệu tấn) | B15: ='03_Revenue_Model'!B5 | C15: ='03_Revenue_Model'!C5 | D15: ='03_Revenue_Model'!D5 | E15: ='03_Revenue_Model'!E5 | F15: ='03_Revenue_Model'!F5 | G15: ='03_Revenue_Model'!G5 | H15: ='03_Revenue_Model'!H5 | I15: ='03_Revenue_Model'!I5
A16: Tổng sản lượng HPG (triệu tấn) | B16: =B14+B15 | C16: =C14+C15 | D16: =D14+D15 | E16: =E14+E15 | F16: =F14+F15 | G16: =G14+G15 | H16: =H14+H15 | I16: =I14+I15
A17: Sản lượng thị trường thép VN (triệu tấn) | B17: 28 | C17: 27 | D17: 25 | E17: 26 | F17: 28 | G17: 30 | H17: 32 | I17: 34
A18: Thị phần HPG (%) | B18: =B16/B17*100 | C18: =C16/C17*100 | D18: =D16/D17*100 | E18: =E16/E17*100 | F18: =F16/F17*100 | G18: =G16/G17*100 | H18: =H16/H17*100 | I18: =I16/I17*100
A20: 3. YẾU TỐ TÁC ĐỘNG NGÀNH THÉP
A21: Yếu tố | B21: Đánh giá
A22: Đầu ra | B22: Giá HRC phụ thuộc nhu cầu TQ, thuế CBPG 27.8% bảo vệ thị trường nội địa
A23: Đầu vào | B23: Quặng sắt (62%Fe) và than cốc chiếm ~60% giá thành. HPG tự chủ 50% quặng
A24: Vĩ mô | B24: GDP VN ~6.5%, đầu tư công cao tốc Bắc-Nam + Long Thành kéo nhu cầu thép
A25: Cạnh tranh | B25: HPG dẫn đầu thị phần HRC (~70%) và thép XD (~40%). Đối thủ: HSG, NKG
A26: Rủi ro | B26: Giá HRC giảm, quặng/than tăng, tỷ giá USD, BĐS suy thoái
A27: Định giá | B27: P/B là công cụ chính (mua 0.7-1.0x, bán 2.0-2.5x). P/E là bẫy chu kỳ
A29: 4. HÀNG TỒN KHO, PHẢI THU & ĐÒN BẨY — DIO/DSO = 365 x Số dư BÌNH QUÂN (đầu+cuối kỳ)/2 / GVHB hoặc DT (chỉ lịch sử — không dự phóng vì ít ảnh hưởng tới định giá)
A30: Chỉ tiêu | B30: 2021A | C30: 2022A | D30: 2023A | E30: 2024A | F30: 2025A | G30: 2026E | H30: 2027E | I30: 2028E
A31: Hàng tồn kho (tỷ VND) | B31: ='05_Balance_Sheet'!B6 | C31: ='05_Balance_Sheet'!C6 | D31: ='05_Balance_Sheet'!D6 | E31: ='05_Balance_Sheet'!E6 | F31: ='05_Balance_Sheet'!F6 | G31: — | H31: — | I31: —
A32: Vòng quay HTK (lần) = GVHB / Tồn kho BQ | B32: ='04_PnL'!B3/'05_Balance_Sheet'!B6 | C32: ='04_PnL'!C3/(('05_Balance_Sheet'!B6+'05_Balance_Sheet'!C6)/2) | D32: ='04_PnL'!D3/(('05_Balance_Sheet'!C6+'05_Balance_Sheet'!D6)/2) | E32: ='04_PnL'!E3/(('05_Balance_Sheet'!D6+'05_Balance_Sheet'!E6)/2) | F32: ='04_PnL'!F3/(('05_Balance_Sheet'!E6+'05_Balance_Sheet'!F6)/2) | G32: — | H32: — | I32: —
A33: Số ngày tồn kho bình quân (DIO) | B33: =365/B32 | C33: =365/C32 | D33: =365/D32 | E33: =365/E32 | F33: =365/F32 | G33: — | H33: — | I33: —
A34: Phải thu ngắn hạn (tỷ VND) | B34: ='05_Balance_Sheet'!B5 | C34: ='05_Balance_Sheet'!C5 | D34: ='05_Balance_Sheet'!D5 | E34: ='05_Balance_Sheet'!E5 | F34: ='05_Balance_Sheet'!F5 | G34: — | H34: — | I34: —
A35: Số ngày phải thu bình quân (DSO) | B35: =365/('04_PnL'!B2/'05_Balance_Sheet'!B5) | C35: =365/('04_PnL'!C2/(('05_Balance_Sheet'!B5+'05_Balance_Sheet'!C5)/2)) | D35: =365/('04_PnL'!D2/(('05_Balance_Sheet'!C5+'05_Balance_Sheet'!D5)/2)) | E35: =365/('04_PnL'!E2/(('05_Balance_Sheet'!D5+'05_Balance_Sheet'!E5)/2)) | F35: =365/('04_PnL'!F2/(('05_Balance_Sheet'!E5+'05_Balance_Sheet'!F5)/2)) | G35: — | H35: — | I35: —
A36: D/E = Vay NH+DH / VCSH | B36: =('05_Balance_Sheet'!B17+'05_Balance_Sheet'!B20)/'05_Balance_Sheet'!B28 | C36: =('05_Balance_Sheet'!C17+'05_Balance_Sheet'!C20)/'05_Balance_Sheet'!C28 | D36: =('05_Balance_Sheet'!D17+'05_Balance_Sheet'!D20)/'05_Balance_Sheet'!D28 | E36: =('05_Balance_Sheet'!E17+'05_Balance_Sheet'!E20)/'05_Balance_Sheet'!E28 | F36: =('05_Balance_Sheet'!F17+'05_Balance_Sheet'!F20)/'05_Balance_Sheet'!F28 | G36: =('05_Balance_Sheet'!G17+'05_Balance_Sheet'!G20)/'05_Balance_Sheet'!G28 | H36: =('05_Balance_Sheet'!H17+'05_Balance_Sheet'!H20)/'05_Balance_Sheet'!H28 | I36: =('05_Balance_Sheet'!I17+'05_Balance_Sheet'!I20)/'05_Balance_Sheet'!I28
A37: Vay ngắn hạn / Tổng vay (%) | B37: ='05_Balance_Sheet'!B17/('05_Balance_Sheet'!B17+'05_Balance_Sheet'!B20)*100 | C37: ='05_Balance_Sheet'!C17/('05_Balance_Sheet'!C17+'05_Balance_Sheet'!C20)*100 | D37: ='05_Balance_Sheet'!D17/('05_Balance_Sheet'!D17+'05_Balance_Sheet'!D20)*100 | E37: ='05_Balance_Sheet'!E17/('05_Balance_Sheet'!E17+'05_Balance_Sheet'!E20)*100 | F37: ='05_Balance_Sheet'!F17/('05_Balance_Sheet'!F17+'05_Balance_Sheet'!F20)*100 | G37: ='05_Balance_Sheet'!G17/('05_Balance_Sheet'!G17+'05_Balance_Sheet'!G20)*100 | H37: ='05_Balance_Sheet'!H17/('05_Balance_Sheet'!H17+'05_Balance_Sheet'!H20)*100 | I37: ='05_Balance_Sheet'!I17/('05_Balance_Sheet'!I17+'05_Balance_Sheet'!I20)*100
A39: 5. ĐỊNH GIÁ CHU KỲ — P/B vs P/E
A40: Chỉ tiêu | B40: 2021A | C40: 2022A | D40: 2023A | E40: 2024A | F40: 2025A | G40: Nhận xét
A41: P/E (TTM cuối năm) | B41: 9.4 | C41: 13.9 | D41: 13.8 | E41: 25.5 | F41: 14.2 | G41: Bẫy chu kỳ: P/E thấp khi LN đỉnh
A42: P/B (cuối năm) | B42: 1.42 | C42: 1.67 | D42: 1.45 | E42: 1.69 | F42: 1.25 | G42: Công cụ chính: mua <1.0x, bán >2.0x
A43: ROE (%) | B43: 38 | C43: 8.8 | D43: 6.6 | E43: 10.5 | F43: 11.8 | G43: P/B = ROE × P/E
A47: 6. DƯ CUNG TOÀN CẦU & SẢN LƯỢNG THÉP THẾ GIỚI
...

Sheet 15_Quarterly_Data
A1: DỮ LIỆU TÀI CHÍNH QUÝ HPG (2018-2026)
A3: A. KẾT QUẢ KINH DOANH (tỷ VND)
B4: Q1/2018 | C4: Q2/2018 | D4: Q3/2018 | E4: Q4/2018 | F4: Q1/2019 | G4: Q2/2019 | H4: Q3/2019 | I4: Q4/2019 | J4: Q1/2020 | K4: Q2/2020 | L4: Q3/2020 | M4: Q4/2020 | N4: Q1/2021 | O4: Q2/2021 | P4: Q3/2021 | Q4: Q4/2021 | R4: Q1/2022 | S4: Q2/2022 | T4: Q3/2022 | U4: Q4/2022 | V4: Q1/2023 | W4: Q2/2023 | X4: Q3/2023 | Y4: Q4/2023 | Z4: Q1/2024 | AA4: Q2/2024 | AB4: Q3/2024 | AC4: Q4/2024 | AD4: Q1/2025 | AE4: Q2/2025 | AF4: Q3/2025 | AG4: Q4/2025 | AH4: Q1/2026
A5: Doanh thu thuần | B5: 13000.963 | C5: 14260.938 | D5: 14188.346 | E5: 14386.211 | F5: 14963.251 | G5: 15632.608 | H5: 15087.031 | I5: 17975.303 | J5: 19232.708 | K5: 20422.202 | L5: 24685.562 | M5: 25778.071 | N5: 31176.875 | O5: 35118.355 | P5: 38673.829 | Q5: 44710.732 | R5: 44058.147 | S5: 37422.055 | T5: 34103.341 | U5: 25825.732 | V5: 26588.752 | W5: 29496.383 | X5: 28484.088 | Y5: 34383.805 | Z5: 30852.36 | AA5: 39555.51 | AB5: 33956.26 | AC5: 34490.982 | AD5: 37621.675 | AE5: 35910.519 | AF5: 36407.416 | AG5: 46176.485 | AH5: 52900.847
A6: Giá vốn hàng bán | B6: 10035.454 | C6: 11379.663 | D6: 10925.13 | E6: 11825.379 | F6: 12342.336 | G6: 12605.804 | H6: 12385.058 | I6: 15139.622 | J6: 15469.65 | K6: 16716.7 | L6: 19516.497 | M6: 19510.834 | N6: 22993.833 | O6: 23641.296 | P6: 26812.93 | Q6: 35123.322 | R6: 33949.82 | S6: 30882.432 | T6: 33102.614 | U6: 26710.982 | V6: 24912.315 | W6: 26301.396 | X6: 24889.281 | Y6: 29912.195 | Z6: 26698.377 | AA6: 34308.029 | AB6: 29225.084 | AC6: 30126.073 | AD6: 32197.521 | AE6: 29320.797 | AF6: 30320.155 | AG6: 39779.834 | AH6: 44535.779
A7: Lợi nhuận gộp | B7: 2965.5092 | C7: 2881.2751 | D7: 3263.2161 | E7: 2560.8319 | F7: 2620.914 | G7: 3026.804 | H7: 2701.9736 | I7: 2835.6806 | J7: 3763.0584 | K7: 3705.5023 | L7: 5169.0653 | M7: 6267.2375 | N7: 8183.0419 | O7: 11477.059 | P7: 11860.899 | Q7: 9587.4097 | R7: 10108.326 | S7: 6539.6222 | T7: 1000.7276 | U7: -885.24994 | V7: 1676.4371 | W7: 3194.987 | X7: 3594.8066 | Y7: 4471.61 | Z7: 4153.983 | AA7: 5247.4805 | AB7: 4731.1767 | AC7: 4364.909 | AD7: 5424.1539 | AE7: 6589.7225 | AF7: 6087.2613 | AG7: 6396.6505 | AH7: 8365.0686
A8: Biên LNG % | B8: 22.8 | C8: 20.2 | D8: 23 | E8: 17.8 | F8: 17.5 | G8: 19.4 | H8: 17.9 | I8: 15.8 | J8: 19.6 | K8: 18.1 | L8: 20.9 | M8: 24.3 | N8: 26.2 | O8: 32.7 | P8: 30.7 | Q8: 21.4 | R8: 22.9 | S8: 17.5 | T8: 2.9 | U8: -3.4 | V8: 6.3 | W8: 10.8 | X8: 12.6 | Y8: 13 | Z8: 13.5 | AA8: 13.3 | AB8: 13.9 | AC8: 12.7 | AD8: 14.4 | AE8: 18.4 | AF8: 16.7 | AG8: 13.9 | AH8: 15.8
A9: CP BH & QLDN | B9: 258.36542 | C9: 220.86701 | D9: 240.26422 | E9: 401.34076 | F9: 314.23694 | G9: 375.29607 | H9: 376.99396 | I9: 375.8102 | J9: 411.08347 | K9: 414.55429 | L9: 461.75923 | M9: 497.38589 | N9: 620.55294 | O9: 784.82996 | P9: 818.70733 | Q9: 1220.2395 | R9: 840.56053 | S9: 856.32827 | T9: 929.40565 | U9: 1058.9559 | V9: 757.48485 | W9: 871.4272 | X9: 878.84788 | Y9: 760.89254 | Z9: 957.65729 | AA9: 1135.9275 | AB9: 1041.7097 | AC9: 747.53014 | AD9: 1085.0595 | AE9: 1147.6578 | AF9: 1154.9293 | AG9: 682.52148 | AH9: 1730.8709
A10: LN từ HĐKD | B10: 2598.7132 | C10: 2580.5738 | D10: 2868.5921 | E10: 2024.2068 | F10: 2157.7061 | G10: 2469.554 | H10: 2135.0132 | I10: 2268.7084 | J10: 2635.6838 | K10: 3081.0328 | L10: 4240.9882 | M10: 5331.7232 | N10: 7683.3368 | O10: 10323.744 | P10: 10961.076 | Q10: 8040.2866 | R10: 8924.4038 | S10: 4312.5965 | T10: -1351.5205 | U10: -2091.4492 | V10: 491.89346 | W10: 1715.017 | X10: 2128.205 | Y10: 3315.6473 | Z10: 2887.6678 | AA10: 3691.5211 | AB10: 3385.0176 | AC10: 3302.7991 | AD10: 3806.582 | AE10: 4960.7863 | AF10: 4571.0247 | AG10: 4567.4409 | AH10: 10704.034
A11: Doanh thu TC | B11: 63.318174 | C11: 79.415973 | D11: 79.985466 | E11: 71.688658 | F11: 91.858568 | G11: 118.36632 | H11: 138.55099 | I11: 122.44355 | J11: 108.97989 | K11: 314.91626 | L11: 247.68908 | M11: 355.49993 | N11: 898.3073 | O11: 446.30979 | P11: 879.41414 | Q11: 856.74019 | R11: 768.92549 | S11: 661.961 | T11: 886.16666 | U11: 1540.9664 | V11: 903.45192 | W11: 732.94208 | X11: 850.62454 | Y11: 732.31628 | Z11: 751.95537 | AA11: 645.0601 | AB11: 528.45317 | AC11: 700.5601 | AD11: 438.05724 | AE11: 498.18373 | AF11: 711.90336 | AG11: 437.28087 | AH11: 5938.3474
A12: Chi phí TC | B12: 171.74875 | C12: 159.25026 | D12: 234.34523 | E12: 206.97292 | F12: 240.82952 | G12: 300.32019 | H12: 328.51739 | I12: 312.17433 | J12: 823.11367 | K12: 541.17732 | L12: 708.51195 | M12: 786.89925 | N12: 767.76803 | O12: 821.22073 | P12: 968.2782 | Q12: 1183.6061 | R12: 1111.1426 | S12: 2032.7308 | T12: 2309.009 | U12: 1688.2098 | V12: 1330.5107 | W12: 1341.4848 | X12: 1438.3783 | Y12: 1127.3864 | Z12: 1060.6133 | AA12: 1065.0919 | AB12: 832.90257 | AC12: 1015.1398 | AD12: 970.56964 | AE12: 979.4621 | AF12: 1073.2106 | AG12: 1583.969 | AH12: 1868.8272
A13: LNTT | B13: 2608.4392 | C13: 2577.218 | D13: 2848.0861 | E13: 2037.3296 | F13: 2170.9402 | G13: 2479.8126 | H13: 2160.9147 | I13: 2284.9967 | J13: 2657.0912 | K13: 3095.7214 | L13: 4271.8716 | M13: 5330.2493 | N13: 7690.2132 | O13: 10349.452 | P13: 10978.756 | Q13: 8038.3563 | R13: 8922.1039 | S13: 4379.3405 | T13: -1299.9553 | U13: -2078.5479 | V13: 532.04279 | W13: 1701.887 | X13: 2174.2301 | Y13: 3384.5689 | Z13: 3261.2154 | AA13: 3733.2257 | AB13: 3412.3851 | AC13: 3286.6761 | AD13: 3839.7653 | AE13: 4972.3835 | AF13: 4628.3132 | AG13: 4600.13 | AH13: 10762.184
A14: LNST | B14: 2222.7556 | C14: 2202.3722 | D14: 2408.4226 | E14: 1767.0002 | F14: 1810.4498 | G14: 2050.0157 | H14: 1794.413 | I14: 1923.3719 | J14: 2304.7606 | K14: 2755.5617 | L14: 3785.1227 | M14: 4660.7215 | N14: 7005.559 | O14: 9745.1514 | P14: 10350.844 | Q14: 7419.4003 | R14: 8206.3304 | S14: 4022.5734 | T14: -1785.7074 | U14: -1998.7673 | V14: 383.22961 | W14: 1447.8248 | X14: 2000.3631 | Y14: 2968.9708 | Z14: 2869.1826 | AA14: 3319.5747 | AB14: 3021.672 | AC14: 2809.5943 | AD14: 3349.8054 | AE14: 4264.5241 | AF14: 4012.2523 | AG14: 3888.3497 | AH14: 9055.9182
A15: LNST CĐCTM | B15: 2211.254 | C15: 2195.5869 | D15: 2401.9525 | E15: 1764.2207 | F15: 1800.7942 | G15: 2035.1941 | H15: 1754.7557 | I15: 1917.0058 | J15: 2285.2869 | K15: 2742.8269 | L15: 3772.7073 | M15: 4637.8546 | N15: 6977.5543 | O15: 9721.4065 | P15: 10351.739 | Q15: 7427.4432 | R15: 8216.9604 | S15: 4032.2323 | T15: -1774.1336 | U15: -1991.5485 | V15: 397.49728 | W15: 1460.0426 | X15: 2004.7451 | Y15: 2972.7794 | Z15: 2870.5887 | AA15: 3319.2631 | AB15: 3022.9466 | AC15: 2808.6454 | AD15: 3344.2847 | AE15: 4256.4872 | AF15: 3988.3185 | AG15: 3864.0836 | AH15: 8994.0032
A17: B. BẢNG CÂN ĐỐI KẾ TOÁN (tỷ VND)
B18: Q1/2018 | C18: Q2/2018 | D18: Q3/2018 | E18: Q4/2018 | F18: Q1/2019 | G18: Q2/2019 | H18: Q3/2019 | I18: Q4/2019 | J18: Q1/2020 | K18: Q2/2020 | L18: Q3/2020 | M18: Q4/2020 | N18: Q1/2021 | O18: Q2/2021 | P18: Q3/2021 | Q18: Q4/2021 | R18: Q1/2022 | S18: Q2/2022 | T18: Q3/2022 | U18: Q4/2022 | V18: Q1/2023 | W18: Q2/2023 | X18: Q3/2023 | Y18: Q4/2023 | Z18: Q1/2024 | AA18: Q2/2024 | AB18: Q3/2024 | AC18: Q4/2024 | AD18: Q1/2025 | AE18: Q2/2025 | AF18: Q3/2025 | AG18: Q4/2025 | AH18: Q1/2026
A19: Tiền & tương đương | B19: 6662.9685 | C19: 5319.0382 | D19: 3976.1517 | E19: 2515.6171 | F19: 6110.8792 | G19: 5900.0761 | H19: 3972.9437 | I19: 4564.9023 | J19: 6157.8272 | K19: 7489.5896 | L19: 5628.5487 | M19: 13001.002 | N19: 14018.629 | O19: 14644.184 | P19: 13376.486 | Q19: 22471.376 | R19: 19060.015 | S19: 20325.198 | T19: 11881.408 | U19: 8324.5889 | V19: 7868.4516 | W19: 13252.855 | X19: 9696.6694 | Y19: 12267.401 | Z19: 12428.888 | AA19: 13032.038 | AB19: 8500.9981 | AC19: 6887.6461 | AD19: 7459.0358 | AE19: 10688.024 | AF19: 9092.5627 | AG19: 8300.8903 | AH19: 11455.231
A20: Tổng tài sản | B20: 54437.484 | C20: 62078.342 | D20: 70102.772 | E20: 78224.963 | F20: 84946.73 | G20: 93019.262 | H20: 97448.356 | I20: 101790.66 | J20: 107108.97 | K20: 112644.2 | L20: 117472.26 | M20: 131511.44 | N20: 138982.27 | O20: 159809.15 | P20: 174643.27 | Q20: 178235.97 | R20: 185847.11 | S20: 207496.63 | T20: 183805.11 | U20: 170335.52 | V20: 175408.61 | W20: 176243.32 | X20: 173507.01 | Y20: 187782.59 | Z20: 201940.23 | AA20: 206609.08 | AB20: 211386.34 | AC20: 224489.71 | AD20: 228861.59 | AE20: 242224.53 | AF20: 246171.34 | AG20: 257899.2 | AH20: 259327.5
A21: Vốn chủ sở hữu | B21: 34428.193 | C21: 36626.844 | D21: 39033.701 | E21: 40608.95 | F21: 42211.124 | G21: 44256.09 | H21: 46049.526 | I21: 47787.787 | J21: 50063.409 | K21: 52580.576 | L21: 54987.271 | M21: 59219.789 | N21: 66221.56 | O21: 73984.439 | P21: 84325.684 | Q21: 90780.177 | R21: 98957.938 | S21: 99915.401 | T21: 98075.483 | U21: 96112.94 | V21: 96437.975 | W21: 97860.291 | X21: 99865.188 | Y21: 102836.42 | Z21: 105624.58 | AA21: 108676.56 | AB21: 111779.1 | AC21: 114647.46 | AD21: 117996.88 | AE21: 122359.5 | AF21: 127516.01 | AG21: 131220.01 | AH21: 139781.79
A22: Hàng tồn kho | B22: 11333.205 | C22: 12887.027 | D22: 14770.217 | E22: 14115.158 | F22: 12658.14 | G22: 15391.106 | H22: 18945.703 | I22: 19411.923 | J22: 19554.349 | K22: 20763.288 | L22: 20979.334 | M22: 26286.822 | N22: 27750.576 | O22: 39803.824 | P22: 46006.414 | Q22: 42134.494 | R22: 40036.171 | S22: 57554.102 | T22: 43880.267 | U22: 34491.111 | V22: 34306.897 | W22: 32001.579 | X22: 33524.023 | Y22: 34504.487 | Z22: 42714.28 | AA22: 40163.541 | AB22: 40197.821 | AC22: 46091.222 | AD22: 46603.844 | AE22: 48853.408 | AF22: 45623.656 | AG22: 52828.227 | AH22: 43515.585
